Workbook

Sheet اقرأني
A1: مشغل الأسبوع 11 — تحليل الفقرات
A2: مساق القياس والتقويم التربوي — دبلوم الدراسات العليا المهني في التدريس
A4: تنبيه: البيانات محاكاة حاسوبية لأغراض التدريب، وليست درجات طلبة حقيقيين.
A5: 150 طالباً × 30 فقرة اختيار من متعدد (أ، ب، ج، د مرمّزة A B C D).
A6: في الاختبار فقرات معيبة عمداً. مهمتك اكتشافها وتفسير سبب عيب كل منها.
A8: أوراق المصنف:
A9: الإجابات: الإجابات الخام لكل طالب، وصف مفتاح الإجابة في الأعلى.
A10: التصحيح: تحويل الإجابات إلى 1/0 بمعادلات، والدرجة الكلية لكل طالب.
A11: تحليل الفقرات: الصعوبة، والتمييز بطريقتين، ومعامل الثبات إذا حُذفت الفقرة، وتوصية آلية.
A12: تحليل المموهات: نسبة اختيار كل بديل في الكل وفي الفئتين العليا والدنيا.
A13: ملخص الاختبار: الإحصاءات الوصفية، وكرونباخ ألفا، والخطأ المعياري للقياس، وتوزيع الدرجات.
A15: الخلايا الصفراء مدخلات يمكن تعديلها (نسبة الفئتين ومعايير القرار). كل ما عداها معادلات حية.
A16: جرّب: صحّح مفتاح الفقرة 7 في ورقة الإجابات وراقب تغيّر التمييز والثبات فوراً.

Sheet الإجابات
A1: رقم الطالب | B1: ف1 | C1: ف2 | D1: ف3 | E1: ف4 | F1: ف5 | G1: ف6 | H1: ف7 | I1: ف8 | J1: ف9 | K1: ف10 | L1: ف11 | M1: ف12 | N1: ف13 | O1: ف14 | P1: ف15 | Q1: ف16 | R1: ف17 | S1: ف18 | T1: ف19 | U1: ف20 | V1: ف21 | W1: ف22 | X1: ف23 | Y1: ف24 | Z1: ف25 | AA1: ف26 | AB1: ف27 | AC1: ف28 | AD1: ف29 | AE1: ف30
A2: مفتاح الإجابة | B2: D | C2: C | D2: D | E2: B | F2: B | G2: B | H2: B | I2: C | J2: A | K2: D | L2: A | M2: C | N2: B | O2: D | P2: C | Q2: A | R2: A | S2: A | T2: D | U2: D | V2: C | W2: C | X2: C | Y2: B | Z2: C | AA2: B | AB2: B | AC2: B | AD2: C | AE2: C
A3: S001 | B3: C | C3: B | D3: B | E3: A | F3: A | G3: B | H3: B | I3: D | J3: C | K3: D | L3: A | M3: C | N3: D | O3: B | P3: D | Q3: D | R3: A | S3: C | T3: D | U3: C | V3: B | W3: D | X3: B | Y3: D | Z3: B | AA3: D | AB3: C | AC3: B | AD3: B | AE3: C
A4: S002 | B4: D | C4: C | D4: D | E4: D | F4: A | G4: A | H4: C | I4: C | J4: A | K4: D | L4: A | M4: C | N4: A | O4: C | P4: A | Q4: A | R4: A | S4: A | T4: B | U4: D | V4: C | W4: C | X4: C | Y4: A | Z4: B | AA4: D | AB4: B | AC4: B | AD4: C | AE4: A
A5: S003 | B5: B | C5: B | D5: C | E5: B | F5: C | G5: C | H5: B | I5: D | J5: A | K5: D | L5: A | M5: C | N5: A | O5: D | P5: D | Q5: A | R5: C | S5: B | T5: C | U5: A | V5: D | W5: B | X5: B | Y5: C | Z5: C | AA5: A | AB5: D | AC5: D | AD5: A | AE5: C
A6: S004 | B6: D | C6: C | D6: C | E6: B | F6: B | G6: B | H6: C | I6: C | J6: A | K6: D | L6: A | M6: C | N6: B | O6: D | P6: A | Q6: A | R6: A | S6: A | T6: D | U6: D | V6: C | W6: C | X6: C | Y6: B | Z6: C | AA6: D | AB6: C | AC6: B | AD6: C | AE6: C
A7: S005 | B7: B | C7: B | D7: B | E7: B | F7: B | G7: B | H7: C | I7: C | J7: A | K7: A | L7: A | M7: C | N7: B | O7: B | P7: A | Q7: A | R7: A | S7: D | T7: D | U7: D | V7: C | W7: C | X7: C | Y7: B | Z7: C | AA7: A | AB7: B | AC7: B | AD7: B | AE7: C
A8: S006 | B8: B | C8: B | D8: C | E8: B | F8: D | G8: C | H8: C | I8: D | J8: A | K8: C | L8: B | M8: C | N8: A | O8: D | P8: A | Q8: D | R8: A | S8: D | T8: B | U8: C | V8: C | W8: D | X8: C | Y8: A | Z8: C | AA8: C | AB8: C | AC8: C | AD8: C | AE8: C
A9: S007 | B9: C | C9: A | D9: A | E9: B | F9: D | G9: D | H9: B | I9: C | J9: A | K9: B | L9: A | M9: C | N9: B | O9: D | P9: C | Q9: A | R9: A | S9: C | T9: C | U9: C | V9: D | W9: A | X9: C | Y9: A | Z9: D | AA9: B | AB9: B | AC9: B | AD9: B | AE9: C
A10: S008 | B10: C | C10: C | D10: D | E10: B | F10: D | G10: A | H10: C | I10: C | J10: A | K10: B | L10: B | M10: C | N10: A | O10: D | P10: C | Q10: A | R10: C | S10: B | T10: A | U10: D | V10: C | W10: C | X10: C | Y10: D | Z10: C | AA10: B | AB10: A | AC10: B | AD10: A | AE10: C
A11: S009 | B11: D | C11: A | D11: C | E11: B | F11: A | G11: A | H11: C | I11: B | J11: A | K11: A | L11: B | M11: C | N11: A | O11: B | P11: A | Q11: A | R11: A | S11: B | T11: B | U11: C | V11: C | W11: D | X11: C | Y11: A | Z11: A | AA11: D | AB11: B | AC11: A | AD11: A | AE11: D
A12: S010 | B12: C | C12: C | D12: C | E12: B | F12: B | G12: A | H12: C | I12: B | J12: A | K12: D | L12: C | M12: C | N12: C | O12: D | P12: A | Q12: A | R12: A | S12: A | T12: D | U12: C | V12: C | W12: D | X12: B | Y12: C | Z12: C | AA12: B | AB12: B | AC12: D | AD12: A | AE12: A
... A152: S150 | B152: D | C152: B | D152: B | E152: B | F152: B | G152: A | H152: B | I152: C | J152: A | K152: D | L152: A | M152: C | N152: B | O152: D | P152: C | Q152: A | R152: A | S152: C | T152: C | U152: D | V152: C | W152: A | X152: B | Y152: A | Z152: C | AA152: D | AB152: A | AC152: B | AD152: C | AE152: C

Sheet التصحيح
A1: رقم الطالب | B1: ف1 | C1: ف2 | D1: ف3 | E1: ف4 | F1: ف5 | G1: ف6 | H1: ف7 | I1: ف8 | J1: ف9 | K1: ف10 | L1: ف11 | M1: ف12 | N1: ف13 | O1: ف14 | P1: ف15 | Q1: ف16 | R1: ف17 | S1: ف18 | T1: ف19 | U1: ف20 | V1: ف21 | W1: ف22 | X1: ف23 | Y1: ف24 | Z1: ف25 | AA1: ف26 | AB1: ف27 | AC1: ف28 | AD1: ف29 | AE1: ف30 | AF1: الدرجة الكلية
A2: الدرجة القصوى | B2: 1 | C2: 1 | D2: 1 | E2: 1 | F2: 1 | G2: 1 | H2: 1 | I2: 1 | J2: 1 | K2: 1 | L2: 1 | M2: 1 | N2: 1 | O2: 1 | P2: 1 | Q2: 1 | R2: 1 | S2: 1 | T2: 1 | U2: 1 | V2: 1 | W2: 1 | X2: 1 | Y2: 1 | Z2: 1 | AA2: 1 | AB2: 1 | AC2: 1 | AD2: 1 | AE2: 1 | AF2: =SUM(B2:AE2) -> 30
A3: =الإجابات!A3 -> S001 | B3: =IF(الإجابات!B3=الإجابات!B$2,1,0) -> 0 | C3: =IF(الإجابات!C3=الإجابات!C$2,1,0) -> 0 | D3: =IF(الإجابات!D3=الإجابات!D$2,1,0) -> 0 | E3: =IF(الإجابات!E3=الإجابات!E$2,1,0) -> 0 | F3: =IF(الإجابات!F3=الإجابات!F$2,1,0) -> 0 | G3: =IF(الإجابات!G3=الإجابات!G$2,1,0) -> 1 | H3: =IF(الإجابات!H3=الإجابات!H$2,1,0) -> 1 | I3: =IF(الإجابات!I3=الإجابات!I$2,1,0) -> 0 | ... AE3: =IF(الإجابات!AE3=الإجابات!AE$2,1,0) -> 1 | AF3: =SUM(B3:AE3) -> 9
A4: =الإجابات!A4 -> S002 | B4: =IF(الإجابات!B4=الإجابات!B$2,1,0) -> 1 | C4: =IF(الإجابات!C4=الإجابات!C$2,1,0) -> 1 | D4: =IF(الإجابات!D4=الإجابات!D$2,1,0) -> 1 | E4: =IF(الإجابات!E4=الإجابات!E$2,1,0) -> 0 | F4: =IF(الإجابات!F4=الإجابات!F$2,1,0) -> 0 | G4: =IF(الإجابات!G4=الإجابات!G$2,1,0) -> 0 | H4: =IF(الإجابات!H4=الإجابات!H$2,1,0) -> 0 | I4: =IF(الإجابات!I4=الإجابات!I$2,1,0) -> 1 | ... AE4: =IF(الإجابات!AE4=الإجابات!AE$2,1,0) -> 0 | AF4: =SUM(B4:AE4) -> 18
A5: =الإجابات!A5 -> S003 | B5: =IF(الإجابات!B5=الإجابات!B$2,1,0) -> 0 | C5: =IF(الإجابات!C5=الإجابات!C$2,1,0) -> 0 | D5: =IF(الإجابات!D5=الإجابات!D$2,1,0) -> 0 | E5: =IF(الإجابات!E5=الإجابات!E$2,1,0) -> 1 | F5: =IF(الإجابات!F5=الإجابات!F$2,1,0) -> 0 | G5: =IF(الإجابات!G5=الإجابات!G$2,1,0) -> 0 | H5: =IF(الإجابات!H5=الإجابات!H$2,1,0) -> 1 | I5: =IF(الإجابات!I5=الإجابات!I$2,1,0) -> 0 | ... AE5: =IF(الإجابات!AE5=الإجابات!AE$2,1,0) -> 1 | AF5: =SUM(B5:AE5) -> 10
A6: =الإجابات!A6 -> S004 | B6: =IF(الإجابات!B6=الإجابات!B$2,1,0) -> 1 | C6: =IF(الإجابات!C6=الإجابات!C$2,1,0) -> 1 | D6: =IF(الإجابات!D6=الإجابات!D$2,1,0) -> 0 | E6: =IF(الإجابات!E6=الإجابات!E$2,1,0) -> 1 | F6: =IF(الإجابات!F6=الإجابات!F$2,1,0) -> 1 | G6: =IF(الإجابات!G6=الإجابات!G$2,1,0) -> 1 | H6: =IF(الإجابات!H6=الإجابات!H$2,1,0) -> 0 | I6: =IF(الإجابات!I6=الإجابات!I$2,1,0) -> 1 | ... AE6: =IF(الإجابات!AE6=الإجابات!AE$2,1,0) -> 1 | AF6: =SUM(B6:AE6) -> 25
A7: =الإجابات!A7 -> S005 | B7: =IF(الإجابات!B7=الإجابات!B$2,1,0) -> 0 | C7: =IF(الإجابات!C7=الإجابات!C$2,1,0) -> 0 | D7: =IF(الإجابات!D7=الإجابات!D$2,1,0) -> 0 | E7: =IF(الإجابات!E7=الإجابات!E$2,1,0) -> 1 | F7: =IF(الإجابات!F7=الإجابات!F$2,1,0) -> 1 | G7: =IF(الإجابات!G7=الإجابات!G$2,1,0) -> 1 | H7: =IF(الإجابات!H7=الإجابات!H$2,1,0) -> 0 | I7: =IF(الإجابات!I7=الإجابات!I$2,1,0) -> 1 | ... AE7: =IF(الإجابات!AE7=الإجابات!AE$2,1,0) -> 1 | AF7: =SUM(B7:AE7) -> 20
A8: =الإجابات!A8 -> S006 | B8: =IF(الإجابات!B8=الإجابات!B$2,1,0) -> 0 | C8: =IF(الإجابات!C8=الإجابات!C$2,1,0) -> 0 | D8: =IF(الإجابات!D8=الإجابات!D$2,1,0) -> 0 | E8: =IF(الإجابات!E8=الإجابات!E$2,1,0) -> 1 | F8: =IF(الإجابات!F8=الإجابات!F$2,1,0) -> 0 | G8: =IF(الإجابات!G8=الإجابات!G$2,1,0) -> 0 | H8: =IF(الإجابات!H8=الإجابات!H$2,1,0) -> 0 | I8: =IF(الإجابات!I8=الإجابات!I$2,1,0) -> 0 | ... AE8: =IF(الإجابات!AE8=الإجابات!AE$2,1,0) -> 1 | AF8: =SUM(B8:AE8) -> 10
A9: =الإجابات!A9 -> S007 | B9: =IF(الإجابات!B9=الإجابات!B$2,1,0) -> 0 | C9: =IF(الإجابات!C9=الإجابات!C$2,1,0) -> 0 | D9: =IF(الإجابات!D9=الإجابات!D$2,1,0) -> 0 | E9: =IF(الإجابات!E9=الإجابات!E$2,1,0) -> 1 | F9: =IF(الإجابات!F9=الإجابات!F$2,1,0) -> 0 | G9: =IF(الإجابات!G9=الإجابات!G$2,1,0) -> 0 | H9: =IF(الإجابات!H9=الإجابات!H$2,1,0) -> 1 | I9: =IF(الإجابات!I9=الإجابات!I$2,1,0) -> 1 | ... AE9: =IF(الإجابات!AE9=الإجابات!AE$2,1,0) -> 1 | AF9: =SUM(B9:AE9) -> 16
A10: =الإجابات!A10 -> S008 | B10: =IF(الإجابات!B10=الإجابات!B$2,1,0) -> 0 | C10: =IF(الإجابات!C10=الإجابات!C$2,1,0) -> 1 | D10: =IF(الإجابات!D10=الإجابات!D$2,1,0) -> 1 | E10: =IF(الإجابات!E10=الإجابات!E$2,1,0) -> 1 | F10: =IF(الإجابات!F10=الإجابات!F$2,1,0) -> 0 | G10: =IF(الإجابات!G10=الإجابات!G$2,1,0) -> 0 | H10: =IF(الإجابات!H10=الإجابات!H$2,1,0) -> 0 | I10: =IF(الإجابات!I10=الإجابات!I$2,1,0) -> 1 | ... AE10: =IF(الإجابات!AE10=الإجابات!AE$2,1,0) -> 1 | AF10: =SUM(B10:AE10) -> 17
A11: =الإجابات!A11 -> S009 | B11: =IF(الإجابات!B11=الإجابات!B$2,1,0) -> 1 | C11: =IF(الإجابات!C11=الإجابات!C$2,1,0) -> 0 | D11: =IF(الإجابات!D11=الإجابات!D$2,1,0) -> 0 | E11: =IF(الإجابات!E11=الإجابات!E$2,1,0) -> 1 | F11: =IF(الإجابات!F11=الإجابات!F$2,1,0) -> 0 | G11: =IF(الإجابات!G11=الإجابات!G$2,1,0) -> 0 | H11: =IF(الإجابات!H11=الإجابات!H$2,1,0) -> 0 | I11: =IF(الإجابات!I11=الإجابات!I$2,1,0) -> 0 | ... AE11: =IF(الإجابات!AE11=الإجابات!AE$2,1,0) -> 0 | AF11: =SUM(B11:AE11) -> 9
A12: =الإجابات!A12 -> S010 | B12: =IF(الإجابات!B12=الإجابات!B$2,1,0) -> 0 | C12: =IF(الإجابات!C12=الإجابات!C$2,1,0) -> 1 | D12: =IF(الإجابات!D12=الإجابات!D$2,1,0) -> 0 | E12: =IF(الإجابات!E12=الإجابات!E$2,1,0) -> 1 | F12: =IF(الإجابات!F12=الإجابات!F$2,1,0) -> 1 | G12: =IF(الإجابات!G12=الإجابات!G$2,1,0) -> 0 | H12: =IF(الإجابات!H12=الإجابات!H$2,1,0) -> 0 | I12: =IF(الإجابات!I12=الإجابات!I$2,1,0) -> 0 | ... AE12: =IF(الإجابات!AE12=الإجابات!AE$2,1,0) -> 0 | AF12: =SUM(B12:AE12) -> 15
A13: =الإجابات!A13 -> S011 | B13: =IF(الإجابات!B13=الإجابات!B$2,1,0) -> 0 | C13: =IF(الإجابات!C13=الإجابات!C$2,1,0) -> 0 | D13: =IF(الإجابات!D13=الإجابات!D$2,1,0) -> 1 | E13: =IF(الإجابات!E13=الإجابات!E$2,1,0) -> 1 | F13: =IF(الإجابات!F13=الإجابات!F$2,1,0) -> 1 | G13: =IF(الإجابات!G13=الإجابات!G$2,1,0) -> 1 | H13: =IF(الإجابات!H13=الإجابات!H$2,1,0) -> 0 | I13: =IF(الإجابات!I13=الإجابات!I$2,1,0) -> 1 | ... AE13: =IF(الإجابات!AE13=الإجابات!AE$2,1,0) -> 1 | AF13: =SUM(B13:AE13) -> 21
A14: =الإجابات!A14 -> S012 | B14: =IF(الإجابات!B14=الإجابات!B$2,1,0) -> 1 | C14: =IF(الإجابات!C14=الإجابات!C$2,1,0) -> 1 | D14: =IF(الإجابات!D14=الإجابات!D$2,1,0) -> 0 | E14: =IF(الإجابات!E14=الإجابات!E$2,1,0) -> 1 | F14: =IF(الإجابات!F14=الإجابات!F$2,1,0) -> 0 | G14: =IF(الإجابات!G14=الإجابات!G$2,1,0) -> 1 | H14: =IF(الإجابات!H14=الإجابات!H$2,1,0) -> 0 | I14: =IF(الإجابات!I14=الإجابات!I$2,1,0) -> 1 | ... AE14: =IF(الإجابات!AE14=الإجابات!AE$2,1,0) -> 1 | AF14: =SUM(B14:AE14) -> 23
... A152: =الإجابات!A152 -> S150 | B152: =IF(الإجابات!B152=الإجابات!B$2,1,0) -> 1 | C152: =IF(الإجابات!C152=الإجابات!C$2,1,0) -> 0 | D152: =IF(الإجابات!D152=الإجابات!D$2,1,0) -> 0 | E152: =IF(الإجابات!E152=الإجابات!E$2,1,0) -> 1 | F152: =IF(الإجابات!F152=الإجابات!F$2,1,0) -> 1 | G152: =IF(الإجابات!G152=الإجابات!G$2,1,0) -> 0 | H152: =IF(الإجابات!H152=الإجابات!H$2,1,0) -> 1 | I152: =IF(الإجابات!I152=الإجابات!I$2,1,0) -> 1 | ... AE152: =IF(الإجابات!AE152=الإجابات!AE$2,1,0) -> 1 | AF152: =SUM(B152:AE152) -> 20

Sheet تحليل الفقرات
A1: المعاملات والمعايير
A2: عدد الطلبة | B2: =COUNT(التصحيح!$AF$3:$AF$152) -> 150
A3: نسبة كل فئة (عليا/دنيا) | B3: 0.27
A4: حجم الفئة | B4: =ROUND(B2*B3,0) -> 41
A5: حدّ الفئة العليا (درجة ≥) | B5: =LARGE(التصحيح!$AF$3:$AF$152,B4) -> 21
A6: حدّ الفئة الدنيا (درجة ≤) | B6: =SMALL(التصحيح!$AF$3:$AF$152,B4) -> 11
A7: عدد الفئة العليا فعلياً | B7: =COUNTIF(التصحيح!$AF$3:$AF$152,">="&B5) -> 45
A8: عدد الفئة الدنيا فعلياً | B8: =COUNTIF(التصحيح!$AF$3:$AF$152,"<="&B6) -> 45
A9: عدد الفقرات k | B9: 30
A10: تباين الدرجة الكلية | B10: =VARP(التصحيح!$AF$3:$AF$152) -> 40.955556
A11: الانحراف المعياري للدرجة الكلية | B11: =SQRT(B10) -> 6.3996528
A12: مجموع تباينات الفقرات | B12: =SUM(G21:G50) -> 6.5197333
A13: الحد الأدنى المقبول للصعوبة | B13: 0.2
A14: الحد الأعلى المقبول للصعوبة | B14: 0.9
A15: الحد الأدنى للتمييز المقبول | B15: 0.2
A16: حدّ التمييز الجيد | B16: 0.3
A17: الحد الأدنى لاختيار المموّه | B17: 0.05
A19: جدول تحليل الفقرات (كل القيم معادلات حية)
A20: الفقرة | B20: المفتاح | C20: الصعوبة p | D20: p الفئة العليا | E20: p الفئة الدنيا | F20: التمييز D | G20: تباين الفقرة | H20: ارتباط الفقرة بالكلية | I20: الارتباط المصحَّح | J20: ألفا إذا حُذفت | K20: % A | L20: % B | M20: % C | N20: % D | O20: أقل مموّه | P20: التوصية
A21: ف1 | B21: =الإجابات!B2 -> D | C21: =AVERAGE(التصحيح!$B$3:$B$152) -> 0.43333333 | D21: =SUMIF(التصحيح!$AF$3:$AF$152,">="&$B$5,التصحيح!$B$3:$B$152)/$B$7 -> 0.77777778 | E21: =SUMIF(التصحيح!$AF$3:$AF$152,"<="&$B$6,التصحيح!$B$3:$B$152)/$B$8 -> 0.13333333 | F21: =D21-E21 -> 0.64444444 | G21: =VARP(التصحيح!$B$3:$B$152) -> 0.24555556 | H21: =IF(G21=0,0,CORREL(التصحيح!$B$3:$B$152,التصحيح!$AF$3:$AF$152)) -> 0.54377334 | I21: =IF(G21=0,0,(H21*$B$11-SQRT(G21))/SQRT(G21+$B$10-2*H21*SQRT(G21)*$B$11)) -> 0.48572382 | J21: =($B$9-1)/($B$9-2)*(1-($B$12-G21)/($B$10+G21-2*H21*SQRT(G21)*$B$11)) -> 0.8635852 | K21: =COUNTIF(الإجابات!$B$3:$B$152,"A")/$B$2 -> 0.16 | L21: =COUNTIF(الإجابات!$B$3:$B$152,"B")/$B$2 -> 0.22 | M21: =COUNTIF(الإجابات!$B$3:$B$152,"C")/$B$2 -> 0.18666667 | N21: =COUNTIF(الإجابات!$B$3:$B$152,"D")/$B$2 -> 0.43333333 | O21: =MIN(IF(B21="A",1,K21),IF(B21="B",1,L21),IF(B21="C",1,M21),IF(B21="D",1,N21)) -> 0.16 | P21: =IF(I21<-0.1,"تمييز سالب: راجِع المفتاح فوراً",IF(OR(C21>$B$14,C21<$B$13),"صعوبة متطرفة: راجِع الصياغة أو المستوى",IF(I21<$B$15,"تمييز ضعيف: راجِع الصياغة والمموهات",IF(O21<$B$17,"مموّه غير فعّال: استبدله",IF(I21<$B$16,"مقبولة وقابلة للتحسين","جيدة"))))) -> جيدة
A22: ف2 | B22: =الإجابات!C2 -> C | C22: =AVERAGE(التصحيح!$C$3:$C$152) -> 0.40666667 | D22: =SUMIF(التصحيح!$AF$3:$AF$152,">="&$B$5,التصحيح!$C$3:$C$152)/$B$7 -> 0.75555556 | E22: =SUMIF(التصحيح!$AF$3:$AF$152,"<="&$B$6,التصحيح!$C$3:$C$152)/$B$8 -> 0.13333333 | F22: =D22-E22 -> 0.62222222 | G22: =VARP(التصحيح!$C$3:$C$152) -> 0.24128889 | H22: =IF(G22=0,0,CORREL(التصحيح!$C$3:$C$152,التصحيح!$AF$3:$AF$152)) -> 0.53131146 | I22: =IF(G22=0,0,(H22*$B$11-SQRT(G22))/SQRT(G22+$B$10-2*H22*SQRT(G22)*$B$11)) -> 0.47279584 | J22: =($B$9-1)/($B$9-2)*(1-($B$12-G22)/($B$10+G22-2*H22*SQRT(G22)*$B$11)) -> 0.86394215 | K22: =COUNTIF(الإجابات!$C$3:$C$152,"A")/$B$2 -> 0.19333333 | L22: =COUNTIF(الإجابات!$C$3:$C$152,"B")/$B$2 -> 0.23333333 | M22: =COUNTIF(الإجابات!$C$3:$C$152,"C")/$B$2 -> 0.40666667 | N22: =COUNTIF(الإجابات!$C$3:$C$152,"D")/$B$2 -> 0.16666667 | O22: =MIN(IF(B22="A",1,K22),IF(B22="B",1,L22),IF(B22="C",1,M22),IF(B22="D",1,N22)) -> 0.16666667 | P22: =IF(I22<-0.1,"تمييز سالب: راجِع المفتاح فوراً",IF(OR(C22>$B$14,C22<$B$13),"صعوبة متطرفة: راجِع الصياغة أو المستوى",IF(I22<$B$15,"تمييز ضعيف: راجِع الصياغة والمموهات",IF(O22<$B$17,"مموّه غير فعّال: استبدله",IF(I22<$B$16,"مقبولة وقابلة للتحسين","جيدة"))))) -> جيدة
A23: ف3 | B23: =الإجابات!D2 -> D | C23: =AVERAGE(التصحيح!$D$3:$D$152) -> 0.37333333 | D23: =SUMIF(التصحيح!$AF$3:$AF$152,">="&$B$5,التصحيح!$D$3:$D$152)/$B$7 -> 0.66666667 | E23: =SUMIF(التصحيح!$AF$3:$AF$152,"<="&$B$6,التصحيح!$D$3:$D$152)/$B$8 -> 0.24444444 | F23: =D23-E23 -> 0.42222222 | G23: =VARP(التصحيح!$D$3:$D$152) -> 0.23395556 | H23: =IF(G23=0,0,CORREL(التصحيح!$D$3:$D$152,التصحيح!$AF$3:$AF$152)) -> 0.41537736 | I23: =IF(G23=0,0,(H23*$B$11-SQRT(G23))/SQRT(G23+$B$10-2*H23*SQRT(G23)*$B$11)) -> 0.34992987 | J23: =($B$9-1)/($B$9-2)*(1-($B$12-G23)/($B$10+G23-2*H23*SQRT(G23)*$B$11)) -> 0.86713286 | K23: =COUNTIF(الإجابات!$D$3:$D$152,"A")/$B$2 -> 0.16666667 | L23: =COUNTIF(الإجابات!$D$3:$D$152,"B")/$B$2 -> 0.2 | M23: =COUNTIF(الإجابات!$D$3:$D$152,"C")/$B$2 -> 0.26 | N23: =COUNTIF(الإجابات!$D$3:$D$152,"D")/$B$2 -> 0.37333333 | O23: =MIN(IF(B23="A",1,K23),IF(B23="B",1,L23),IF(B23="C",1,M23),IF(B23="D",1,N23)) -> 0.16666667 | P23: =IF(I23<-0.1,"تمييز سالب: راجِع المفتاح فوراً",IF(OR(C23>$B$14,C23<$B$13),"صعوبة متطرفة: راجِع الصياغة أو المستوى",IF(I23<$B$15,"تمييز ضعيف: راجِع الصياغة والمموهات",IF(O23<$B$17,"مموّه غير فعّال: استبدله",IF(I23<$B$16,"مقبولة وقابلة للتحسين","جيدة"))))) -> جيدة
A24: ف4 | B24: =الإجابات!E2 -> B | C24: =AVERAGE(التصحيح!$E$3:$E$152) -> 0.76666667 | D24: =SUMIF(التصحيح!$AF$3:$AF$152,">="&$B$5,التصحيح!$E$3:$E$152)/$B$7 -> 1 | E24: =SUMIF(التصحيح!$AF$3:$AF$152,"<="&$B$6,التصحيح!$E$3:$E$152)/$B$8 -> 0.44444444 | F24: =D24-E24 -> 0.55555556 | G24: =VARP(التصحيح!$E$3:$E$152) -> 0.17888889 | H24: =IF(G24=0,0,CORREL(التصحيح!$E$3:$E$152,التصحيح!$AF$3:$AF$152)) -> 0.4958797 | I24: =IF(G24=0,0,(H24*$B$11-SQRT(G24))/SQRT(G24+$B$10-2*H24*SQRT(G24)*$B$11)) -> 0.4435722 | J24: =($B$9-1)/($B$9-2)*(1-($B$12-G24)/($B$10+G24-2*H24*SQRT(G24)*$B$11)) -> 0.86491316 | K24: =COUNTIF(الإجابات!$E$3:$E$152,"A")/$B$2 -> 0.053333333 | L24: =COUNTIF(الإجابات!$E$3:$E$152,"B")/$B$2 -> 0.76666667 | M24: =COUNTIF(الإجابات!$E$3:$E$152,"C")/$B$2 -> 0.06 | N24: =COUNTIF(الإجابات!$E$3:$E$152,"D")/$B$2 -> 0.12 | O24: =MIN(IF(B24="A",1,K24),IF(B24="B",1,L24),IF(B24="C",1,M24),IF(B24="D",1,N24)) -> 0.053333333 | P24: =IF(I24<-0.1,"تمييز سالب: راجِع المفتاح فوراً",IF(OR(C24>$B$14,C24<$B$13),"صعوبة متطرفة: راجِع الصياغة أو المستوى",IF(I24<$B$15,"تمييز ضعيف: راجِع الصياغة والمموهات",IF(O24<$B$17,"مموّه غير فعّال: استبدله",IF(I24<$B$16,"مقبولة وقابلة للتحسين","جيدة"))))) -> جيدة
A25: ف5 | B25: =الإجابات!F2 -> B | C25: =AVERAGE(التصحيح!$F$3:$F$152) -> 0.42666667 | D25: =SUMIF(التصحيح!$AF$3:$AF$152,">="&$B$5,التصحيح!$F$3:$F$152)/$B$7 -> 0.71111111 | E25: =SUMIF(التصحيح!$AF$3:$AF$152,"<="&$B$6,التصحيح!$F$3:$F$152)/$B$8 -> 0.13333333 | F25: =D25-E25 -> 0.57777778 | G25: =VARP(التصحيح!$F$3:$F$152) -> 0.24462222 | H25: =IF(G25=0,0,CORREL(التصحيح!$F$3:$F$152,التصحيح!$AF$3:$AF$152)) -> 0.50577438 | I25: =IF(G25=0,0,(H25*$B$11-SQRT(G25))/SQRT(G25+$B$10-2*H25*SQRT(G25)*$B$11)) -> 0.44485091 | J25: =($B$9-1)/($B$9-2)*(1-($B$12-G25)/($B$10+G25-2*H25*SQRT(G25)*$B$11)) -> 0.86467492 | K25: =COUNTIF(الإجابات!$F$3:$F$152,"A")/$B$2 -> 0.28666667 | L25: =COUNTIF(الإجابات!$F$3:$F$152,"B")/$B$2 -> 0.42666667 | M25: =COUNTIF(الإجابات!$F$3:$F$152,"C")/$B$2 -> 0.17333333 | N25: =COUNTIF(الإجابات!$F$3:$F$152,"D")/$B$2 -> 0.11333333 | O25: =MIN(IF(B25="A",1,K25),IF(B25="B",1,L25),IF(B25="C",1,M25),IF(B25="D",1,N25)) -> 0.11333333 | P25: =IF(I25<-0.1,"تمييز سالب: راجِع المفتاح فوراً",IF(OR(C25>$B$14,C25<$B$13),"صعوبة متطرفة: راجِع الصياغة أو المستوى",IF(I25<$B$15,"تمييز ضعيف: راجِع الصياغة والمموهات",IF(O25<$B$17,"مموّه غير فعّال: استبدله",IF(I25<$B$16,"مقبولة وقابلة للتحسين","جيدة"))))) -> جيدة
A26: ف6 | B26: =الإجابات!G2 -> B | C26: =AVERAGE(التصحيح!$G$3:$G$152) -> 0.47333333 | D26: =SUMIF(التصحيح!$AF$3:$AF$152,">="&$B$5,التصحيح!$G$3:$G$152)/$B$7 -> 0.82222222 | E26: =SUMIF(التصحيح!$AF$3:$AF$152,"<="&$B$6,التصحيح!$G$3:$G$152)/$B$8 -> 0.22222222 | F26: =D26-E26 -> 0.6 | G26: =VARP(التصحيح!$G$3:$G$152) -> 0.24928889 | H26: =IF(G26=0,0,CORREL(التصحيح!$G$3:$G$152,التصحيح!$AF$3:$AF$152)) -> 0.48168387 | I26: =IF(G26=0,0,(H26*$B$11-SQRT(G26))/SQRT(G26+$B$10-2*H26*SQRT(G26)*$B$11)) -> 0.41837356 | J26: =($B$9-1)/($B$9-2)*(1-($B$12-G26)/($B$10+G26-2*H26*SQRT(G26)*$B$11)) -> 0.86537691 | K26: =COUNTIF(الإجابات!$G$3:$G$152,"A")/$B$2 -> 0.22666667 | L26: =COUNTIF(الإجابات!$G$3:$G$152,"B")/$B$2 -> 0.47333333 | M26: =COUNTIF(الإجابات!$G$3:$G$152,"C")/$B$2 -> 0.12666667 | N26: =COUNTIF(الإجابات!$G$3:$G$152,"D")/$B$2 -> 0.17333333 | O26: =MIN(IF(B26="A",1,K26),IF(B26="B",1,L26),IF(B26="C",1,M26),IF(B26="D",1,N26)) -> 0.12666667 | P26: =IF(I26<-0.1,"تمييز سالب: راجِع المفتاح فوراً",IF(OR(C26>$B$14,C26<$B$13),"صعوبة متطرفة: راجِع الصياغة أو المستوى",IF(I26<$B$15,"تمييز ضعيف: راجِع الصياغة والمموهات",IF(O26<$B$17,"مموّه غير فعّال: استبدله",IF(I26<$B$16,"مقبولة وقابلة للتحسين","جيدة"))))) -> جيدة
A27: ف7 | B27: =الإجابات!H2 -> B | C27: =AVERAGE(التصحيح!$H$3:$H$152) -> 0.25333333 | D27: =SUMIF(التصحيح!$AF$3:$AF$152,">="&$B$5,التصحيح!$H$3:$H$152)/$B$7 -> 0.044444444 | E27: =SUMIF(التصحيح!$AF$3:$AF$152,"<="&$B$6,التصحيح!$H$3:$H$152)/$B$8 -> 0.44444444 | F27: =D27-E27 -> -0.4 | G27: =VARP(التصحيح!$H$3:$H$152) -> 0.18915556 | H27: =IF(G27=0,0,CORREL(التصحيح!$H$3:$H$152,التصحيح!$AF$3:$AF$152)) -> -0.37301334 | I27: =IF(G27=0,0,(H27*$B$11-SQRT(G27))/SQRT(G27+$B$10-2*H27*SQRT(G27)*$B$11)) -> -0.4292601 | J27: =($B$9-1)/($B$9-2)*(1-($B$12-G27)/($B$10+G27-2*H27*SQRT(G27)*$B$11)) -> 0.88401381 | K27: =COUNTIF(الإجابات!$H$3:$H$152,"A")/$B$2 -> 0.033333333 | L27: =COUNTIF(الإجابات!$H$3:$H$152,"B")/$B$2 -> 0.25333333 | M27: =COUNTIF(الإجابات!$H$3:$H$152,"C")/$B$2 -> 0.68 | N27: =COUNTIF(الإجابات!$H$3:$H$152,"D")/$B$2 -> 0.033333333 | O27: =MIN(IF(B27="A",1,K27),IF(B27="B",1,L27),IF(B27="C",1,M27),IF(B27="D",1,N27)) -> 0.033333333 | P27: =IF(I27<-0.1,"تمييز سالب: راجِع المفتاح فوراً",IF(OR(C27>$B$14,C27<$B$13),"صعوبة متطرفة: راجِع الصياغة أو المستوى",IF(I27<$B$15,"تمييز ضعيف: راجِع الصياغة والمموهات",IF(O27<$B$17,"مموّه غير فعّال: استبدله",IF(I27<$B$16,"مقبولة وقابلة للتحسين","جيدة"))))) -> تمييز سالب: راجِع المفتاح فوراً
A28: ف8 | B28: =الإجابات!I2 -> C | C28: =AVERAGE(التصحيح!$I$3:$I$152) -> 0.66 | D28: =SUMIF(التصحيح!$AF$3:$AF$152,">="&$B$5,التصحيح!$I$3:$I$152)/$B$7 -> 0.97777778 | E28: =SUMIF(التصحيح!$AF$3:$AF$152,"<="&$B$6,التصحيح!$I$3:$I$152)/$B$8 -> 0.26666667 | F28: =D28-E28 -> 0.71111111 | G28: =VARP(التصحيح!$I$3:$I$152) -> 0.2244 | H28: =IF(G28=0,0,CORREL(التصحيح!$I$3:$I$152,التصحيح!$AF$3:$AF$152)) -> 0.61750149 | I28: =IF(G28=0,0,(H28*$B$11-SQRT(G28))/SQRT(G28+$B$10-2*H28*SQRT(G28)*$B$11)) -> 0.56845474 | J28: =($B$9-1)/($B$9-2)*(1-($B$12-G28)/($B$10+G28-2*H28*SQRT(G28)*$B$11)) -> 0.86154572 | K28: =COUNTIF(الإجابات!$I$3:$I$152,"A")/$B$2 -> 0.13333333 | L28: =COUNTIF(الإجابات!$I$3:$I$152,"B")/$B$2 -> 0.1 | M28: =COUNTIF(الإجابات!$I$3:$I$152,"C")/$B$2 -> 0.66 | N28: =COUNTIF(الإجابات!$I$3:$I$152,"D")/$B$2 -> 0.10666667 | O28: =MIN(IF(B28="A",1,K28),IF(B28="B",1,L28),IF(B28="C",1,M28),IF(B28="D",1,N28)) -> 0.1 | P28: =IF(I28<-0.1,"تمييز سالب: راجِع المفتاح فوراً",IF(OR(C28>$B$14,C28<$B$13),"صعوبة متطرفة: راجِع الصياغة أو المستوى",IF(I28<$B$15,"تمييز ضعيف: راجِع الصياغة والمموهات",IF(O28<$B$17,"مموّه غير فعّال: استبدله",IF(I28<$B$16,"مقبولة وقابلة للتحسين","جيدة"))))) -> جيدة
A29: ف9 | B29: =الإجابات!J2 -> A | C29: =AVERAGE(التصحيح!$J$3:$J$152) -> 0.90666667 | D29: =SUMIF(التصحيح!$AF$3:$AF$152,">="&$B$5,التصحيح!$J$3:$J$152)/$B$7 -> 1 | E29: =SUMIF(التصحيح!$AF$3:$AF$152,"<="&$B$6,التصحيح!$J$3:$J$152)/$B$8 -> 0.75555556 | F29: =D29-E29 -> 0.24444444 | G29: =VARP(التصحيح!$J$3:$J$152) -> 0.084622222 | H29: =IF(G29=0,0,CORREL(التصحيح!$J$3:$J$152,التصحيح!$AF$3:$AF$152)) -> 0.34210943 | I29: =IF(G29=0,0,(H29*$B$11-SQRT(G29))/SQRT(G29+$B$10-2*H29*SQRT(G29)*$B$11)) -> 0.30105683 | J29: =($B$9-1)/($B$9-2)*(1-($B$12-G29)/($B$10+G29-2*H29*SQRT(G29)*$B$11)) -> 0.86811208 | K29: =COUNTIF(الإجابات!$J$3:$J$152,"A")/$B$2 -> 0.90666667 | L29: =COUNTIF(الإجابات!$J$3:$J$152,"B")/$B$2 -> 0.04 | M29: =COUNTIF(الإجابات!$J$3:$J$152,"C")/$B$2 -> 0.033333333 | N29: =COUNTIF(الإجابات!$J$3:$J$152,"D")/$B$2 -> 0.02 | O29: =MIN(IF(B29="A",1,K29),IF(B29="B",1,L29),IF(B29="C",1,M29),IF(B29="D",1,N29)) -> 0.02 | P29: =IF(I29<-0.1,"تمييز سالب: راجِع المفتاح فوراً",IF(OR(C29>$B$14,C29<$B$13),"صعوبة متطرفة: راجِع الصياغة أو المستوى",IF(I29<$B$15,"تمييز ضعيف: راجِع الصياغة والمموهات",IF(O29<$B$17,"مموّه غير فعّال: استبدله",IF(I29<$B$16,"مقبولة وقابلة للتحسين","جيدة"))))) -> صعوبة متطرفة: راجِع الصياغة أو المستوى
A30: ف10 | B30: =الإجابات!K2 -> D | C30: =AVERAGE(التصحيح!$K$3:$K$152) -> 0.49333333 | D30: =SUMIF(التصحيح!$AF$3:$AF$152,">="&$B$5,التصحيح!$K$3:$K$152)/$B$7 -> 0.93333333 | E30: =SUMIF(التصحيح!$AF$3:$AF$152,"<="&$B$6,التصحيح!$K$3:$K$152)/$B$8 -> 0.17777778 | F30: =D30-E30 -> 0.75555556 | G30: =VARP(التصحيح!$K$3:$K$152) -> 0.24995556 | H30: =IF(G30=0,0,CORREL(التصحيح!$K$3:$K$152,التصحيح!$AF$3:$AF$152)) -> 0.62814547 | I30: =IF(G30=0,0,(H30*$B$11-SQRT(G30))/SQRT(G30+$B$10-2*H30*SQRT(G30)*$B$11)) -> 0.57722872 | J30: =($B$9-1)/($B$9-2)*(1-($B$12-G30)/($B$10+G30-2*H30*SQRT(G30)*$B$11)) -> 0.86108657 | K30: =COUNTIF(الإجابات!$K$3:$K$152,"A")/$B$2 -> 0.18666667 | L30: =COUNTIF(الإجابات!$K$3:$K$152,"B")/$B$2 -> 0.2 | M30: =COUNTIF(الإجابات!$K$3:$K$152,"C")/$B$2 -> 0.12 | N30: =COUNTIF(الإجابات!$K$3:$K$152,"D")/$B$2 -> 0.49333333 | O30: =MIN(IF(B30="A",1,K30),IF(B30="B",1,L30),IF(B30="C",1,M30),IF(B30="D",1,N30)) -> 0.12 | P30: =IF(I30<-0.1,"تمييز سالب: راجِع المفتاح فوراً",IF(OR(C30>$B$14,C30<$B$13),"صعوبة متطرفة: راجِع الصياغة أو المستوى",IF(I30<$B$15,"تمييز ضعيف: راجِع الصياغة والمموهات",IF(O30<$B$17,"مموّه غير فعّال: استبدله",IF(I30<$B$16,"مقبولة وقابلة للتحسين","جيدة"))))) -> جيدة
A31: ف11 | B31: =الإجابات!L2 -> A | C31: =AVERAGE(التصحيح!$L$3:$L$152) -> 0.62 | D31: =SUMIF(التصحيح!$AF$3:$AF$152,">="&$B$5,التصحيح!$L$3:$L$152)/$B$7 -> 0.93333333 | E31: =SUMIF(التصحيح!$AF$3:$AF$152,"<="&$B$6,التصحيح!$L$3:$L$152)/$B$8 -> 0.22222222 | F31: =D31-E31 -> 0.71111111 | G31: =VARP(التصحيح!$L$3:$L$152) -> 0.2356 | H31: =IF(G31=0,0,CORREL(التصحيح!$L$3:$L$152,التصحيح!$AF$3:$AF$152)) -> 0.58075436 | I31: =IF(G31=0,0,(H31*$B$11-SQRT(G31))/SQRT(G31+$B$10-2*H31*SQRT(G31)*$B$11)) -> 0.52707518 | J31: =($B$9-1)/($B$9-2)*(1-($B$12-G31)/($B$10+G31-2*H31*SQRT(G31)*$B$11)) -> 0.86253653 | K31: =COUNTIF(الإجابات!$L$3:$L$152,"A")/$B$2 -> 0.62 | L31: =COUNTIF(الإجابات!$L$3:$L$152,"B")/$B$2 -> 0.21333333 | M31: =COUNTIF(الإجابات!$L$3:$L$152,"C")/$B$2 -> 0.13333333 | N31: =COUNTIF(الإجابات!$L$3:$L$152,"D")/$B$2 -> 0.033333333 | O31: =MIN(IF(B31="A",1,K31),IF(B31="B",1,L31),IF(B31="C",1,M31),IF(B31="D",1,N31)) -> 0.033333333 | P31: =IF(I31<-0.1,"تمييز سالب: راجِع المفتاح فوراً",IF(OR(C31>$B$14,C31<$B$13),"صعوبة متطرفة: راجِع الصياغة أو المستوى",IF(I31<$B$15,"تمييز ضعيف: راجِع الصياغة والمموهات",IF(O31<$B$17,"مموّه غير فعّال: استبدله",IF(I31<$B$16,"مقبولة وقابلة للتحسين","جيدة"))))) -> مموّه غير فعّال: استبدله
A32: ف12 | B32: =الإجابات!M2 -> C | C32: =AVERAGE(التصحيح!$M$3:$M$152) -> 0.97333333 | D32: =SUMIF(التصحيح!$AF$3:$AF$152,">="&$B$5,التصحيح!$M$3:$M$152)/$B$7 -> 1 | E32: =SUMIF(التصحيح!$AF$3:$AF$152,"<="&$B$6,التصحيح!$M$3:$M$152)/$B$8 -> 0.91111111 | F32: =D32-E32 -> 0.088888889 | G32: =VARP(التصحيح!$M$3:$M$152) -> 0.025955556 | H32: =IF(G32=0,0,CORREL(التصحيح!$M$3:$M$152,التصحيح!$AF$3:$AF$152)) -> 0.24484669 | I32: =IF(G32=0,0,(H32*$B$11-SQRT(G32))/SQRT(G32+$B$10-2*H32*SQRT(G32)*$B$11)) -> 0.22096811 | J32: =($B$9-1)/($B$9-2)*(1-($B$12-G32)/($B$10+G32-2*H32*SQRT(G32)*$B$11)) -> 0.86955174 | K32: =COUNTIF(الإجابات!$M$3:$M$152,"A")/$B$2 -> 0.013333333 | L32: =COUNTIF(الإجابات!$M$3:$M$152,"B")/$B$2 -> 0.0066666667 | M32: =COUNTIF(الإجابات!$M$3:$M$152,"C")/$B$2 -> 0.97333333 | N32: =COUNTIF(الإجابات!$M$3:$M$152,"D")/$B$2 -> 0.0066666667 | O32: =MIN(IF(B32="A",1,K32),IF(B32="B",1,L32),IF(B32="C",1,M32),IF(B32="D",1,N32)) -> 0.0066666667 | P32: =IF(I32<-0.1,"تمييز سالب: راجِع المفتاح فوراً",IF(OR(C32>$B$14,C32<$B$13),"صعوبة متطرفة: راجِع الصياغة أو المستوى",IF(I32<$B$15,"تمييز ضعيف: راجِع الصياغة والمموهات",IF(O32<$B$17,"مموّه غير فعّال: استبدله",IF(I32<$B$16,"مقبولة وقابلة للتحسين","جيدة"))))) -> صعوبة متطرفة: راجِع الصياغة أو المستوى
A33: ف13 | B33: =الإجابات!N2 -> B | C33: =AVERAGE(التصحيح!$N$3:$N$152) -> 0.41333333 | D33: =SUMIF(التصحيح!$AF$3:$AF$152,">="&$B$5,التصحيح!$N$3:$N$152)/$B$7 -> 0.84444444 | E33: =SUMIF(التصحيح!$AF$3:$AF$152,"<="&$B$6,التصحيح!$N$3:$N$152)/$B$8 -> 0.044444444 | F33: =D33-E33 -> 0.8 | G33: =VARP(التصحيح!$N$3:$N$152) -> 0.24248889 | H33: =IF(G33=0,0,CORREL(التصحيح!$N$3:$N$152,التصحيح!$AF$3:$AF$152)) -> 0.65593603 | I33: =IF(G33=0,0,(H33*$B$11-SQRT(G33))/SQRT(G33+$B$10-2*H33*SQRT(G33)*$B$11)) -> 0.60862801 | J33: =($B$9-1)/($B$9-2)*(1-($B$12-G33)/($B$10+G33-2*H33*SQRT(G33)*$B$11)) -> 0.86030249 | K33: =COUNTIF(الإجابات!$N$3:$N$152,"A")/$B$2 -> 0.26666667 | L33: =COUNTIF(الإجابات!$N$3:$N$152,"B")/$B$2 -> 0.41333333 | M33: =COUNTIF(الإجابات!$N$3:$N$152,"C")/$B$2 -> 0.18 | N33: =COUNTIF(الإجابات!$N$3:$N$152,"D")/$B$2 -> 0.14 | O33: =MIN(IF(B33="A",1,K33),IF(B33="B",1,L33),IF(B33="C",1,M33),IF(B33="D",1,N33)) -> 0.14 | P33: =IF(I33<-0.1,"تمييز سالب: راجِع المفتاح فوراً",IF(OR(C33>$B$14,C33<$B$13),"صعوبة متطرفة: راجِع الصياغة أو المستوى",IF(I33<$B$15,"تمييز ضعيف: راجِع الصياغة والمموهات",IF(O33<$B$17,"مموّه غير فعّال: استبدله",IF(I33<$B$16,"مقبولة وقابلة للتحسين","جيدة"))))) -> جيدة
A34: ف14 | B34: =الإجابات!O2 -> D | C34: =AVERAGE(التصحيح!$O$3:$O$152) -> 0.62 | D34: =SUMIF(التصحيح!$AF$3:$AF$152,">="&$B$5,التصحيح!$O$3:$O$152)/$B$7 -> 0.91111111 | E34: =SUMIF(التصحيح!$AF$3:$AF$152,"<="&$B$6,التصحيح!$O$3:$O$152)/$B$8 -> 0.35555556 | F34: =D34-E34 -> 0.55555556 | G34: =VARP(التصحيح!$O$3:$O$152) -> 0.2356 | H34: =IF(G34=0,0,CORREL(التصحيح!$O$3:$O$152,التصحيح!$AF$3:$AF$152)) -> 0.48203041 | I34: =IF(G34=0,0,(H34*$B$11-SQRT(G34))/SQRT(G34+$B$10-2*H34*SQRT(G34)*$B$11)) -> 0.42059898 | J34: =($B$9-1)/($B$9-2)*(1-($B$12-G34)/($B$10+G34-2*H34*SQRT(G34)*$B$11)) -> 0.8653173 | K34: =COUNTIF(الإجابات!$O$3:$O$152,"A")/$B$2 -> 0.08 | L34: =COUNTIF(الإجابات!$O$3:$O$152,"B")/$B$2 -> 0.18 | M34: =COUNTIF(الإجابات!$O$3:$O$152,"C")/$B$2 -> 0.12 | N34: =COUNTIF(الإجابات!$O$3:$O$152,"D")/$B$2 -> 0.62 | O34: =MIN(IF(B34="A",1,K34),IF(B34="B",1,L34),IF(B34="C",1,M34),IF(B34="D",1,N34)) -> 0.08 | P34: =IF(I34<-0.1,"تمييز سالب: راجِع المفتاح فوراً",IF(OR(C34>$B$14,C34<$B$13),"صعوبة متطرفة: راجِع الصياغة أو المستوى",IF(I34<$B$15,"تمييز ضعيف: راجِع الصياغة والمموهات",IF(O34<$B$17,"مموّه غير فعّال: استبدله",IF(I34<$B$16,"مقبولة وقابلة للتحسين","جيدة"))))) -> جيدة
A35: ف15 | B35: =الإجابات!P2 -> C | C35: =AVERAGE(التصحيح!$P$3:$P$152) -> 0.4 | D35: =SUMIF(التصحيح!$AF$3:$AF$152,">="&$B$5,التصحيح!$P$3:$P$152)/$B$7 -> 0.42222222 | E35: =SUMIF(التصحيح!$AF$3:$AF$152,"<="&$B$6,التصحيح!$P$3:$P$152)/$B$8 -> 0.15555556 | F35: =D35-E35 -> 0.26666667 | G35: =VARP(التصحيح!$P$3:$P$152) -> 0.24 | H35: =IF(G35=0,0,CORREL(التصحيح!$P$3:$P$152,التصحيح!$AF$3:$AF$152)) -> 0.22114649 | I35: =IF(G35=0,0,(H35*$B$11-SQRT(G35))/SQRT(G35+$B$10-2*H35*SQRT(G35)*$B$11)) -> 0.14666349 | J35: =($B$9-1)/($B$9-2)*(1-($B$12-G35)/($B$10+G35-2*H35*SQRT(G35)*$B$11)) -> 0.87233345 | K35: =COUNTIF(الإجابات!$P$3:$P$152,"A")/$B$2 -> 0.37333333 | L35: =COUNTIF(الإجابات!$P$3:$P$152,"B")/$B$2 -> 0.08 | M35: =COUNTIF(الإجابات!$P$3:$P$152,"C")/$B$2 -> 0.4 | N35: =COUNTIF(الإجابات!$P$3:$P$152,"D")/$B$2 -> 0.14666667 | O35: =MIN(IF(B35="A",1,K35),IF(B35="B",1,L35),IF(B35="C",1,M35),IF(B35="D",1,N35)) -> 0.08 | P35: =IF(I35<-0.1,"تمييز سالب: راجِع المفتاح فوراً",IF(OR(C35>$B$14,C35<$B$13),"صعوبة متطرفة: راجِع الصياغة أو المستوى",IF(I35<$B$15,"تمييز ضعيف: راجِع الصياغة والمموهات",IF(O35<$B$17,"مموّه غير فعّال: استبدله",IF(I35<$B$16,"مقبولة وقابلة للتحسين","جيدة"))))) -> تمييز ضعيف: راجِع الصياغة والمموهات
A36: ف16 | B36: =الإجابات!Q2 -> A | C36: =AVERAGE(التصحيح!$Q$3:$Q$152) -> 0.84 | D36: =SUMIF(التصحيح!$AF$3:$AF$152,">="&$B$5,التصحيح!$Q$3:$Q$152)/$B$7 -> 1 | E36: =SUMIF(التصحيح!$AF$3:$AF$152,"<="&$B$6,التصحيح!$Q$3:$Q$152)/$B$8 -> 0.57777778 | F36: =D36-E36 -> 0.42222222 | G36: =VARP(التصحيح!$Q$3:$Q$152) -> 0.1344 | H36: =IF(G36=0,0,CORREL(التصحيح!$Q$3:$Q$152,التصحيح!$AF$3:$AF$152)) -> 0.46373818 | I36: =IF(G36=0,0,(H36*$B$11-SQRT(G36))/SQRT(G36+$B$10-2*H36*SQRT(G36)*$B$11)) -> 0.41697875 | J36: =($B$9-1)/($B$9-2)*(1-($B$12-G36)/($B$10+G36-2*H36*SQRT(G36)*$B$11)) -> 0.86576546 | K36: =COUNTIF(الإجابات!$Q$3:$Q$152,"A")/$B$2 -> 0.84 | L36: =COUNTIF(الإجابات!$Q$3:$Q$152,"B")/$B$2 -> 0.053333333 | M36: =COUNTIF(الإجابات!$Q$3:$Q$152,"C")/$B$2 -> 0.053333333 | N36: =COUNTIF(الإجابات!$Q$3:$Q$152,"D")/$B$2 -> 0.053333333 | O36: =MIN(IF(B36="A",1,K36),IF(B36="B",1,L36),IF(B36="C",1,M36),IF(B36="D",1,N36)) -> 0.053333333 | P36: =IF(I36<-0.1,"تمييز سالب: راجِع المفتاح فوراً",IF(OR(C36>$B$14,C36<$B$13),"صعوبة متطرفة: راجِع الصياغة أو المستوى",IF(I36<$B$15,"تمييز ضعيف: راجِع الصياغة والمموهات",IF(O36<$B$17,"مموّه غير فعّال: استبدله",IF(I36<$B$16,"مقبولة وقابلة للتحسين","جيدة"))))) -> جيدة
A37: ف17 | B37: =الإجابات!R2 -> A | C37: =AVERAGE(التصحيح!$R$3:$R$152) -> 0.86666667 | D37: =SUMIF(التصحيح!$AF$3:$AF$152,">="&$B$5,التصحيح!$R$3:$R$152)/$B$7 -> 1 | E37: =SUMIF(التصحيح!$AF$3:$AF$152,"<="&$B$6,التصحيح!$R$3:$R$152)/$B$8 -> 0.6 | F37: =D37-E37 -> 0.4 | G37: =VARP(التصحيح!$R$3:$R$152) -> 0.11555556 | H37: =IF(G37=0,0,CORREL(التصحيح!$R$3:$R$152,التصحيح!$AF$3:$AF$152)) -> 0.4484357 | I37: =IF(G37=0,0,(H37*$B$11-SQRT(G37))/SQRT(G37+$B$10-2*H37*SQRT(G37)*$B$11)) -> 0.40448611 | J37: =($B$9-1)/($B$9-2)*(1-($B$12-G37)/($B$10+G37-2*H37*SQRT(G37)*$B$11)) -> 0.86616167 | K37: =COUNTIF(الإجابات!$R$3:$R$152,"A")/$B$2 -> 0.86666667 | L37: =COUNTIF(الإجابات!$R$3:$R$152,"B")/$B$2 -> 0.066666667 | M37: =COUNTIF(الإجابات!$R$3:$R$152,"C")/$B$2 -> 0.046666667 | N37: =COUNTIF(الإجابات!$R$3:$R$152,"D")/$B$2 -> 0.02 | O37: =MIN(IF(B37="A",1,K37),IF(B37="B",1,L37),IF(B37="C",1,M37),IF(B37="D",1,N37)) -> 0.02 | P37: =IF(I37<-0.1,"تمييز سالب: راجِع المفتاح فوراً",IF(OR(C37>$B$14,C37<$B$13),"صعوبة متطرفة: راجِع الصياغة أو المستوى",IF(I37<$B$15,"تمييز ضعيف: راجِع الصياغة والمموهات",IF(O37<$B$17,"مموّه غير فعّال: استبدله",IF(I37<$B$16,"مقبولة وقابلة للتحسين","جيدة"))))) -> مموّه غير فعّال: استبدله
A38: ف18 | B38: =الإجابات!S2 -> A | C38: =AVERAGE(التصحيح!$S$3:$S$152) -> 0.24 | D38: =SUMIF(التصحيح!$AF$3:$AF$152,">="&$B$5,التصحيح!$S$3:$S$152)/$B$7 -> 0.28888889 | E38: =SUMIF(التصحيح!$AF$3:$AF$152,"<="&$B$6,التصحيح!$S$3:$S$152)/$B$8 -> 0.2 | F38: =D38-E38 -> 0.088888889 | G38: =VARP(التصحيح!$S$3:$S$152) -> 0.1824 | H38: =IF(G38=0,0,CORREL(التصحيح!$S$3:$S$152,التصحيح!$AF$3:$AF$152)) -> 0.098054147 | I38: =IF(G38=0,0,(H38*$B$11-SQRT(G38))/SQRT(G38+$B$10-2*H38*SQRT(G38)*$B$11)) -> 0.031454868 | J38: =($B$9-1)/($B$9-2)*(1-($B$12-G38)/($B$10+G38-2*H38*SQRT(G38)*$B$11)) -> 0.87405541 | K38: =COUNTIF(الإجابات!$S$3:$S$152,"A")/$B$2 -> 0.24 | L38: =COUNTIF(الإجابات!$S$3:$S$152,"B")/$B$2 -> 0.25333333 | M38: =COUNTIF(الإجابات!$S$3:$S$152,"C")/$B$2 -> 0.26666667 | N38: =COUNTIF(الإجابات!$S$3:$S$152,"D")/$B$2 -> 0.24 | O38: =MIN(IF(B38="A",1,K38),IF(B38="B",1,L38),IF(B38="C",1,M38),IF(B38="D",1,N38)) -> 0.24 | P38: =IF(I38<-0.1,"تمييز سالب: راجِع المفتاح فوراً",IF(OR(C38>$B$14,C38<$B$13),"صعوبة متطرفة: راجِع الصياغة أو المستوى",IF(I38<$B$15,"تمييز ضعيف: راجِع الصياغة والمموهات",IF(O38<$B$17,"مموّه غير فعّال: استبدله",IF(I38<$B$16,"مقبولة وقابلة للتحسين","جيدة"))))) -> تمييز ضعيف: راجِع الصياغة والمموهات
A39: ف19 | B39: =الإجابات!T2 -> D | C39: =AVERAGE(التصحيح!$T$3:$T$152) -> 0.56666667 | D39: =SUMIF(التصحيح!$AF$3:$AF$152,">="&$B$5,التصحيح!$T$3:$T$152)/$B$7 -> 0.8 | E39: =SUMIF(التصحيح!$AF$3:$AF$152,"<="&$B$6,التصحيح!$T$3:$T$152)/$B$8 -> 0.35555556 | F39: =D39-E39 -> 0.44444444 | G39: =VARP(التصحيح!$T$3:$T$152) -> 0.24555556 | H39: =IF(G39=0,0,CORREL(التصحيح!$T$3:$T$152,التصحيح!$AF$3:$AF$152)) -> 0.38120193 | I39: =IF(G39=0,0,(H39*$B$11-SQRT(G39))/SQRT(G39+$B$10-2*H39*SQRT(G39)*$B$11)) -> 0.31216136 | J39: =($B$9-1)/($B$9-2)*(1-($B$12-G39)/($B$10+G39-2*H39*SQRT(G39)*$B$11)) -> 0.8681615 | K39: =COUNTIF(الإجابات!$T$3:$T$152,"A")/$B$2 -> 0.15333333 | L39: =COUNTIF(الإجابات!$T$3:$T$152,"B")/$B$2 -> 0.1 | M39: =COUNTIF(الإجابات!$T$3:$T$152,"C")/$B$2 -> 0.18 | N39: =COUNTIF(الإجابات!$T$3:$T$152,"D")/$B$2 -> 0.56666667 | O39: =MIN(IF(B39="A",1,K39),IF(B39="B",1,L39),IF(B39="C",1,M39),IF(B39="D",1,N39)) -> 0.1 | P39: =IF(I39<-0.1,"تمييز سالب: راجِع المفتاح فوراً",IF(OR(C39>$B$14,C39<$B$13),"صعوبة متطرفة: راجِع الصياغة أو المستوى",IF(I39<$B$15,"تمييز ضعيف: راجِع الصياغة والمموهات",IF(O39<$B$17,"مموّه غير فعّال: استبدله",IF(I39<$B$16,"مقبولة وقابلة للتحسين","جيدة"))))) -> جيدة
A40: ف20 | B40: =الإجابات!U2 -> D | C40: =AVERAGE(التصحيح!$U$3:$U$152) -> 0.52 | D40: =SUMIF(التصحيح!$AF$3:$AF$152,">="&$B$5,التصحيح!$U$3:$U$152)/$B$7 -> 0.93333333 | E40: =SUMIF(التصحيح!$AF$3:$AF$152,"<="&$B$6,التصحيح!$U$3:$U$152)/$B$8 -> 0.13333333 | F40: =D40-E40 -> 0.8 | G40: =VARP(التصحيح!$U$3:$U$152) -> 0.2496 | H40: =IF(G40=0,0,CORREL(التصحيح!$U$3:$U$152,التصحيح!$AF$3:$AF$152)) -> 0.64763676 | I40: =IF(G40=0,0,(H40*$B$11-SQRT(G40))/SQRT(G40+$B$10-2*H40*SQRT(G40)*$B$11)) -> 0.59872646 | J40: =($B$9-1)/($B$9-2)*(1-($B$12-G40)/($B$10+G40-2*H40*SQRT(G40)*$B$11)) -> 0.8605012 | K40: =COUNTIF(الإجابات!$U$3:$U$152,"A")/$B$2 -> 0.16666667 | L40: =COUNTIF(الإجابات!$U$3:$U$152,"B")/$B$2 -> 0.15333333 | M40: =COUNTIF(الإجابات!$U$3:$U$152,"C")/$B$2 -> 0.16 | N40: =COUNTIF(الإجابات!$U$3:$U$152,"D")/$B$2 -> 0.52 | O40: =MIN(IF(B40="A",1,K40),IF(B40="B",1,L40),IF(B40="C",1,M40),IF(B40="D",1,N40)) -> 0.15333333 | P40: =IF(I40<-0.1,"تمييز سالب: راجِع المفتاح فوراً",IF(OR(C40>$B$14,C40<$B$13),"صعوبة متطرفة: راجِع الصياغة أو المستوى",IF(I40<$B$15,"تمييز ضعيف: راجِع الصياغة والمموهات",IF(O40<$B$17,"مموّه غير فعّال: استبدله",IF(I40<$B$16,"مقبولة وقابلة للتحسين","جيدة"))))) -> جيدة
A41: ف21 | B41: =الإجابات!V2 -> C | C41: =AVERAGE(التصحيح!$V$3:$V$152) -> 0.55333333 | D41: =SUMIF(التصحيح!$AF$3:$AF$152,">="&$B$5,التصحيح!$V$3:$V$152)/$B$7 -> 0.93333333 | E41: =SUMIF(التصحيح!$AF$3:$AF$152,"<="&$B$6,التصحيح!$V$3:$V$152)/$B$8 -> 0.28888889 | F41: =D41-E41 -> 0.64444444 | G41: =VARP(التصحيح!$V$3:$V$152) -> 0.24715556 | H41: =IF(G41=0,0,CORREL(التصحيح!$V$3:$V$152,التصحيح!$AF$3:$AF$152)) -> 0.54536303 | I41: =IF(G41=0,0,(H41*$B$11-SQRT(G41))/SQRT(G41+$B$10-2*H41*SQRT(G41)*$B$11)) -> 0.48724461 | J41: =($B$9-1)/($B$9-2)*(1-($B$12-G41)/($B$10+G41-2*H41*SQRT(G41)*$B$11)) -> 0.8635391 | K41: =COUNTIF(الإجابات!$V$3:$V$152,"A")/$B$2 -> 0.18 | L41: =COUNTIF(الإجابات!$V$3:$V$152,"B")/$B$2 -> 0.12 | M41: =COUNTIF(الإجابات!$V$3:$V$152,"C")/$B$2 -> 0.55333333 | N41: =COUNTIF(الإجابات!$V$3:$V$152,"D")/$B$2 -> 0.14666667 | O41: =MIN(IF(B41="A",1,K41),IF(B41="B",1,L41),IF(B41="C",1,M41),IF(B41="D",1,N41)) -> 0.12 | P41: =IF(I41<-0.1,"تمييز سالب: راجِع المفتاح فوراً",IF(OR(C41>$B$14,C41<$B$13),"صعوبة متطرفة: راجِع الصياغة أو المستوى",IF(I41<$B$15,"تمييز ضعيف: راجِع الصياغة والمموهات",IF(O41<$B$17,"مموّه غير فعّال: استبدله",IF(I41<$B$16,"مقبولة وقابلة للتحسين","جيدة"))))) -> جيدة
...

Sheet تحليل المموهات
A1: الفقرة | B1: البديل | C1: هو المفتاح؟ | D1: نسبة الاختيار (الكل) | E1: عدد الفئة العليا | F1: عدد الفئة الدنيا | G1: الفرق (عليا − دنيا) | H1: قراءة
A2: ف1 | B2: A | C2: =IF(الإجابات!$B$2=B2,"نعم","") | D2: =COUNTIF(الإجابات!$B$3:$B$152,B2)/'تحليل الفقرات'!$B$2 -> 0.16 | E2: =COUNTIFS(الإجابات!$B$3:$B$152,B2,التصحيح!$AF$3:$AF$152,">="&'تحليل الفقرات'!$B$5) -> 3 | F2: =COUNTIFS(الإجابات!$B$3:$B$152,B2,التصحيح!$AF$3:$AF$152,"<="&'تحليل الفقرات'!$B$6) -> 10 | G2: =E2-F2 -> -7 | H2: =IF(C2="نعم",IF(G2>0,"المفتاح يميّز كما يجب","المفتاح لا يميّز: راجِع"),IF(D2<'تحليل الفقرات'!$B$17,"مموّه غير فعّال",IF(G2>0,"مموّه يجذب المتفوقين: راجِعه","مموّه يعمل"))) -> مموّه يعمل
A3: ف1 | B3: B | C3: =IF(الإجابات!$B$2=B3,"نعم","") | D3: =COUNTIF(الإجابات!$B$3:$B$152,B3)/'تحليل الفقرات'!$B$2 -> 0.22 | E3: =COUNTIFS(الإجابات!$B$3:$B$152,B3,التصحيح!$AF$3:$AF$152,">="&'تحليل الفقرات'!$B$5) -> 4 | F3: =COUNTIFS(الإجابات!$B$3:$B$152,B3,التصحيح!$AF$3:$AF$152,"<="&'تحليل الفقرات'!$B$6) -> 18 | G3: =E3-F3 -> -14 | H3: =IF(C3="نعم",IF(G3>0,"المفتاح يميّز كما يجب","المفتاح لا يميّز: راجِع"),IF(D3<'تحليل الفقرات'!$B$17,"مموّه غير فعّال",IF(G3>0,"مموّه يجذب المتفوقين: راجِعه","مموّه يعمل"))) -> مموّه يعمل
A4: ف1 | B4: C | C4: =IF(الإجابات!$B$2=B4,"نعم","") | D4: =COUNTIF(الإجابات!$B$3:$B$152,B4)/'تحليل الفقرات'!$B$2 -> 0.18666667 | E4: =COUNTIFS(الإجابات!$B$3:$B$152,B4,التصحيح!$AF$3:$AF$152,">="&'تحليل الفقرات'!$B$5) -> 3 | F4: =COUNTIFS(الإجابات!$B$3:$B$152,B4,التصحيح!$AF$3:$AF$152,"<="&'تحليل الفقرات'!$B$6) -> 11 | G4: =E4-F4 -> -8 | H4: =IF(C4="نعم",IF(G4>0,"المفتاح يميّز كما يجب","المفتاح لا يميّز: راجِع"),IF(D4<'تحليل الفقرات'!$B$17,"مموّه غير فعّال",IF(G4>0,"مموّه يجذب المتفوقين: راجِعه","مموّه يعمل"))) -> مموّه يعمل
A5: ف1 | B5: D | C5: =IF(الإجابات!$B$2=B5,"نعم","") -> نعم | D5: =COUNTIF(الإجابات!$B$3:$B$152,B5)/'تحليل الفقرات'!$B$2 -> 0.43333333 | E5: =COUNTIFS(الإجابات!$B$3:$B$152,B5,التصحيح!$AF$3:$AF$152,">="&'تحليل الفقرات'!$B$5) -> 35 | F5: =COUNTIFS(الإجابات!$B$3:$B$152,B5,التصحيح!$AF$3:$AF$152,"<="&'تحليل الفقرات'!$B$6) -> 6 | G5: =E5-F5 -> 29 | H5: =IF(C5="نعم",IF(G5>0,"المفتاح يميّز كما يجب","المفتاح لا يميّز: راجِع"),IF(D5<'تحليل الفقرات'!$B$17,"مموّه غير فعّال",IF(G5>0,"مموّه يجذب المتفوقين: راجِعه","مموّه يعمل"))) -> المفتاح يميّز كما يجب
A6: ف2 | B6: A | C6: =IF(الإجابات!$C$2=B6,"نعم","") | D6: =COUNTIF(الإجابات!$C$3:$C$152,B6)/'تحليل الفقرات'!$B$2 -> 0.19333333 | E6: =COUNTIFS(الإجابات!$C$3:$C$152,B6,التصحيح!$AF$3:$AF$152,">="&'تحليل الفقرات'!$B$5) -> 4 | F6: =COUNTIFS(الإجابات!$C$3:$C$152,B6,التصحيح!$AF$3:$AF$152,"<="&'تحليل الفقرات'!$B$6) -> 12 | G6: =E6-F6 -> -8 | H6: =IF(C6="نعم",IF(G6>0,"المفتاح يميّز كما يجب","المفتاح لا يميّز: راجِع"),IF(D6<'تحليل الفقرات'!$B$17,"مموّه غير فعّال",IF(G6>0,"مموّه يجذب المتفوقين: راجِعه","مموّه يعمل"))) -> مموّه يعمل
A7: ف2 | B7: B | C7: =IF(الإجابات!$C$2=B7,"نعم","") | D7: =COUNTIF(الإجابات!$C$3:$C$152,B7)/'تحليل الفقرات'!$B$2 -> 0.23333333 | E7: =COUNTIFS(الإجابات!$C$3:$C$152,B7,التصحيح!$AF$3:$AF$152,">="&'تحليل الفقرات'!$B$5) -> 3 | F7: =COUNTIFS(الإجابات!$C$3:$C$152,B7,التصحيح!$AF$3:$AF$152,"<="&'تحليل الفقرات'!$B$6) -> 16 | G7: =E7-F7 -> -13 | H7: =IF(C7="نعم",IF(G7>0,"المفتاح يميّز كما يجب","المفتاح لا يميّز: راجِع"),IF(D7<'تحليل الفقرات'!$B$17,"مموّه غير فعّال",IF(G7>0,"مموّه يجذب المتفوقين: راجِعه","مموّه يعمل"))) -> مموّه يعمل
A8: ف2 | B8: C | C8: =IF(الإجابات!$C$2=B8,"نعم","") -> نعم | D8: =COUNTIF(الإجابات!$C$3:$C$152,B8)/'تحليل الفقرات'!$B$2 -> 0.40666667 | E8: =COUNTIFS(الإجابات!$C$3:$C$152,B8,التصحيح!$AF$3:$AF$152,">="&'تحليل الفقرات'!$B$5) -> 34 | F8: =COUNTIFS(الإجابات!$C$3:$C$152,B8,التصحيح!$AF$3:$AF$152,"<="&'تحليل الفقرات'!$B$6) -> 6 | G8: =E8-F8 -> 28 | H8: =IF(C8="نعم",IF(G8>0,"المفتاح يميّز كما يجب","المفتاح لا يميّز: راجِع"),IF(D8<'تحليل الفقرات'!$B$17,"مموّه غير فعّال",IF(G8>0,"مموّه يجذب المتفوقين: راجِعه","مموّه يعمل"))) -> المفتاح يميّز كما يجب
A9: ف2 | B9: D | C9: =IF(الإجابات!$C$2=B9,"نعم","") | D9: =COUNTIF(الإجابات!$C$3:$C$152,B9)/'تحليل الفقرات'!$B$2 -> 0.16666667 | E9: =COUNTIFS(الإجابات!$C$3:$C$152,B9,التصحيح!$AF$3:$AF$152,">="&'تحليل الفقرات'!$B$5) -> 4 | F9: =COUNTIFS(الإجابات!$C$3:$C$152,B9,التصحيح!$AF$3:$AF$152,"<="&'تحليل الفقرات'!$B$6) -> 11 | G9: =E9-F9 -> -7 | H9: =IF(C9="نعم",IF(G9>0,"المفتاح يميّز كما يجب","المفتاح لا يميّز: راجِع"),IF(D9<'تحليل الفقرات'!$B$17,"مموّه غير فعّال",IF(G9>0,"مموّه يجذب المتفوقين: راجِعه","مموّه يعمل"))) -> مموّه يعمل
A10: ف3 | B10: A | C10: =IF(الإجابات!$D$2=B10,"نعم","") | D10: =COUNTIF(الإجابات!$D$3:$D$152,B10)/'تحليل الفقرات'!$B$2 -> 0.16666667 | E10: =COUNTIFS(الإجابات!$D$3:$D$152,B10,التصحيح!$AF$3:$AF$152,">="&'تحليل الفقرات'!$B$5) -> 8 | F10: =COUNTIFS(الإجابات!$D$3:$D$152,B10,التصحيح!$AF$3:$AF$152,"<="&'تحليل الفقرات'!$B$6) -> 9 | G10: =E10-F10 -> -1 | H10: =IF(C10="نعم",IF(G10>0,"المفتاح يميّز كما يجب","المفتاح لا يميّز: راجِع"),IF(D10<'تحليل الفقرات'!$B$17,"مموّه غير فعّال",IF(G10>0,"مموّه يجذب المتفوقين: راجِعه","مموّه يعمل"))) -> مموّه يعمل
A11: ف3 | B11: B | C11: =IF(الإجابات!$D$2=B11,"نعم","") | D11: =COUNTIF(الإجابات!$D$3:$D$152,B11)/'تحليل الفقرات'!$B$2 -> 0.2 | E11: =COUNTIFS(الإجابات!$D$3:$D$152,B11,التصحيح!$AF$3:$AF$152,">="&'تحليل الفقرات'!$B$5) -> 2 | F11: =COUNTIFS(الإجابات!$D$3:$D$152,B11,التصحيح!$AF$3:$AF$152,"<="&'تحليل الفقرات'!$B$6) -> 11 | G11: =E11-F11 -> -9 | H11: =IF(C11="نعم",IF(G11>0,"المفتاح يميّز كما يجب","المفتاح لا يميّز: راجِع"),IF(D11<'تحليل الفقرات'!$B$17,"مموّه غير فعّال",IF(G11>0,"مموّه يجذب المتفوقين: راجِعه","مموّه يعمل"))) -> مموّه يعمل
A12: ف3 | B12: C | C12: =IF(الإجابات!$D$2=B12,"نعم","") | D12: =COUNTIF(الإجابات!$D$3:$D$152,B12)/'تحليل الفقرات'!$B$2 -> 0.26 | E12: =COUNTIFS(الإجابات!$D$3:$D$152,B12,التصحيح!$AF$3:$AF$152,">="&'تحليل الفقرات'!$B$5) -> 5 | F12: =COUNTIFS(الإجابات!$D$3:$D$152,B12,التصحيح!$AF$3:$AF$152,"<="&'تحليل الفقرات'!$B$6) -> 14 | G12: =E12-F12 -> -9 | H12: =IF(C12="نعم",IF(G12>0,"المفتاح يميّز كما يجب","المفتاح لا يميّز: راجِع"),IF(D12<'تحليل الفقرات'!$B$17,"مموّه غير فعّال",IF(G12>0,"مموّه يجذب المتفوقين: راجِعه","مموّه يعمل"))) -> مموّه يعمل
A13: ف3 | B13: D | C13: =IF(الإجابات!$D$2=B13,"نعم","") -> نعم | D13: =COUNTIF(الإجابات!$D$3:$D$152,B13)/'تحليل الفقرات'!$B$2 -> 0.37333333 | E13: =COUNTIFS(الإجابات!$D$3:$D$152,B13,التصحيح!$AF$3:$AF$152,">="&'تحليل الفقرات'!$B$5) -> 30 | F13: =COUNTIFS(الإجابات!$D$3:$D$152,B13,التصحيح!$AF$3:$AF$152,"<="&'تحليل الفقرات'!$B$6) -> 11 | G13: =E13-F13 -> 19 | H13: =IF(C13="نعم",IF(G13>0,"المفتاح يميّز كما يجب","المفتاح لا يميّز: راجِع"),IF(D13<'تحليل الفقرات'!$B$17,"مموّه غير فعّال",IF(G13>0,"مموّه يجذب المتفوقين: راجِعه","مموّه يعمل"))) -> المفتاح يميّز كما يجب
A14: ف4 | B14: A | C14: =IF(الإجابات!$E$2=B14,"نعم","") | D14: =COUNTIF(الإجابات!$E$3:$E$152,B14)/'تحليل الفقرات'!$B$2 -> 0.053333333 | E14: =COUNTIFS(الإجابات!$E$3:$E$152,B14,التصحيح!$AF$3:$AF$152,">="&'تحليل الفقرات'!$B$5) -> 0 | F14: =COUNTIFS(الإجابات!$E$3:$E$152,B14,التصحيح!$AF$3:$AF$152,"<="&'تحليل الفقرات'!$B$6) -> 8 | G14: =E14-F14 -> -8 | H14: =IF(C14="نعم",IF(G14>0,"المفتاح يميّز كما يجب","المفتاح لا يميّز: راجِع"),IF(D14<'تحليل الفقرات'!$B$17,"مموّه غير فعّال",IF(G14>0,"مموّه يجذب المتفوقين: راجِعه","مموّه يعمل"))) -> مموّه يعمل
A15: ف4 | B15: B | C15: =IF(الإجابات!$E$2=B15,"نعم","") -> نعم | D15: =COUNTIF(الإجابات!$E$3:$E$152,B15)/'تحليل الفقرات'!$B$2 -> 0.76666667 | E15: =COUNTIFS(الإجابات!$E$3:$E$152,B15,التصحيح!$AF$3:$AF$152,">="&'تحليل الفقرات'!$B$5) -> 45 | F15: =COUNTIFS(الإجابات!$E$3:$E$152,B15,التصحيح!$AF$3:$AF$152,"<="&'تحليل الفقرات'!$B$6) -> 20 | G15: =E15-F15 -> 25 | H15: =IF(C15="نعم",IF(G15>0,"المفتاح يميّز كما يجب","المفتاح لا يميّز: راجِع"),IF(D15<'تحليل الفقرات'!$B$17,"مموّه غير فعّال",IF(G15>0,"مموّه يجذب المتفوقين: راجِعه","مموّه يعمل"))) -> المفتاح يميّز كما يجب
A16: ف4 | B16: C | C16: =IF(الإجابات!$E$2=B16,"نعم","") | D16: =COUNTIF(الإجابات!$E$3:$E$152,B16)/'تحليل الفقرات'!$B$2 -> 0.06 | E16: =COUNTIFS(الإجابات!$E$3:$E$152,B16,التصحيح!$AF$3:$AF$152,">="&'تحليل الفقرات'!$B$5) -> 0 | F16: =COUNTIFS(الإجابات!$E$3:$E$152,B16,التصحيح!$AF$3:$AF$152,"<="&'تحليل الفقرات'!$B$6) -> 6 | G16: =E16-F16 -> -6 | H16: =IF(C16="نعم",IF(G16>0,"المفتاح يميّز كما يجب","المفتاح لا يميّز: راجِع"),IF(D16<'تحليل الفقرات'!$B$17,"مموّه غير فعّال",IF(G16>0,"مموّه يجذب المتفوقين: راجِعه","مموّه يعمل"))) -> مموّه يعمل
A17: ف4 | B17: D | C17: =IF(الإجابات!$E$2=B17,"نعم","") | D17: =COUNTIF(الإجابات!$E$3:$E$152,B17)/'تحليل الفقرات'!$B$2 -> 0.12 | E17: =COUNTIFS(الإجابات!$E$3:$E$152,B17,التصحيح!$AF$3:$AF$152,">="&'تحليل الفقرات'!$B$5) -> 0 | F17: =COUNTIFS(الإجابات!$E$3:$E$152,B17,التصحيح!$AF$3:$AF$152,"<="&'تحليل الفقرات'!$B$6) -> 11 | G17: =E17-F17 -> -11 | H17: =IF(C17="نعم",IF(G17>0,"المفتاح يميّز كما يجب","المفتاح لا يميّز: راجِع"),IF(D17<'تحليل الفقرات'!$B$17,"مموّه غير فعّال",IF(G17>0,"مموّه يجذب المتفوقين: راجِعه","مموّه يعمل"))) -> مموّه يعمل
A18: ف5 | B18: A | C18: =IF(الإجابات!$F$2=B18,"نعم","") | D18: =COUNTIF(الإجابات!$F$3:$F$152,B18)/'تحليل الفقرات'!$B$2 -> 0.28666667 | E18: =COUNTIFS(الإجابات!$F$3:$F$152,B18,التصحيح!$AF$3:$AF$152,">="&'تحليل الفقرات'!$B$5) -> 6 | F18: =COUNTIFS(الإجابات!$F$3:$F$152,B18,التصحيح!$AF$3:$AF$152,"<="&'تحليل الفقرات'!$B$6) -> 20 | G18: =E18-F18 -> -14 | H18: =IF(C18="نعم",IF(G18>0,"المفتاح يميّز كما يجب","المفتاح لا يميّز: راجِع"),IF(D18<'تحليل الفقرات'!$B$17,"مموّه غير فعّال",IF(G18>0,"مموّه يجذب المتفوقين: راجِعه","مموّه يعمل"))) -> مموّه يعمل
A19: ف5 | B19: B | C19: =IF(الإجابات!$F$2=B19,"نعم","") -> نعم | D19: =COUNTIF(الإجابات!$F$3:$F$152,B19)/'تحليل الفقرات'!$B$2 -> 0.42666667 | E19: =COUNTIFS(الإجابات!$F$3:$F$152,B19,التصحيح!$AF$3:$AF$152,">="&'تحليل الفقرات'!$B$5) -> 32 | F19: =COUNTIFS(الإجابات!$F$3:$F$152,B19,التصحيح!$AF$3:$AF$152,"<="&'تحليل الفقرات'!$B$6) -> 6 | G19: =E19-F19 -> 26 | H19: =IF(C19="نعم",IF(G19>0,"المفتاح يميّز كما يجب","المفتاح لا يميّز: راجِع"),IF(D19<'تحليل الفقرات'!$B$17,"مموّه غير فعّال",IF(G19>0,"مموّه يجذب المتفوقين: راجِعه","مموّه يعمل"))) -> المفتاح يميّز كما يجب
A20: ف5 | B20: C | C20: =IF(الإجابات!$F$2=B20,"نعم","") | D20: =COUNTIF(الإجابات!$F$3:$F$152,B20)/'تحليل الفقرات'!$B$2 -> 0.17333333 | E20: =COUNTIFS(الإجابات!$F$3:$F$152,B20,التصحيح!$AF$3:$AF$152,">="&'تحليل الفقرات'!$B$5) -> 4 | F20: =COUNTIFS(الإجابات!$F$3:$F$152,B20,التصحيح!$AF$3:$AF$152,"<="&'تحليل الفقرات'!$B$6) -> 13 | G20: =E20-F20 -> -9 | H20: =IF(C20="نعم",IF(G20>0,"المفتاح يميّز كما يجب","المفتاح لا يميّز: راجِع"),IF(D20<'تحليل الفقرات'!$B$17,"مموّه غير فعّال",IF(G20>0,"مموّه يجذب المتفوقين: راجِعه","مموّه يعمل"))) -> مموّه يعمل
A21: ف5 | B21: D | C21: =IF(الإجابات!$F$2=B21,"نعم","") | D21: =COUNTIF(الإجابات!$F$3:$F$152,B21)/'تحليل الفقرات'!$B$2 -> 0.11333333 | E21: =COUNTIFS(الإجابات!$F$3:$F$152,B21,التصحيح!$AF$3:$AF$152,">="&'تحليل الفقرات'!$B$5) -> 3 | F21: =COUNTIFS(الإجابات!$F$3:$F$152,B21,التصحيح!$AF$3:$AF$152,"<="&'تحليل الفقرات'!$B$6) -> 6 | G21: =E21-F21 -> -3 | H21: =IF(C21="نعم",IF(G21>0,"المفتاح يميّز كما يجب","المفتاح لا يميّز: راجِع"),IF(D21<'تحليل الفقرات'!$B$17,"مموّه غير فعّال",IF(G21>0,"مموّه يجذب المتفوقين: راجِعه","مموّه يعمل"))) -> مموّه يعمل
A22: ف6 | B22: A | C22: =IF(الإجابات!$G$2=B22,"نعم","") | D22: =COUNTIF(الإجابات!$G$3:$G$152,B22)/'تحليل الفقرات'!$B$2 -> 0.22666667 | E22: =COUNTIFS(الإجابات!$G$3:$G$152,B22,التصحيح!$AF$3:$AF$152,">="&'تحليل الفقرات'!$B$5) -> 4 | F22: =COUNTIFS(الإجابات!$G$3:$G$152,B22,التصحيح!$AF$3:$AF$152,"<="&'تحليل الفقرات'!$B$6) -> 14 | G22: =E22-F22 -> -10 | H22: =IF(C22="نعم",IF(G22>0,"المفتاح يميّز كما يجب","المفتاح لا يميّز: راجِع"),IF(D22<'تحليل الفقرات'!$B$17,"مموّه غير فعّال",IF(G22>0,"مموّه يجذب المتفوقين: راجِعه","مموّه يعمل"))) -> مموّه يعمل
A23: ف6 | B23: B | C23: =IF(الإجابات!$G$2=B23,"نعم","") -> نعم | D23: =COUNTIF(الإجابات!$G$3:$G$152,B23)/'تحليل الفقرات'!$B$2 -> 0.47333333 | E23: =COUNTIFS(الإجابات!$G$3:$G$152,B23,التصحيح!$AF$3:$AF$152,">="&'تحليل الفقرات'!$B$5) -> 37 | F23: =COUNTIFS(الإجابات!$G$3:$G$152,B23,التصحيح!$AF$3:$AF$152,"<="&'تحليل الفقرات'!$B$6) -> 10 | G23: =E23-F23 -> 27 | H23: =IF(C23="نعم",IF(G23>0,"المفتاح يميّز كما يجب","المفتاح لا يميّز: راجِع"),IF(D23<'تحليل الفقرات'!$B$17,"مموّه غير فعّال",IF(G23>0,"مموّه يجذب المتفوقين: راجِعه","مموّه يعمل"))) -> المفتاح يميّز كما يجب
A24: ف6 | B24: C | C24: =IF(الإجابات!$G$2=B24,"نعم","") | D24: =COUNTIF(الإجابات!$G$3:$G$152,B24)/'تحليل الفقرات'!$B$2 -> 0.12666667 | E24: =COUNTIFS(الإجابات!$G$3:$G$152,B24,التصحيح!$AF$3:$AF$152,">="&'تحليل الفقرات'!$B$5) -> 1 | F24: =COUNTIFS(الإجابات!$G$3:$G$152,B24,التصحيح!$AF$3:$AF$152,"<="&'تحليل الفقرات'!$B$6) -> 13 | G24: =E24-F24 -> -12 | H24: =IF(C24="نعم",IF(G24>0,"المفتاح يميّز كما يجب","المفتاح لا يميّز: راجِع"),IF(D24<'تحليل الفقرات'!$B$17,"مموّه غير فعّال",IF(G24>0,"مموّه يجذب المتفوقين: راجِعه","مموّه يعمل"))) -> مموّه يعمل
A25: ف6 | B25: D | C25: =IF(الإجابات!$G$2=B25,"نعم","") | D25: =COUNTIF(الإجابات!$G$3:$G$152,B25)/'تحليل الفقرات'!$B$2 -> 0.17333333 | E25: =COUNTIFS(الإجابات!$G$3:$G$152,B25,التصحيح!$AF$3:$AF$152,">="&'تحليل الفقرات'!$B$5) -> 3 | F25: =COUNTIFS(الإجابات!$G$3:$G$152,B25,التصحيح!$AF$3:$AF$152,"<="&'تحليل الفقرات'!$B$6) -> 8 | G25: =E25-F25 -> -5 | H25: =IF(C25="نعم",IF(G25>0,"المفتاح يميّز كما يجب","المفتاح لا يميّز: راجِع"),IF(D25<'تحليل الفقرات'!$B$17,"مموّه غير فعّال",IF(G25>0,"مموّه يجذب المتفوقين: راجِعه","مموّه يعمل"))) -> مموّه يعمل
A26: ف7 | B26: A | C26: =IF(الإجابات!$H$2=B26,"نعم","") | D26: =COUNTIF(الإجابات!$H$3:$H$152,B26)/'تحليل الفقرات'!$B$2 -> 0.033333333 | E26: =COUNTIFS(الإجابات!$H$3:$H$152,B26,التصحيح!$AF$3:$AF$152,">="&'تحليل الفقرات'!$B$5) -> 0 | F26: =COUNTIFS(الإجابات!$H$3:$H$152,B26,التصحيح!$AF$3:$AF$152,"<="&'تحليل الفقرات'!$B$6) -> 3 | G26: =E26-F26 -> -3 | H26: =IF(C26="نعم",IF(G26>0,"المفتاح يميّز كما يجب","المفتاح لا يميّز: راجِع"),IF(D26<'تحليل الفقرات'!$B$17,"مموّه غير فعّال",IF(G26>0,"مموّه يجذب المتفوقين: راجِعه","مموّه يعمل"))) -> مموّه غير فعّال
A27: ف7 | B27: B | C27: =IF(الإجابات!$H$2=B27,"نعم","") -> نعم | D27: =COUNTIF(الإجابات!$H$3:$H$152,B27)/'تحليل الفقرات'!$B$2 -> 0.25333333 | E27: =COUNTIFS(الإجابات!$H$3:$H$152,B27,التصحيح!$AF$3:$AF$152,">="&'تحليل الفقرات'!$B$5) -> 2 | F27: =COUNTIFS(الإجابات!$H$3:$H$152,B27,التصحيح!$AF$3:$AF$152,"<="&'تحليل الفقرات'!$B$6) -> 20 | G27: =E27-F27 -> -18 | H27: =IF(C27="نعم",IF(G27>0,"المفتاح يميّز كما يجب","المفتاح لا يميّز: راجِع"),IF(D27<'تحليل الفقرات'!$B$17,"مموّه غير فعّال",IF(G27>0,"مموّه يجذب المتفوقين: راجِعه","مموّه يعمل"))) -> المفتاح لا يميّز: راجِع
A28: ف7 | B28: C | C28: =IF(الإجابات!$H$2=B28,"نعم","") | D28: =COUNTIF(الإجابات!$H$3:$H$152,B28)/'تحليل الفقرات'!$B$2 -> 0.68 | E28: =COUNTIFS(الإجابات!$H$3:$H$152,B28,التصحيح!$AF$3:$AF$152,">="&'تحليل الفقرات'!$B$5) -> 43 | F28: =COUNTIFS(الإجابات!$H$3:$H$152,B28,التصحيح!$AF$3:$AF$152,"<="&'تحليل الفقرات'!$B$6) -> 17 | G28: =E28-F28 -> 26 | H28: =IF(C28="نعم",IF(G28>0,"المفتاح يميّز كما يجب","المفتاح لا يميّز: راجِع"),IF(D28<'تحليل الفقرات'!$B$17,"مموّه غير فعّال",IF(G28>0,"مموّه يجذب المتفوقين: راجِعه","مموّه يعمل"))) -> مموّه يجذب المتفوقين: راجِعه
A29: ف7 | B29: D | C29: =IF(الإجابات!$H$2=B29,"نعم","") | D29: =COUNTIF(الإجابات!$H$3:$H$152,B29)/'تحليل الفقرات'!$B$2 -> 0.033333333 | E29: =COUNTIFS(الإجابات!$H$3:$H$152,B29,التصحيح!$AF$3:$AF$152,">="&'تحليل الفقرات'!$B$5) -> 0 | F29: =COUNTIFS(الإجابات!$H$3:$H$152,B29,التصحيح!$AF$3:$AF$152,"<="&'تحليل الفقرات'!$B$6) -> 5 | G29: =E29-F29 -> -5 | H29: =IF(C29="نعم",IF(G29>0,"المفتاح يميّز كما يجب","المفتاح لا يميّز: راجِع"),IF(D29<'تحليل الفقرات'!$B$17,"مموّه غير فعّال",IF(G29>0,"مموّه يجذب المتفوقين: راجِعه","مموّه يعمل"))) -> مموّه غير فعّال
A30: ف8 | B30: A | C30: =IF(الإجابات!$I$2=B30,"نعم","") | D30: =COUNTIF(الإجابات!$I$3:$I$152,B30)/'تحليل الفقرات'!$B$2 -> 0.13333333 | E30: =COUNTIFS(الإجابات!$I$3:$I$152,B30,التصحيح!$AF$3:$AF$152,">="&'تحليل الفقرات'!$B$5) -> 0 | F30: =COUNTIFS(الإجابات!$I$3:$I$152,B30,التصحيح!$AF$3:$AF$152,"<="&'تحليل الفقرات'!$B$6) -> 14 | G30: =E30-F30 -> -14 | H30: =IF(C30="نعم",IF(G30>0,"المفتاح يميّز كما يجب","المفتاح لا يميّز: راجِع"),IF(D30<'تحليل الفقرات'!$B$17,"مموّه غير فعّال",IF(G30>0,"مموّه يجذب المتفوقين: راجِعه","مموّه يعمل"))) -> مموّه يعمل
A31: ف8 | B31: B | C31: =IF(الإجابات!$I$2=B31,"نعم","") | D31: =COUNTIF(الإجابات!$I$3:$I$152,B31)/'تحليل الفقرات'!$B$2 -> 0.1 | E31: =COUNTIFS(الإجابات!$I$3:$I$152,B31,التصحيح!$AF$3:$AF$152,">="&'تحليل الفقرات'!$B$5) -> 1 | F31: =COUNTIFS(الإجابات!$I$3:$I$152,B31,التصحيح!$AF$3:$AF$152,"<="&'تحليل الفقرات'!$B$6) -> 7 | G31: =E31-F31 -> -6 | H31: =IF(C31="نعم",IF(G31>0,"المفتاح يميّز كما يجب","المفتاح لا يميّز: راجِع"),IF(D31<'تحليل الفقرات'!$B$17,"مموّه غير فعّال",IF(G31>0,"مموّه يجذب المتفوقين: راجِعه","مموّه يعمل"))) -> مموّه يعمل
A32: ف8 | B32: C | C32: =IF(الإجابات!$I$2=B32,"نعم","") -> نعم | D32: =COUNTIF(الإجابات!$I$3:$I$152,B32)/'تحليل الفقرات'!$B$2 -> 0.66 | E32: =COUNTIFS(الإجابات!$I$3:$I$152,B32,التصحيح!$AF$3:$AF$152,">="&'تحليل الفقرات'!$B$5) -> 44 | F32: =COUNTIFS(الإجابات!$I$3:$I$152,B32,التصحيح!$AF$3:$AF$152,"<="&'تحليل الفقرات'!$B$6) -> 12 | G32: =E32-F32 -> 32 | H32: =IF(C32="نعم",IF(G32>0,"المفتاح يميّز كما يجب","المفتاح لا يميّز: راجِع"),IF(D32<'تحليل الفقرات'!$B$17,"مموّه غير فعّال",IF(G32>0,"مموّه يجذب المتفوقين: راجِعه","مموّه يعمل"))) -> المفتاح يميّز كما يجب
A33: ف8 | B33: D | C33: =IF(الإجابات!$I$2=B33,"نعم","") | D33: =COUNTIF(الإجابات!$I$3:$I$152,B33)/'تحليل الفقرات'!$B$2 -> 0.10666667 | E33: =COUNTIFS(الإجابات!$I$3:$I$152,B33,التصحيح!$AF$3:$AF$152,">="&'تحليل الفقرات'!$B$5) -> 0 | F33: =COUNTIFS(الإجابات!$I$3:$I$152,B33,التصحيح!$AF$3:$AF$152,"<="&'تحليل الفقرات'!$B$6) -> 12 | G33: =E33-F33 -> -12 | H33: =IF(C33="نعم",IF(G33>0,"المفتاح يميّز كما يجب","المفتاح لا يميّز: راجِع"),IF(D33<'تحليل الفقرات'!$B$17,"مموّه غير فعّال",IF(G33>0,"مموّه يجذب المتفوقين: راجِعه","مموّه يعمل"))) -> مموّه يعمل
A34: ف9 | B34: A | C34: =IF(الإجابات!$J$2=B34,"نعم","") -> نعم | D34: =COUNTIF(الإجابات!$J$3:$J$152,B34)/'تحليل الفقرات'!$B$2 -> 0.90666667 | E34: =COUNTIFS(الإجابات!$J$3:$J$152,B34,التصحيح!$AF$3:$AF$152,">="&'تحليل الفقرات'!$B$5) -> 45 | F34: =COUNTIFS(الإجابات!$J$3:$J$152,B34,التصحيح!$AF$3:$AF$152,"<="&'تحليل الفقرات'!$B$6) -> 34 | G34: =E34-F34 -> 11 | H34: =IF(C34="نعم",IF(G34>0,"المفتاح يميّز كما يجب","المفتاح لا يميّز: راجِع"),IF(D34<'تحليل الفقرات'!$B$17,"مموّه غير فعّال",IF(G34>0,"مموّه يجذب المتفوقين: راجِعه","مموّه يعمل"))) -> المفتاح يميّز كما يجب
A35: ف9 | B35: B | C35: =IF(الإجابات!$J$2=B35,"نعم","") | D35: =COUNTIF(الإجابات!$J$3:$J$152,B35)/'تحليل الفقرات'!$B$2 -> 0.04 | E35: =COUNTIFS(الإجابات!$J$3:$J$152,B35,التصحيح!$AF$3:$AF$152,">="&'تحليل الفقرات'!$B$5) -> 0 | F35: =COUNTIFS(الإجابات!$J$3:$J$152,B35,التصحيح!$AF$3:$AF$152,"<="&'تحليل الفقرات'!$B$6) -> 5 | G35: =E35-F35 -> -5 | H35: =IF(C35="نعم",IF(G35>0,"المفتاح يميّز كما يجب","المفتاح لا يميّز: راجِع"),IF(D35<'تحليل الفقرات'!$B$17,"مموّه غير فعّال",IF(G35>0,"مموّه يجذب المتفوقين: راجِعه","مموّه يعمل"))) -> مموّه غير فعّال
A36: ف9 | B36: C | C36: =IF(الإجابات!$J$2=B36,"نعم","") | D36: =COUNTIF(الإجابات!$J$3:$J$152,B36)/'تحليل الفقرات'!$B$2 -> 0.033333333 | E36: =COUNTIFS(الإجابات!$J$3:$J$152,B36,التصحيح!$AF$3:$AF$152,">="&'تحليل الفقرات'!$B$5) -> 0 | F36: =COUNTIFS(الإجابات!$J$3:$J$152,B36,التصحيح!$AF$3:$AF$152,"<="&'تحليل الفقرات'!$B$6) -> 4 | G36: =E36-F36 -> -4 | H36: =IF(C36="نعم",IF(G36>0,"المفتاح يميّز كما يجب","المفتاح لا يميّز: راجِع"),IF(D36<'تحليل الفقرات'!$B$17,"مموّه غير فعّال",IF(G36>0,"مموّه يجذب المتفوقين: راجِعه","مموّه يعمل"))) -> مموّه غير فعّال
A37: ف9 | B37: D | C37: =IF(الإجابات!$J$2=B37,"نعم","") | D37: =COUNTIF(الإجابات!$J$3:$J$152,B37)/'تحليل الفقرات'!$B$2 -> 0.02 | E37: =COUNTIFS(الإجابات!$J$3:$J$152,B37,التصحيح!$AF$3:$AF$152,">="&'تحليل الفقرات'!$B$5) -> 0 | F37: =COUNTIFS(الإجابات!$J$3:$J$152,B37,التصحيح!$AF$3:$AF$152,"<="&'تحليل الفقرات'!$B$6) -> 2 | G37: =E37-F37 -> -2 | H37: =IF(C37="نعم",IF(G37>0,"المفتاح يميّز كما يجب","المفتاح لا يميّز: راجِع"),IF(D37<'تحليل الفقرات'!$B$17,"مموّه غير فعّال",IF(G37>0,"مموّه يجذب المتفوقين: راجِعه","مموّه يعمل"))) -> مموّه غير فعّال
A38: ف10 | B38: A | C38: =IF(الإجابات!$K$2=B38,"نعم","") | D38: =COUNTIF(الإجابات!$K$3:$K$152,B38)/'تحليل الفقرات'!$B$2 -> 0.18666667 | E38: =COUNTIFS(الإجابات!$K$3:$K$152,B38,التصحيح!$AF$3:$AF$152,">="&'تحليل الفقرات'!$B$5) -> 1 | F38: =COUNTIFS(الإجابات!$K$3:$K$152,B38,التصحيح!$AF$3:$AF$152,"<="&'تحليل الفقرات'!$B$6) -> 15 | G38: =E38-F38 -> -14 | H38: =IF(C38="نعم",IF(G38>0,"المفتاح يميّز كما يجب","المفتاح لا يميّز: راجِع"),IF(D38<'تحليل الفقرات'!$B$17,"مموّه غير فعّال",IF(G38>0,"مموّه يجذب المتفوقين: راجِعه","مموّه يعمل"))) -> مموّه يعمل
A39: ف10 | B39: B | C39: =IF(الإجابات!$K$2=B39,"نعم","") | D39: =COUNTIF(الإجابات!$K$3:$K$152,B39)/'تحليل الفقرات'!$B$2 -> 0.2 | E39: =COUNTIFS(الإجابات!$K$3:$K$152,B39,التصحيح!$AF$3:$AF$152,">="&'تحليل الفقرات'!$B$5) -> 2 | F39: =COUNTIFS(الإجابات!$K$3:$K$152,B39,التصحيح!$AF$3:$AF$152,"<="&'تحليل الفقرات'!$B$6) -> 12 | G39: =E39-F39 -> -10 | H39: =IF(C39="نعم",IF(G39>0,"المفتاح يميّز كما يجب","المفتاح لا يميّز: راجِع"),IF(D39<'تحليل الفقرات'!$B$17,"مموّه غير فعّال",IF(G39>0,"مموّه يجذب المتفوقين: راجِعه","مموّه يعمل"))) -> مموّه يعمل
A40: ف10 | B40: C | C40: =IF(الإجابات!$K$2=B40,"نعم","") | D40: =COUNTIF(الإجابات!$K$3:$K$152,B40)/'تحليل الفقرات'!$B$2 -> 0.12 | E40: =COUNTIFS(الإجابات!$K$3:$K$152,B40,التصحيح!$AF$3:$AF$152,">="&'تحليل الفقرات'!$B$5) -> 0 | F40: =COUNTIFS(الإجابات!$K$3:$K$152,B40,التصحيح!$AF$3:$AF$152,"<="&'تحليل الفقرات'!$B$6) -> 10 | G40: =E40-F40 -> -10 | H40: =IF(C40="نعم",IF(G40>0,"المفتاح يميّز كما يجب","المفتاح لا يميّز: راجِع"),IF(D40<'تحليل الفقرات'!$B$17,"مموّه غير فعّال",IF(G40>0,"مموّه يجذب المتفوقين: راجِعه","مموّه يعمل"))) -> مموّه يعمل
...

Sheet ملخص الاختبار
A1: المؤشر | B1: القيمة
A2: عدد الطلبة | B2: ='تحليل الفقرات'!B2 -> 150
A3: عدد الفقرات | B3: ='تحليل الفقرات'!B9 -> 30
A4: المتوسط | B4: =AVERAGE(التصحيح!$AF$3:$AF$152) -> 16.466667
A5: الانحراف المعياري | B5: ='تحليل الفقرات'!B11 -> 6.3996528
A6: أدنى درجة | B6: =MIN(التصحيح!$AF$3:$AF$152) -> 4
A7: أعلى درجة | B7: =MAX(التصحيح!$AF$3:$AF$152) -> 28
A8: كرونباخ ألفا (KR-20 للفقرات الثنائية) | B8: ='تحليل الفقرات'!B9/('تحليل الفقرات'!B9-1)*(1-'تحليل الفقرات'!B12/'تحليل الفقرات'!B10) -> 0.86980298
A9: الخطأ المعياري للقياس | B9: =B5*SQRT(1-B8) -> 2.3091754
