Workbook

Sheet Read me
A1: Week 11 workshop — Item Analysis
A2: Educational Measurement and Evaluation — Postgraduate Professional Diploma in Teaching
A4: Note: the data are a computer simulation for training purposes, not the scores of real students.
A5: 150 students × 30 multiple-choice items (four options coded A B C D).
A6: The test contains deliberately defective items. Your task is to detect them and explain the cause of each flaw.
A8: Sheets in the workbook:
A9: Responses: the raw responses of each student, with the answer key row at the top.
A10: Scoring: converting the responses to 1/0 with formulas, and each student's total score.
A11: Item Analysis: difficulty, discrimination by two methods, the reliability coefficient if the item is deleted, and an automatic recommendation.
A12: Distractor Analysis: the proportion choosing each option overall and in the upper and lower groups.
A13: Test Summary: descriptive statistics, Cronbach's alpha, the standard error of measurement, and the score distribution.
A15: Yellow cells are editable inputs (the group proportion and the decision criteria). Everything else is live formulas.
A16: Try it: correct the key of Item 7 in the Responses sheet and watch discrimination and reliability change immediately.

Sheet Responses
A1: Student ID | B1: Q1 | C1: Q2 | D1: Q3 | E1: Q4 | F1: Q5 | G1: Q6 | H1: Q7 | I1: Q8 | J1: Q9 | K1: Q10 | L1: Q11 | M1: Q12 | N1: Q13 | O1: Q14 | P1: Q15 | Q1: Q16 | R1: Q17 | S1: Q18 | T1: Q19 | U1: Q20 | V1: Q21 | W1: Q22 | X1: Q23 | Y1: Q24 | Z1: Q25 | AA1: Q26 | AB1: Q27 | AC1: Q28 | AD1: Q29 | AE1: Q30
A2: Answer key | B2: D | C2: C | D2: D | E2: B | F2: B | G2: B | H2: B | I2: C | J2: A | K2: D | L2: A | M2: C | N2: B | O2: D | P2: C | Q2: A | R2: A | S2: A | T2: D | U2: D | V2: C | W2: C | X2: C | Y2: B | Z2: C | AA2: B | AB2: B | AC2: B | AD2: C | AE2: C
A3: S001 | B3: C | C3: B | D3: B | E3: A | F3: A | G3: B | H3: B | I3: D | J3: C | K3: D | L3: A | M3: C | N3: D | O3: B | P3: D | Q3: D | R3: A | S3: C | T3: D | U3: C | V3: B | W3: D | X3: B | Y3: D | Z3: B | AA3: D | AB3: C | AC3: B | AD3: B | AE3: C
A4: S002 | B4: D | C4: C | D4: D | E4: D | F4: A | G4: A | H4: C | I4: C | J4: A | K4: D | L4: A | M4: C | N4: A | O4: C | P4: A | Q4: A | R4: A | S4: A | T4: B | U4: D | V4: C | W4: C | X4: C | Y4: A | Z4: B | AA4: D | AB4: B | AC4: B | AD4: C | AE4: A
A5: S003 | B5: B | C5: B | D5: C | E5: B | F5: C | G5: C | H5: B | I5: D | J5: A | K5: D | L5: A | M5: C | N5: A | O5: D | P5: D | Q5: A | R5: C | S5: B | T5: C | U5: A | V5: D | W5: B | X5: B | Y5: C | Z5: C | AA5: A | AB5: D | AC5: D | AD5: A | AE5: C
A6: S004 | B6: D | C6: C | D6: C | E6: B | F6: B | G6: B | H6: C | I6: C | J6: A | K6: D | L6: A | M6: C | N6: B | O6: D | P6: A | Q6: A | R6: A | S6: A | T6: D | U6: D | V6: C | W6: C | X6: C | Y6: B | Z6: C | AA6: D | AB6: C | AC6: B | AD6: C | AE6: C
A7: S005 | B7: B | C7: B | D7: B | E7: B | F7: B | G7: B | H7: C | I7: C | J7: A | K7: A | L7: A | M7: C | N7: B | O7: B | P7: A | Q7: A | R7: A | S7: D | T7: D | U7: D | V7: C | W7: C | X7: C | Y7: B | Z7: C | AA7: A | AB7: B | AC7: B | AD7: B | AE7: C
A8: S006 | B8: B | C8: B | D8: C | E8: B | F8: D | G8: C | H8: C | I8: D | J8: A | K8: C | L8: B | M8: C | N8: A | O8: D | P8: A | Q8: D | R8: A | S8: D | T8: B | U8: C | V8: C | W8: D | X8: C | Y8: A | Z8: C | AA8: C | AB8: C | AC8: C | AD8: C | AE8: C
A9: S007 | B9: C | C9: A | D9: A | E9: B | F9: D | G9: D | H9: B | I9: C | J9: A | K9: B | L9: A | M9: C | N9: B | O9: D | P9: C | Q9: A | R9: A | S9: C | T9: C | U9: C | V9: D | W9: A | X9: C | Y9: A | Z9: D | AA9: B | AB9: B | AC9: B | AD9: B | AE9: C
A10: S008 | B10: C | C10: C | D10: D | E10: B | F10: D | G10: A | H10: C | I10: C | J10: A | K10: B | L10: B | M10: C | N10: A | O10: D | P10: C | Q10: A | R10: C | S10: B | T10: A | U10: D | V10: C | W10: C | X10: C | Y10: D | Z10: C | AA10: B | AB10: A | AC10: B | AD10: A | AE10: C
A11: S009 | B11: D | C11: A | D11: C | E11: B | F11: A | G11: A | H11: C | I11: B | J11: A | K11: A | L11: B | M11: C | N11: A | O11: B | P11: A | Q11: A | R11: A | S11: B | T11: B | U11: C | V11: C | W11: D | X11: C | Y11: A | Z11: A | AA11: D | AB11: B | AC11: A | AD11: A | AE11: D
A12: S010 | B12: C | C12: C | D12: C | E12: B | F12: B | G12: A | H12: C | I12: B | J12: A | K12: D | L12: C | M12: C | N12: C | O12: D | P12: A | Q12: A | R12: A | S12: A | T12: D | U12: C | V12: C | W12: D | X12: B | Y12: C | Z12: C | AA12: B | AB12: B | AC12: D | AD12: A | AE12: A
... A152: S150 | B152: D | C152: B | D152: B | E152: B | F152: B | G152: A | H152: B | I152: C | J152: A | K152: D | L152: A | M152: C | N152: B | O152: D | P152: C | Q152: A | R152: A | S152: C | T152: C | U152: D | V152: C | W152: A | X152: B | Y152: A | Z152: C | AA152: D | AB152: A | AC152: B | AD152: C | AE152: C

Sheet Scoring
A1: Student ID | B1: Q1 | C1: Q2 | D1: Q3 | E1: Q4 | F1: Q5 | G1: Q6 | H1: Q7 | I1: Q8 | J1: Q9 | K1: Q10 | L1: Q11 | M1: Q12 | N1: Q13 | O1: Q14 | P1: Q15 | Q1: Q16 | R1: Q17 | S1: Q18 | T1: Q19 | U1: Q20 | V1: Q21 | W1: Q22 | X1: Q23 | Y1: Q24 | Z1: Q25 | AA1: Q26 | AB1: Q27 | AC1: Q28 | AD1: Q29 | AE1: Q30 | AF1: Total score
A2: Maximum score | B2: 1 | C2: 1 | D2: 1 | E2: 1 | F2: 1 | G2: 1 | H2: 1 | I2: 1 | J2: 1 | K2: 1 | L2: 1 | M2: 1 | N2: 1 | O2: 1 | P2: 1 | Q2: 1 | R2: 1 | S2: 1 | T2: 1 | U2: 1 | V2: 1 | W2: 1 | X2: 1 | Y2: 1 | Z2: 1 | AA2: 1 | AB2: 1 | AC2: 1 | AD2: 1 | AE2: 1 | AF2: =SUM(B2:AE2) -> 30
A3: =Responses!A3 -> S001 | B3: =IF(Responses!B3=Responses!B$2,1,0) -> 0 | C3: =IF(Responses!C3=Responses!C$2,1,0) -> 0 | D3: =IF(Responses!D3=Responses!D$2,1,0) -> 0 | E3: =IF(Responses!E3=Responses!E$2,1,0) -> 0 | F3: =IF(Responses!F3=Responses!F$2,1,0) -> 0 | G3: =IF(Responses!G3=Responses!G$2,1,0) -> 1 | H3: =IF(Responses!H3=Responses!H$2,1,0) -> 1 | I3: =IF(Responses!I3=Responses!I$2,1,0) -> 0 | ... AE3: =IF(Responses!AE3=Responses!AE$2,1,0) -> 1 | AF3: =SUM(B3:AE3) -> 9
A4: =Responses!A4 -> S002 | B4: =IF(Responses!B4=Responses!B$2,1,0) -> 1 | C4: =IF(Responses!C4=Responses!C$2,1,0) -> 1 | D4: =IF(Responses!D4=Responses!D$2,1,0) -> 1 | E4: =IF(Responses!E4=Responses!E$2,1,0) -> 0 | F4: =IF(Responses!F4=Responses!F$2,1,0) -> 0 | G4: =IF(Responses!G4=Responses!G$2,1,0) -> 0 | H4: =IF(Responses!H4=Responses!H$2,1,0) -> 0 | I4: =IF(Responses!I4=Responses!I$2,1,0) -> 1 | ... AE4: =IF(Responses!AE4=Responses!AE$2,1,0) -> 0 | AF4: =SUM(B4:AE4) -> 18
A5: =Responses!A5 -> S003 | B5: =IF(Responses!B5=Responses!B$2,1,0) -> 0 | C5: =IF(Responses!C5=Responses!C$2,1,0) -> 0 | D5: =IF(Responses!D5=Responses!D$2,1,0) -> 0 | E5: =IF(Responses!E5=Responses!E$2,1,0) -> 1 | F5: =IF(Responses!F5=Responses!F$2,1,0) -> 0 | G5: =IF(Responses!G5=Responses!G$2,1,0) -> 0 | H5: =IF(Responses!H5=Responses!H$2,1,0) -> 1 | I5: =IF(Responses!I5=Responses!I$2,1,0) -> 0 | ... AE5: =IF(Responses!AE5=Responses!AE$2,1,0) -> 1 | AF5: =SUM(B5:AE5) -> 10
A6: =Responses!A6 -> S004 | B6: =IF(Responses!B6=Responses!B$2,1,0) -> 1 | C6: =IF(Responses!C6=Responses!C$2,1,0) -> 1 | D6: =IF(Responses!D6=Responses!D$2,1,0) -> 0 | E6: =IF(Responses!E6=Responses!E$2,1,0) -> 1 | F6: =IF(Responses!F6=Responses!F$2,1,0) -> 1 | G6: =IF(Responses!G6=Responses!G$2,1,0) -> 1 | H6: =IF(Responses!H6=Responses!H$2,1,0) -> 0 | I6: =IF(Responses!I6=Responses!I$2,1,0) -> 1 | ... AE6: =IF(Responses!AE6=Responses!AE$2,1,0) -> 1 | AF6: =SUM(B6:AE6) -> 25
A7: =Responses!A7 -> S005 | B7: =IF(Responses!B7=Responses!B$2,1,0) -> 0 | C7: =IF(Responses!C7=Responses!C$2,1,0) -> 0 | D7: =IF(Responses!D7=Responses!D$2,1,0) -> 0 | E7: =IF(Responses!E7=Responses!E$2,1,0) -> 1 | F7: =IF(Responses!F7=Responses!F$2,1,0) -> 1 | G7: =IF(Responses!G7=Responses!G$2,1,0) -> 1 | H7: =IF(Responses!H7=Responses!H$2,1,0) -> 0 | I7: =IF(Responses!I7=Responses!I$2,1,0) -> 1 | ... AE7: =IF(Responses!AE7=Responses!AE$2,1,0) -> 1 | AF7: =SUM(B7:AE7) -> 20
A8: =Responses!A8 -> S006 | B8: =IF(Responses!B8=Responses!B$2,1,0) -> 0 | C8: =IF(Responses!C8=Responses!C$2,1,0) -> 0 | D8: =IF(Responses!D8=Responses!D$2,1,0) -> 0 | E8: =IF(Responses!E8=Responses!E$2,1,0) -> 1 | F8: =IF(Responses!F8=Responses!F$2,1,0) -> 0 | G8: =IF(Responses!G8=Responses!G$2,1,0) -> 0 | H8: =IF(Responses!H8=Responses!H$2,1,0) -> 0 | I8: =IF(Responses!I8=Responses!I$2,1,0) -> 0 | ... AE8: =IF(Responses!AE8=Responses!AE$2,1,0) -> 1 | AF8: =SUM(B8:AE8) -> 10
A9: =Responses!A9 -> S007 | B9: =IF(Responses!B9=Responses!B$2,1,0) -> 0 | C9: =IF(Responses!C9=Responses!C$2,1,0) -> 0 | D9: =IF(Responses!D9=Responses!D$2,1,0) -> 0 | E9: =IF(Responses!E9=Responses!E$2,1,0) -> 1 | F9: =IF(Responses!F9=Responses!F$2,1,0) -> 0 | G9: =IF(Responses!G9=Responses!G$2,1,0) -> 0 | H9: =IF(Responses!H9=Responses!H$2,1,0) -> 1 | I9: =IF(Responses!I9=Responses!I$2,1,0) -> 1 | ... AE9: =IF(Responses!AE9=Responses!AE$2,1,0) -> 1 | AF9: =SUM(B9:AE9) -> 16
A10: =Responses!A10 -> S008 | B10: =IF(Responses!B10=Responses!B$2,1,0) -> 0 | C10: =IF(Responses!C10=Responses!C$2,1,0) -> 1 | D10: =IF(Responses!D10=Responses!D$2,1,0) -> 1 | E10: =IF(Responses!E10=Responses!E$2,1,0) -> 1 | F10: =IF(Responses!F10=Responses!F$2,1,0) -> 0 | G10: =IF(Responses!G10=Responses!G$2,1,0) -> 0 | H10: =IF(Responses!H10=Responses!H$2,1,0) -> 0 | I10: =IF(Responses!I10=Responses!I$2,1,0) -> 1 | ... AE10: =IF(Responses!AE10=Responses!AE$2,1,0) -> 1 | AF10: =SUM(B10:AE10) -> 17
A11: =Responses!A11 -> S009 | B11: =IF(Responses!B11=Responses!B$2,1,0) -> 1 | C11: =IF(Responses!C11=Responses!C$2,1,0) -> 0 | D11: =IF(Responses!D11=Responses!D$2,1,0) -> 0 | E11: =IF(Responses!E11=Responses!E$2,1,0) -> 1 | F11: =IF(Responses!F11=Responses!F$2,1,0) -> 0 | G11: =IF(Responses!G11=Responses!G$2,1,0) -> 0 | H11: =IF(Responses!H11=Responses!H$2,1,0) -> 0 | I11: =IF(Responses!I11=Responses!I$2,1,0) -> 0 | ... AE11: =IF(Responses!AE11=Responses!AE$2,1,0) -> 0 | AF11: =SUM(B11:AE11) -> 9
A12: =Responses!A12 -> S010 | B12: =IF(Responses!B12=Responses!B$2,1,0) -> 0 | C12: =IF(Responses!C12=Responses!C$2,1,0) -> 1 | D12: =IF(Responses!D12=Responses!D$2,1,0) -> 0 | E12: =IF(Responses!E12=Responses!E$2,1,0) -> 1 | F12: =IF(Responses!F12=Responses!F$2,1,0) -> 1 | G12: =IF(Responses!G12=Responses!G$2,1,0) -> 0 | H12: =IF(Responses!H12=Responses!H$2,1,0) -> 0 | I12: =IF(Responses!I12=Responses!I$2,1,0) -> 0 | ... AE12: =IF(Responses!AE12=Responses!AE$2,1,0) -> 0 | AF12: =SUM(B12:AE12) -> 15
A13: =Responses!A13 -> S011 | B13: =IF(Responses!B13=Responses!B$2,1,0) -> 0 | C13: =IF(Responses!C13=Responses!C$2,1,0) -> 0 | D13: =IF(Responses!D13=Responses!D$2,1,0) -> 1 | E13: =IF(Responses!E13=Responses!E$2,1,0) -> 1 | F13: =IF(Responses!F13=Responses!F$2,1,0) -> 1 | G13: =IF(Responses!G13=Responses!G$2,1,0) -> 1 | H13: =IF(Responses!H13=Responses!H$2,1,0) -> 0 | I13: =IF(Responses!I13=Responses!I$2,1,0) -> 1 | ... AE13: =IF(Responses!AE13=Responses!AE$2,1,0) -> 1 | AF13: =SUM(B13:AE13) -> 21
A14: =Responses!A14 -> S012 | B14: =IF(Responses!B14=Responses!B$2,1,0) -> 1 | C14: =IF(Responses!C14=Responses!C$2,1,0) -> 1 | D14: =IF(Responses!D14=Responses!D$2,1,0) -> 0 | E14: =IF(Responses!E14=Responses!E$2,1,0) -> 1 | F14: =IF(Responses!F14=Responses!F$2,1,0) -> 0 | G14: =IF(Responses!G14=Responses!G$2,1,0) -> 1 | H14: =IF(Responses!H14=Responses!H$2,1,0) -> 0 | I14: =IF(Responses!I14=Responses!I$2,1,0) -> 1 | ... AE14: =IF(Responses!AE14=Responses!AE$2,1,0) -> 1 | AF14: =SUM(B14:AE14) -> 23
... A152: =Responses!A152 -> S150 | B152: =IF(Responses!B152=Responses!B$2,1,0) -> 1 | C152: =IF(Responses!C152=Responses!C$2,1,0) -> 0 | D152: =IF(Responses!D152=Responses!D$2,1,0) -> 0 | E152: =IF(Responses!E152=Responses!E$2,1,0) -> 1 | F152: =IF(Responses!F152=Responses!F$2,1,0) -> 1 | G152: =IF(Responses!G152=Responses!G$2,1,0) -> 0 | H152: =IF(Responses!H152=Responses!H$2,1,0) -> 1 | I152: =IF(Responses!I152=Responses!I$2,1,0) -> 1 | ... AE152: =IF(Responses!AE152=Responses!AE$2,1,0) -> 1 | AF152: =SUM(B152:AE152) -> 20

Sheet Item Analysis
A1: Parameters and criteria
A2: Number of students | B2: =COUNT(Scoring!$AF$3:$AF$152) -> 150
A3: Proportion in each group (upper/lower) | B3: 0.27
A4: Group size | B4: =ROUND(B2*B3,0) -> 41
A5: Upper group cut-off (score ≥) | B5: =LARGE(Scoring!$AF$3:$AF$152,B4) -> 21
A6: Lower group cut-off (score ≤) | B6: =SMALL(Scoring!$AF$3:$AF$152,B4) -> 11
A7: Actual size of upper group | B7: =COUNTIF(Scoring!$AF$3:$AF$152,">="&B5) -> 45
A8: Actual size of lower group | B8: =COUNTIF(Scoring!$AF$3:$AF$152,"<="&B6) -> 45
A9: Number of items k | B9: 30
A10: Variance of total score | B10: =VARP(Scoring!$AF$3:$AF$152) -> 40.955556
A11: Standard deviation of total score | B11: =SQRT(B10) -> 6.3996528
A12: Sum of item variances | B12: =SUM(G21:G50) -> 6.5197333
A13: Minimum acceptable difficulty | B13: 0.2
A14: Maximum acceptable difficulty | B14: 0.9
A15: Minimum acceptable discrimination | B15: 0.2
A16: Good discrimination threshold | B16: 0.3
A17: Minimum distractor selection | B17: 0.05
A19: Item analysis table (all values are live formulas)
A20: Item | B20: Key | C20: Difficulty p | D20: p upper group | E20: p lower group | F20: Discrimination D | G20: Item variance | H20: Item-total correlation | I20: Corrected correlation | J20: Alpha if deleted | K20: % A | L20: % B | M20: % C | N20: % D | O20: Weakest distractor | P20: Recommendation
A21: Q1 | B21: =Responses!B2 -> D | C21: =AVERAGE(Scoring!$B$3:$B$152) -> 0.43333333 | D21: =SUMIF(Scoring!$AF$3:$AF$152,">="&$B$5,Scoring!$B$3:$B$152)/$B$7 -> 0.77777778 | E21: =SUMIF(Scoring!$AF$3:$AF$152,"<="&$B$6,Scoring!$B$3:$B$152)/$B$8 -> 0.13333333 | F21: =D21-E21 -> 0.64444444 | G21: =VARP(Scoring!$B$3:$B$152) -> 0.24555556 | H21: =IF(G21=0,0,CORREL(Scoring!$B$3:$B$152,Scoring!$AF$3:$AF$152)) -> 0.54377334 | I21: =IF(G21=0,0,(H21*$B$11-SQRT(G21))/SQRT(G21+$B$10-2*H21*SQRT(G21)*$B$11)) -> 0.48572382 | J21: =($B$9-1)/($B$9-2)*(1-($B$12-G21)/($B$10+G21-2*H21*SQRT(G21)*$B$11)) -> 0.8635852 | K21: =COUNTIF(Responses!$B$3:$B$152,"A")/$B$2 -> 0.16 | L21: =COUNTIF(Responses!$B$3:$B$152,"B")/$B$2 -> 0.22 | M21: =COUNTIF(Responses!$B$3:$B$152,"C")/$B$2 -> 0.18666667 | N21: =COUNTIF(Responses!$B$3:$B$152,"D")/$B$2 -> 0.43333333 | O21: =MIN(IF(B21="A",1,K21),IF(B21="B",1,L21),IF(B21="C",1,M21),IF(B21="D",1,N21)) -> 0.16 | P21: =IF(I21<-0.1,"Discrimination negative: review the key immediately",IF(OR(C21>$B$14,C21<$B$13),"Extreme difficulty: review the wording or level",IF(I21<$B$15,"Discrimination weak: review the wording and distractors",IF(O21<$B$17,"Ineffective distractor: replace it",IF(I21<$B$16,"Acceptable and can be improved","Good"))))) -> Good
A22: Q2 | B22: =Responses!C2 -> C | C22: =AVERAGE(Scoring!$C$3:$C$152) -> 0.40666667 | D22: =SUMIF(Scoring!$AF$3:$AF$152,">="&$B$5,Scoring!$C$3:$C$152)/$B$7 -> 0.75555556 | E22: =SUMIF(Scoring!$AF$3:$AF$152,"<="&$B$6,Scoring!$C$3:$C$152)/$B$8 -> 0.13333333 | F22: =D22-E22 -> 0.62222222 | G22: =VARP(Scoring!$C$3:$C$152) -> 0.24128889 | H22: =IF(G22=0,0,CORREL(Scoring!$C$3:$C$152,Scoring!$AF$3:$AF$152)) -> 0.53131146 | I22: =IF(G22=0,0,(H22*$B$11-SQRT(G22))/SQRT(G22+$B$10-2*H22*SQRT(G22)*$B$11)) -> 0.47279584 | J22: =($B$9-1)/($B$9-2)*(1-($B$12-G22)/($B$10+G22-2*H22*SQRT(G22)*$B$11)) -> 0.86394215 | K22: =COUNTIF(Responses!$C$3:$C$152,"A")/$B$2 -> 0.19333333 | L22: =COUNTIF(Responses!$C$3:$C$152,"B")/$B$2 -> 0.23333333 | M22: =COUNTIF(Responses!$C$3:$C$152,"C")/$B$2 -> 0.40666667 | N22: =COUNTIF(Responses!$C$3:$C$152,"D")/$B$2 -> 0.16666667 | O22: =MIN(IF(B22="A",1,K22),IF(B22="B",1,L22),IF(B22="C",1,M22),IF(B22="D",1,N22)) -> 0.16666667 | P22: =IF(I22<-0.1,"Discrimination negative: review the key immediately",IF(OR(C22>$B$14,C22<$B$13),"Extreme difficulty: review the wording or level",IF(I22<$B$15,"Discrimination weak: review the wording and distractors",IF(O22<$B$17,"Ineffective distractor: replace it",IF(I22<$B$16,"Acceptable and can be improved","Good"))))) -> Good
A23: Q3 | B23: =Responses!D2 -> D | C23: =AVERAGE(Scoring!$D$3:$D$152) -> 0.37333333 | D23: =SUMIF(Scoring!$AF$3:$AF$152,">="&$B$5,Scoring!$D$3:$D$152)/$B$7 -> 0.66666667 | E23: =SUMIF(Scoring!$AF$3:$AF$152,"<="&$B$6,Scoring!$D$3:$D$152)/$B$8 -> 0.24444444 | F23: =D23-E23 -> 0.42222222 | G23: =VARP(Scoring!$D$3:$D$152) -> 0.23395556 | H23: =IF(G23=0,0,CORREL(Scoring!$D$3:$D$152,Scoring!$AF$3:$AF$152)) -> 0.41537736 | I23: =IF(G23=0,0,(H23*$B$11-SQRT(G23))/SQRT(G23+$B$10-2*H23*SQRT(G23)*$B$11)) -> 0.34992987 | J23: =($B$9-1)/($B$9-2)*(1-($B$12-G23)/($B$10+G23-2*H23*SQRT(G23)*$B$11)) -> 0.86713286 | K23: =COUNTIF(Responses!$D$3:$D$152,"A")/$B$2 -> 0.16666667 | L23: =COUNTIF(Responses!$D$3:$D$152,"B")/$B$2 -> 0.2 | M23: =COUNTIF(Responses!$D$3:$D$152,"C")/$B$2 -> 0.26 | N23: =COUNTIF(Responses!$D$3:$D$152,"D")/$B$2 -> 0.37333333 | O23: =MIN(IF(B23="A",1,K23),IF(B23="B",1,L23),IF(B23="C",1,M23),IF(B23="D",1,N23)) -> 0.16666667 | P23: =IF(I23<-0.1,"Discrimination negative: review the key immediately",IF(OR(C23>$B$14,C23<$B$13),"Extreme difficulty: review the wording or level",IF(I23<$B$15,"Discrimination weak: review the wording and distractors",IF(O23<$B$17,"Ineffective distractor: replace it",IF(I23<$B$16,"Acceptable and can be improved","Good"))))) -> Good
A24: Q4 | B24: =Responses!E2 -> B | C24: =AVERAGE(Scoring!$E$3:$E$152) -> 0.76666667 | D24: =SUMIF(Scoring!$AF$3:$AF$152,">="&$B$5,Scoring!$E$3:$E$152)/$B$7 -> 1 | E24: =SUMIF(Scoring!$AF$3:$AF$152,"<="&$B$6,Scoring!$E$3:$E$152)/$B$8 -> 0.44444444 | F24: =D24-E24 -> 0.55555556 | G24: =VARP(Scoring!$E$3:$E$152) -> 0.17888889 | H24: =IF(G24=0,0,CORREL(Scoring!$E$3:$E$152,Scoring!$AF$3:$AF$152)) -> 0.4958797 | I24: =IF(G24=0,0,(H24*$B$11-SQRT(G24))/SQRT(G24+$B$10-2*H24*SQRT(G24)*$B$11)) -> 0.4435722 | J24: =($B$9-1)/($B$9-2)*(1-($B$12-G24)/($B$10+G24-2*H24*SQRT(G24)*$B$11)) -> 0.86491316 | K24: =COUNTIF(Responses!$E$3:$E$152,"A")/$B$2 -> 0.053333333 | L24: =COUNTIF(Responses!$E$3:$E$152,"B")/$B$2 -> 0.76666667 | M24: =COUNTIF(Responses!$E$3:$E$152,"C")/$B$2 -> 0.06 | N24: =COUNTIF(Responses!$E$3:$E$152,"D")/$B$2 -> 0.12 | O24: =MIN(IF(B24="A",1,K24),IF(B24="B",1,L24),IF(B24="C",1,M24),IF(B24="D",1,N24)) -> 0.053333333 | P24: =IF(I24<-0.1,"Discrimination negative: review the key immediately",IF(OR(C24>$B$14,C24<$B$13),"Extreme difficulty: review the wording or level",IF(I24<$B$15,"Discrimination weak: review the wording and distractors",IF(O24<$B$17,"Ineffective distractor: replace it",IF(I24<$B$16,"Acceptable and can be improved","Good"))))) -> Good
A25: Q5 | B25: =Responses!F2 -> B | C25: =AVERAGE(Scoring!$F$3:$F$152) -> 0.42666667 | D25: =SUMIF(Scoring!$AF$3:$AF$152,">="&$B$5,Scoring!$F$3:$F$152)/$B$7 -> 0.71111111 | E25: =SUMIF(Scoring!$AF$3:$AF$152,"<="&$B$6,Scoring!$F$3:$F$152)/$B$8 -> 0.13333333 | F25: =D25-E25 -> 0.57777778 | G25: =VARP(Scoring!$F$3:$F$152) -> 0.24462222 | H25: =IF(G25=0,0,CORREL(Scoring!$F$3:$F$152,Scoring!$AF$3:$AF$152)) -> 0.50577438 | I25: =IF(G25=0,0,(H25*$B$11-SQRT(G25))/SQRT(G25+$B$10-2*H25*SQRT(G25)*$B$11)) -> 0.44485091 | J25: =($B$9-1)/($B$9-2)*(1-($B$12-G25)/($B$10+G25-2*H25*SQRT(G25)*$B$11)) -> 0.86467492 | K25: =COUNTIF(Responses!$F$3:$F$152,"A")/$B$2 -> 0.28666667 | L25: =COUNTIF(Responses!$F$3:$F$152,"B")/$B$2 -> 0.42666667 | M25: =COUNTIF(Responses!$F$3:$F$152,"C")/$B$2 -> 0.17333333 | N25: =COUNTIF(Responses!$F$3:$F$152,"D")/$B$2 -> 0.11333333 | O25: =MIN(IF(B25="A",1,K25),IF(B25="B",1,L25),IF(B25="C",1,M25),IF(B25="D",1,N25)) -> 0.11333333 | P25: =IF(I25<-0.1,"Discrimination negative: review the key immediately",IF(OR(C25>$B$14,C25<$B$13),"Extreme difficulty: review the wording or level",IF(I25<$B$15,"Discrimination weak: review the wording and distractors",IF(O25<$B$17,"Ineffective distractor: replace it",IF(I25<$B$16,"Acceptable and can be improved","Good"))))) -> Good
A26: Q6 | B26: =Responses!G2 -> B | C26: =AVERAGE(Scoring!$G$3:$G$152) -> 0.47333333 | D26: =SUMIF(Scoring!$AF$3:$AF$152,">="&$B$5,Scoring!$G$3:$G$152)/$B$7 -> 0.82222222 | E26: =SUMIF(Scoring!$AF$3:$AF$152,"<="&$B$6,Scoring!$G$3:$G$152)/$B$8 -> 0.22222222 | F26: =D26-E26 -> 0.6 | G26: =VARP(Scoring!$G$3:$G$152) -> 0.24928889 | H26: =IF(G26=0,0,CORREL(Scoring!$G$3:$G$152,Scoring!$AF$3:$AF$152)) -> 0.48168387 | I26: =IF(G26=0,0,(H26*$B$11-SQRT(G26))/SQRT(G26+$B$10-2*H26*SQRT(G26)*$B$11)) -> 0.41837356 | J26: =($B$9-1)/($B$9-2)*(1-($B$12-G26)/($B$10+G26-2*H26*SQRT(G26)*$B$11)) -> 0.86537691 | K26: =COUNTIF(Responses!$G$3:$G$152,"A")/$B$2 -> 0.22666667 | L26: =COUNTIF(Responses!$G$3:$G$152,"B")/$B$2 -> 0.47333333 | M26: =COUNTIF(Responses!$G$3:$G$152,"C")/$B$2 -> 0.12666667 | N26: =COUNTIF(Responses!$G$3:$G$152,"D")/$B$2 -> 0.17333333 | O26: =MIN(IF(B26="A",1,K26),IF(B26="B",1,L26),IF(B26="C",1,M26),IF(B26="D",1,N26)) -> 0.12666667 | P26: =IF(I26<-0.1,"Discrimination negative: review the key immediately",IF(OR(C26>$B$14,C26<$B$13),"Extreme difficulty: review the wording or level",IF(I26<$B$15,"Discrimination weak: review the wording and distractors",IF(O26<$B$17,"Ineffective distractor: replace it",IF(I26<$B$16,"Acceptable and can be improved","Good"))))) -> Good
A27: Q7 | B27: =Responses!H2 -> B | C27: =AVERAGE(Scoring!$H$3:$H$152) -> 0.25333333 | D27: =SUMIF(Scoring!$AF$3:$AF$152,">="&$B$5,Scoring!$H$3:$H$152)/$B$7 -> 0.044444444 | E27: =SUMIF(Scoring!$AF$3:$AF$152,"<="&$B$6,Scoring!$H$3:$H$152)/$B$8 -> 0.44444444 | F27: =D27-E27 -> -0.4 | G27: =VARP(Scoring!$H$3:$H$152) -> 0.18915556 | H27: =IF(G27=0,0,CORREL(Scoring!$H$3:$H$152,Scoring!$AF$3:$AF$152)) -> -0.37301334 | I27: =IF(G27=0,0,(H27*$B$11-SQRT(G27))/SQRT(G27+$B$10-2*H27*SQRT(G27)*$B$11)) -> -0.4292601 | J27: =($B$9-1)/($B$9-2)*(1-($B$12-G27)/($B$10+G27-2*H27*SQRT(G27)*$B$11)) -> 0.88401381 | K27: =COUNTIF(Responses!$H$3:$H$152,"A")/$B$2 -> 0.033333333 | L27: =COUNTIF(Responses!$H$3:$H$152,"B")/$B$2 -> 0.25333333 | M27: =COUNTIF(Responses!$H$3:$H$152,"C")/$B$2 -> 0.68 | N27: =COUNTIF(Responses!$H$3:$H$152,"D")/$B$2 -> 0.033333333 | O27: =MIN(IF(B27="A",1,K27),IF(B27="B",1,L27),IF(B27="C",1,M27),IF(B27="D",1,N27)) -> 0.033333333 | P27: =IF(I27<-0.1,"Discrimination negative: review the key immediately",IF(OR(C27>$B$14,C27<$B$13),"Extreme difficulty: review the wording or level",IF(I27<$B$15,"Discrimination weak: review the wording and distractors",IF(O27<$B$17,"Ineffective distractor: replace it",IF(I27<$B$16,"Acceptable and can be improved","Good"))))) -> Discrimination negative: review the key immediately
A28: Q8 | B28: =Responses!I2 -> C | C28: =AVERAGE(Scoring!$I$3:$I$152) -> 0.66 | D28: =SUMIF(Scoring!$AF$3:$AF$152,">="&$B$5,Scoring!$I$3:$I$152)/$B$7 -> 0.97777778 | E28: =SUMIF(Scoring!$AF$3:$AF$152,"<="&$B$6,Scoring!$I$3:$I$152)/$B$8 -> 0.26666667 | F28: =D28-E28 -> 0.71111111 | G28: =VARP(Scoring!$I$3:$I$152) -> 0.2244 | H28: =IF(G28=0,0,CORREL(Scoring!$I$3:$I$152,Scoring!$AF$3:$AF$152)) -> 0.61750149 | I28: =IF(G28=0,0,(H28*$B$11-SQRT(G28))/SQRT(G28+$B$10-2*H28*SQRT(G28)*$B$11)) -> 0.56845474 | J28: =($B$9-1)/($B$9-2)*(1-($B$12-G28)/($B$10+G28-2*H28*SQRT(G28)*$B$11)) -> 0.86154572 | K28: =COUNTIF(Responses!$I$3:$I$152,"A")/$B$2 -> 0.13333333 | L28: =COUNTIF(Responses!$I$3:$I$152,"B")/$B$2 -> 0.1 | M28: =COUNTIF(Responses!$I$3:$I$152,"C")/$B$2 -> 0.66 | N28: =COUNTIF(Responses!$I$3:$I$152,"D")/$B$2 -> 0.10666667 | O28: =MIN(IF(B28="A",1,K28),IF(B28="B",1,L28),IF(B28="C",1,M28),IF(B28="D",1,N28)) -> 0.1 | P28: =IF(I28<-0.1,"Discrimination negative: review the key immediately",IF(OR(C28>$B$14,C28<$B$13),"Extreme difficulty: review the wording or level",IF(I28<$B$15,"Discrimination weak: review the wording and distractors",IF(O28<$B$17,"Ineffective distractor: replace it",IF(I28<$B$16,"Acceptable and can be improved","Good"))))) -> Good
A29: Q9 | B29: =Responses!J2 -> A | C29: =AVERAGE(Scoring!$J$3:$J$152) -> 0.90666667 | D29: =SUMIF(Scoring!$AF$3:$AF$152,">="&$B$5,Scoring!$J$3:$J$152)/$B$7 -> 1 | E29: =SUMIF(Scoring!$AF$3:$AF$152,"<="&$B$6,Scoring!$J$3:$J$152)/$B$8 -> 0.75555556 | F29: =D29-E29 -> 0.24444444 | G29: =VARP(Scoring!$J$3:$J$152) -> 0.084622222 | H29: =IF(G29=0,0,CORREL(Scoring!$J$3:$J$152,Scoring!$AF$3:$AF$152)) -> 0.34210943 | I29: =IF(G29=0,0,(H29*$B$11-SQRT(G29))/SQRT(G29+$B$10-2*H29*SQRT(G29)*$B$11)) -> 0.30105683 | J29: =($B$9-1)/($B$9-2)*(1-($B$12-G29)/($B$10+G29-2*H29*SQRT(G29)*$B$11)) -> 0.86811208 | K29: =COUNTIF(Responses!$J$3:$J$152,"A")/$B$2 -> 0.90666667 | L29: =COUNTIF(Responses!$J$3:$J$152,"B")/$B$2 -> 0.04 | M29: =COUNTIF(Responses!$J$3:$J$152,"C")/$B$2 -> 0.033333333 | N29: =COUNTIF(Responses!$J$3:$J$152,"D")/$B$2 -> 0.02 | O29: =MIN(IF(B29="A",1,K29),IF(B29="B",1,L29),IF(B29="C",1,M29),IF(B29="D",1,N29)) -> 0.02 | P29: =IF(I29<-0.1,"Discrimination negative: review the key immediately",IF(OR(C29>$B$14,C29<$B$13),"Extreme difficulty: review the wording or level",IF(I29<$B$15,"Discrimination weak: review the wording and distractors",IF(O29<$B$17,"Ineffective distractor: replace it",IF(I29<$B$16,"Acceptable and can be improved","Good"))))) -> Extreme difficulty: review the wording or level
A30: Q10 | B30: =Responses!K2 -> D | C30: =AVERAGE(Scoring!$K$3:$K$152) -> 0.49333333 | D30: =SUMIF(Scoring!$AF$3:$AF$152,">="&$B$5,Scoring!$K$3:$K$152)/$B$7 -> 0.93333333 | E30: =SUMIF(Scoring!$AF$3:$AF$152,"<="&$B$6,Scoring!$K$3:$K$152)/$B$8 -> 0.17777778 | F30: =D30-E30 -> 0.75555556 | G30: =VARP(Scoring!$K$3:$K$152) -> 0.24995556 | H30: =IF(G30=0,0,CORREL(Scoring!$K$3:$K$152,Scoring!$AF$3:$AF$152)) -> 0.62814547 | I30: =IF(G30=0,0,(H30*$B$11-SQRT(G30))/SQRT(G30+$B$10-2*H30*SQRT(G30)*$B$11)) -> 0.57722872 | J30: =($B$9-1)/($B$9-2)*(1-($B$12-G30)/($B$10+G30-2*H30*SQRT(G30)*$B$11)) -> 0.86108657 | K30: =COUNTIF(Responses!$K$3:$K$152,"A")/$B$2 -> 0.18666667 | L30: =COUNTIF(Responses!$K$3:$K$152,"B")/$B$2 -> 0.2 | M30: =COUNTIF(Responses!$K$3:$K$152,"C")/$B$2 -> 0.12 | N30: =COUNTIF(Responses!$K$3:$K$152,"D")/$B$2 -> 0.49333333 | O30: =MIN(IF(B30="A",1,K30),IF(B30="B",1,L30),IF(B30="C",1,M30),IF(B30="D",1,N30)) -> 0.12 | P30: =IF(I30<-0.1,"Discrimination negative: review the key immediately",IF(OR(C30>$B$14,C30<$B$13),"Extreme difficulty: review the wording or level",IF(I30<$B$15,"Discrimination weak: review the wording and distractors",IF(O30<$B$17,"Ineffective distractor: replace it",IF(I30<$B$16,"Acceptable and can be improved","Good"))))) -> Good
A31: Q11 | B31: =Responses!L2 -> A | C31: =AVERAGE(Scoring!$L$3:$L$152) -> 0.62 | D31: =SUMIF(Scoring!$AF$3:$AF$152,">="&$B$5,Scoring!$L$3:$L$152)/$B$7 -> 0.93333333 | E31: =SUMIF(Scoring!$AF$3:$AF$152,"<="&$B$6,Scoring!$L$3:$L$152)/$B$8 -> 0.22222222 | F31: =D31-E31 -> 0.71111111 | G31: =VARP(Scoring!$L$3:$L$152) -> 0.2356 | H31: =IF(G31=0,0,CORREL(Scoring!$L$3:$L$152,Scoring!$AF$3:$AF$152)) -> 0.58075436 | I31: =IF(G31=0,0,(H31*$B$11-SQRT(G31))/SQRT(G31+$B$10-2*H31*SQRT(G31)*$B$11)) -> 0.52707518 | J31: =($B$9-1)/($B$9-2)*(1-($B$12-G31)/($B$10+G31-2*H31*SQRT(G31)*$B$11)) -> 0.86253653 | K31: =COUNTIF(Responses!$L$3:$L$152,"A")/$B$2 -> 0.62 | L31: =COUNTIF(Responses!$L$3:$L$152,"B")/$B$2 -> 0.21333333 | M31: =COUNTIF(Responses!$L$3:$L$152,"C")/$B$2 -> 0.13333333 | N31: =COUNTIF(Responses!$L$3:$L$152,"D")/$B$2 -> 0.033333333 | O31: =MIN(IF(B31="A",1,K31),IF(B31="B",1,L31),IF(B31="C",1,M31),IF(B31="D",1,N31)) -> 0.033333333 | P31: =IF(I31<-0.1,"Discrimination negative: review the key immediately",IF(OR(C31>$B$14,C31<$B$13),"Extreme difficulty: review the wording or level",IF(I31<$B$15,"Discrimination weak: review the wording and distractors",IF(O31<$B$17,"Ineffective distractor: replace it",IF(I31<$B$16,"Acceptable and can be improved","Good"))))) -> Ineffective distractor: replace it
A32: Q12 | B32: =Responses!M2 -> C | C32: =AVERAGE(Scoring!$M$3:$M$152) -> 0.97333333 | D32: =SUMIF(Scoring!$AF$3:$AF$152,">="&$B$5,Scoring!$M$3:$M$152)/$B$7 -> 1 | E32: =SUMIF(Scoring!$AF$3:$AF$152,"<="&$B$6,Scoring!$M$3:$M$152)/$B$8 -> 0.91111111 | F32: =D32-E32 -> 0.088888889 | G32: =VARP(Scoring!$M$3:$M$152) -> 0.025955556 | H32: =IF(G32=0,0,CORREL(Scoring!$M$3:$M$152,Scoring!$AF$3:$AF$152)) -> 0.24484669 | I32: =IF(G32=0,0,(H32*$B$11-SQRT(G32))/SQRT(G32+$B$10-2*H32*SQRT(G32)*$B$11)) -> 0.22096811 | J32: =($B$9-1)/($B$9-2)*(1-($B$12-G32)/($B$10+G32-2*H32*SQRT(G32)*$B$11)) -> 0.86955174 | K32: =COUNTIF(Responses!$M$3:$M$152,"A")/$B$2 -> 0.013333333 | L32: =COUNTIF(Responses!$M$3:$M$152,"B")/$B$2 -> 0.0066666667 | M32: =COUNTIF(Responses!$M$3:$M$152,"C")/$B$2 -> 0.97333333 | N32: =COUNTIF(Responses!$M$3:$M$152,"D")/$B$2 -> 0.0066666667 | O32: =MIN(IF(B32="A",1,K32),IF(B32="B",1,L32),IF(B32="C",1,M32),IF(B32="D",1,N32)) -> 0.0066666667 | P32: =IF(I32<-0.1,"Discrimination negative: review the key immediately",IF(OR(C32>$B$14,C32<$B$13),"Extreme difficulty: review the wording or level",IF(I32<$B$15,"Discrimination weak: review the wording and distractors",IF(O32<$B$17,"Ineffective distractor: replace it",IF(I32<$B$16,"Acceptable and can be improved","Good"))))) -> Extreme difficulty: review the wording or level
A33: Q13 | B33: =Responses!N2 -> B | C33: =AVERAGE(Scoring!$N$3:$N$152) -> 0.41333333 | D33: =SUMIF(Scoring!$AF$3:$AF$152,">="&$B$5,Scoring!$N$3:$N$152)/$B$7 -> 0.84444444 | E33: =SUMIF(Scoring!$AF$3:$AF$152,"<="&$B$6,Scoring!$N$3:$N$152)/$B$8 -> 0.044444444 | F33: =D33-E33 -> 0.8 | G33: =VARP(Scoring!$N$3:$N$152) -> 0.24248889 | H33: =IF(G33=0,0,CORREL(Scoring!$N$3:$N$152,Scoring!$AF$3:$AF$152)) -> 0.65593603 | I33: =IF(G33=0,0,(H33*$B$11-SQRT(G33))/SQRT(G33+$B$10-2*H33*SQRT(G33)*$B$11)) -> 0.60862801 | J33: =($B$9-1)/($B$9-2)*(1-($B$12-G33)/($B$10+G33-2*H33*SQRT(G33)*$B$11)) -> 0.86030249 | K33: =COUNTIF(Responses!$N$3:$N$152,"A")/$B$2 -> 0.26666667 | L33: =COUNTIF(Responses!$N$3:$N$152,"B")/$B$2 -> 0.41333333 | M33: =COUNTIF(Responses!$N$3:$N$152,"C")/$B$2 -> 0.18 | N33: =COUNTIF(Responses!$N$3:$N$152,"D")/$B$2 -> 0.14 | O33: =MIN(IF(B33="A",1,K33),IF(B33="B",1,L33),IF(B33="C",1,M33),IF(B33="D",1,N33)) -> 0.14 | P33: =IF(I33<-0.1,"Discrimination negative: review the key immediately",IF(OR(C33>$B$14,C33<$B$13),"Extreme difficulty: review the wording or level",IF(I33<$B$15,"Discrimination weak: review the wording and distractors",IF(O33<$B$17,"Ineffective distractor: replace it",IF(I33<$B$16,"Acceptable and can be improved","Good"))))) -> Good
A34: Q14 | B34: =Responses!O2 -> D | C34: =AVERAGE(Scoring!$O$3:$O$152) -> 0.62 | D34: =SUMIF(Scoring!$AF$3:$AF$152,">="&$B$5,Scoring!$O$3:$O$152)/$B$7 -> 0.91111111 | E34: =SUMIF(Scoring!$AF$3:$AF$152,"<="&$B$6,Scoring!$O$3:$O$152)/$B$8 -> 0.35555556 | F34: =D34-E34 -> 0.55555556 | G34: =VARP(Scoring!$O$3:$O$152) -> 0.2356 | H34: =IF(G34=0,0,CORREL(Scoring!$O$3:$O$152,Scoring!$AF$3:$AF$152)) -> 0.48203041 | I34: =IF(G34=0,0,(H34*$B$11-SQRT(G34))/SQRT(G34+$B$10-2*H34*SQRT(G34)*$B$11)) -> 0.42059898 | J34: =($B$9-1)/($B$9-2)*(1-($B$12-G34)/($B$10+G34-2*H34*SQRT(G34)*$B$11)) -> 0.8653173 | K34: =COUNTIF(Responses!$O$3:$O$152,"A")/$B$2 -> 0.08 | L34: =COUNTIF(Responses!$O$3:$O$152,"B")/$B$2 -> 0.18 | M34: =COUNTIF(Responses!$O$3:$O$152,"C")/$B$2 -> 0.12 | N34: =COUNTIF(Responses!$O$3:$O$152,"D")/$B$2 -> 0.62 | O34: =MIN(IF(B34="A",1,K34),IF(B34="B",1,L34),IF(B34="C",1,M34),IF(B34="D",1,N34)) -> 0.08 | P34: =IF(I34<-0.1,"Discrimination negative: review the key immediately",IF(OR(C34>$B$14,C34<$B$13),"Extreme difficulty: review the wording or level",IF(I34<$B$15,"Discrimination weak: review the wording and distractors",IF(O34<$B$17,"Ineffective distractor: replace it",IF(I34<$B$16,"Acceptable and can be improved","Good"))))) -> Good
A35: Q15 | B35: =Responses!P2 -> C | C35: =AVERAGE(Scoring!$P$3:$P$152) -> 0.4 | D35: =SUMIF(Scoring!$AF$3:$AF$152,">="&$B$5,Scoring!$P$3:$P$152)/$B$7 -> 0.42222222 | E35: =SUMIF(Scoring!$AF$3:$AF$152,"<="&$B$6,Scoring!$P$3:$P$152)/$B$8 -> 0.15555556 | F35: =D35-E35 -> 0.26666667 | G35: =VARP(Scoring!$P$3:$P$152) -> 0.24 | H35: =IF(G35=0,0,CORREL(Scoring!$P$3:$P$152,Scoring!$AF$3:$AF$152)) -> 0.22114649 | I35: =IF(G35=0,0,(H35*$B$11-SQRT(G35))/SQRT(G35+$B$10-2*H35*SQRT(G35)*$B$11)) -> 0.14666349 | J35: =($B$9-1)/($B$9-2)*(1-($B$12-G35)/($B$10+G35-2*H35*SQRT(G35)*$B$11)) -> 0.87233345 | K35: =COUNTIF(Responses!$P$3:$P$152,"A")/$B$2 -> 0.37333333 | L35: =COUNTIF(Responses!$P$3:$P$152,"B")/$B$2 -> 0.08 | M35: =COUNTIF(Responses!$P$3:$P$152,"C")/$B$2 -> 0.4 | N35: =COUNTIF(Responses!$P$3:$P$152,"D")/$B$2 -> 0.14666667 | O35: =MIN(IF(B35="A",1,K35),IF(B35="B",1,L35),IF(B35="C",1,M35),IF(B35="D",1,N35)) -> 0.08 | P35: =IF(I35<-0.1,"Discrimination negative: review the key immediately",IF(OR(C35>$B$14,C35<$B$13),"Extreme difficulty: review the wording or level",IF(I35<$B$15,"Discrimination weak: review the wording and distractors",IF(O35<$B$17,"Ineffective distractor: replace it",IF(I35<$B$16,"Acceptable and can be improved","Good"))))) -> Discrimination weak: review the wording and distractors
A36: Q16 | B36: =Responses!Q2 -> A | C36: =AVERAGE(Scoring!$Q$3:$Q$152) -> 0.84 | D36: =SUMIF(Scoring!$AF$3:$AF$152,">="&$B$5,Scoring!$Q$3:$Q$152)/$B$7 -> 1 | E36: =SUMIF(Scoring!$AF$3:$AF$152,"<="&$B$6,Scoring!$Q$3:$Q$152)/$B$8 -> 0.57777778 | F36: =D36-E36 -> 0.42222222 | G36: =VARP(Scoring!$Q$3:$Q$152) -> 0.1344 | H36: =IF(G36=0,0,CORREL(Scoring!$Q$3:$Q$152,Scoring!$AF$3:$AF$152)) -> 0.46373818 | I36: =IF(G36=0,0,(H36*$B$11-SQRT(G36))/SQRT(G36+$B$10-2*H36*SQRT(G36)*$B$11)) -> 0.41697875 | J36: =($B$9-1)/($B$9-2)*(1-($B$12-G36)/($B$10+G36-2*H36*SQRT(G36)*$B$11)) -> 0.86576546 | K36: =COUNTIF(Responses!$Q$3:$Q$152,"A")/$B$2 -> 0.84 | L36: =COUNTIF(Responses!$Q$3:$Q$152,"B")/$B$2 -> 0.053333333 | M36: =COUNTIF(Responses!$Q$3:$Q$152,"C")/$B$2 -> 0.053333333 | N36: =COUNTIF(Responses!$Q$3:$Q$152,"D")/$B$2 -> 0.053333333 | O36: =MIN(IF(B36="A",1,K36),IF(B36="B",1,L36),IF(B36="C",1,M36),IF(B36="D",1,N36)) -> 0.053333333 | P36: =IF(I36<-0.1,"Discrimination negative: review the key immediately",IF(OR(C36>$B$14,C36<$B$13),"Extreme difficulty: review the wording or level",IF(I36<$B$15,"Discrimination weak: review the wording and distractors",IF(O36<$B$17,"Ineffective distractor: replace it",IF(I36<$B$16,"Acceptable and can be improved","Good"))))) -> Good
A37: Q17 | B37: =Responses!R2 -> A | C37: =AVERAGE(Scoring!$R$3:$R$152) -> 0.86666667 | D37: =SUMIF(Scoring!$AF$3:$AF$152,">="&$B$5,Scoring!$R$3:$R$152)/$B$7 -> 1 | E37: =SUMIF(Scoring!$AF$3:$AF$152,"<="&$B$6,Scoring!$R$3:$R$152)/$B$8 -> 0.6 | F37: =D37-E37 -> 0.4 | G37: =VARP(Scoring!$R$3:$R$152) -> 0.11555556 | H37: =IF(G37=0,0,CORREL(Scoring!$R$3:$R$152,Scoring!$AF$3:$AF$152)) -> 0.4484357 | I37: =IF(G37=0,0,(H37*$B$11-SQRT(G37))/SQRT(G37+$B$10-2*H37*SQRT(G37)*$B$11)) -> 0.40448611 | J37: =($B$9-1)/($B$9-2)*(1-($B$12-G37)/($B$10+G37-2*H37*SQRT(G37)*$B$11)) -> 0.86616167 | K37: =COUNTIF(Responses!$R$3:$R$152,"A")/$B$2 -> 0.86666667 | L37: =COUNTIF(Responses!$R$3:$R$152,"B")/$B$2 -> 0.066666667 | M37: =COUNTIF(Responses!$R$3:$R$152,"C")/$B$2 -> 0.046666667 | N37: =COUNTIF(Responses!$R$3:$R$152,"D")/$B$2 -> 0.02 | O37: =MIN(IF(B37="A",1,K37),IF(B37="B",1,L37),IF(B37="C",1,M37),IF(B37="D",1,N37)) -> 0.02 | P37: =IF(I37<-0.1,"Discrimination negative: review the key immediately",IF(OR(C37>$B$14,C37<$B$13),"Extreme difficulty: review the wording or level",IF(I37<$B$15,"Discrimination weak: review the wording and distractors",IF(O37<$B$17,"Ineffective distractor: replace it",IF(I37<$B$16,"Acceptable and can be improved","Good"))))) -> Ineffective distractor: replace it
A38: Q18 | B38: =Responses!S2 -> A | C38: =AVERAGE(Scoring!$S$3:$S$152) -> 0.24 | D38: =SUMIF(Scoring!$AF$3:$AF$152,">="&$B$5,Scoring!$S$3:$S$152)/$B$7 -> 0.28888889 | E38: =SUMIF(Scoring!$AF$3:$AF$152,"<="&$B$6,Scoring!$S$3:$S$152)/$B$8 -> 0.2 | F38: =D38-E38 -> 0.088888889 | G38: =VARP(Scoring!$S$3:$S$152) -> 0.1824 | H38: =IF(G38=0,0,CORREL(Scoring!$S$3:$S$152,Scoring!$AF$3:$AF$152)) -> 0.098054147 | I38: =IF(G38=0,0,(H38*$B$11-SQRT(G38))/SQRT(G38+$B$10-2*H38*SQRT(G38)*$B$11)) -> 0.031454868 | J38: =($B$9-1)/($B$9-2)*(1-($B$12-G38)/($B$10+G38-2*H38*SQRT(G38)*$B$11)) -> 0.87405541 | K38: =COUNTIF(Responses!$S$3:$S$152,"A")/$B$2 -> 0.24 | L38: =COUNTIF(Responses!$S$3:$S$152,"B")/$B$2 -> 0.25333333 | M38: =COUNTIF(Responses!$S$3:$S$152,"C")/$B$2 -> 0.26666667 | N38: =COUNTIF(Responses!$S$3:$S$152,"D")/$B$2 -> 0.24 | O38: =MIN(IF(B38="A",1,K38),IF(B38="B",1,L38),IF(B38="C",1,M38),IF(B38="D",1,N38)) -> 0.24 | P38: =IF(I38<-0.1,"Discrimination negative: review the key immediately",IF(OR(C38>$B$14,C38<$B$13),"Extreme difficulty: review the wording or level",IF(I38<$B$15,"Discrimination weak: review the wording and distractors",IF(O38<$B$17,"Ineffective distractor: replace it",IF(I38<$B$16,"Acceptable and can be improved","Good"))))) -> Discrimination weak: review the wording and distractors
A39: Q19 | B39: =Responses!T2 -> D | C39: =AVERAGE(Scoring!$T$3:$T$152) -> 0.56666667 | D39: =SUMIF(Scoring!$AF$3:$AF$152,">="&$B$5,Scoring!$T$3:$T$152)/$B$7 -> 0.8 | E39: =SUMIF(Scoring!$AF$3:$AF$152,"<="&$B$6,Scoring!$T$3:$T$152)/$B$8 -> 0.35555556 | F39: =D39-E39 -> 0.44444444 | G39: =VARP(Scoring!$T$3:$T$152) -> 0.24555556 | H39: =IF(G39=0,0,CORREL(Scoring!$T$3:$T$152,Scoring!$AF$3:$AF$152)) -> 0.38120193 | I39: =IF(G39=0,0,(H39*$B$11-SQRT(G39))/SQRT(G39+$B$10-2*H39*SQRT(G39)*$B$11)) -> 0.31216136 | J39: =($B$9-1)/($B$9-2)*(1-($B$12-G39)/($B$10+G39-2*H39*SQRT(G39)*$B$11)) -> 0.8681615 | K39: =COUNTIF(Responses!$T$3:$T$152,"A")/$B$2 -> 0.15333333 | L39: =COUNTIF(Responses!$T$3:$T$152,"B")/$B$2 -> 0.1 | M39: =COUNTIF(Responses!$T$3:$T$152,"C")/$B$2 -> 0.18 | N39: =COUNTIF(Responses!$T$3:$T$152,"D")/$B$2 -> 0.56666667 | O39: =MIN(IF(B39="A",1,K39),IF(B39="B",1,L39),IF(B39="C",1,M39),IF(B39="D",1,N39)) -> 0.1 | P39: =IF(I39<-0.1,"Discrimination negative: review the key immediately",IF(OR(C39>$B$14,C39<$B$13),"Extreme difficulty: review the wording or level",IF(I39<$B$15,"Discrimination weak: review the wording and distractors",IF(O39<$B$17,"Ineffective distractor: replace it",IF(I39<$B$16,"Acceptable and can be improved","Good"))))) -> Good
A40: Q20 | B40: =Responses!U2 -> D | C40: =AVERAGE(Scoring!$U$3:$U$152) -> 0.52 | D40: =SUMIF(Scoring!$AF$3:$AF$152,">="&$B$5,Scoring!$U$3:$U$152)/$B$7 -> 0.93333333 | E40: =SUMIF(Scoring!$AF$3:$AF$152,"<="&$B$6,Scoring!$U$3:$U$152)/$B$8 -> 0.13333333 | F40: =D40-E40 -> 0.8 | G40: =VARP(Scoring!$U$3:$U$152) -> 0.2496 | H40: =IF(G40=0,0,CORREL(Scoring!$U$3:$U$152,Scoring!$AF$3:$AF$152)) -> 0.64763676 | I40: =IF(G40=0,0,(H40*$B$11-SQRT(G40))/SQRT(G40+$B$10-2*H40*SQRT(G40)*$B$11)) -> 0.59872646 | J40: =($B$9-1)/($B$9-2)*(1-($B$12-G40)/($B$10+G40-2*H40*SQRT(G40)*$B$11)) -> 0.8605012 | K40: =COUNTIF(Responses!$U$3:$U$152,"A")/$B$2 -> 0.16666667 | L40: =COUNTIF(Responses!$U$3:$U$152,"B")/$B$2 -> 0.15333333 | M40: =COUNTIF(Responses!$U$3:$U$152,"C")/$B$2 -> 0.16 | N40: =COUNTIF(Responses!$U$3:$U$152,"D")/$B$2 -> 0.52 | O40: =MIN(IF(B40="A",1,K40),IF(B40="B",1,L40),IF(B40="C",1,M40),IF(B40="D",1,N40)) -> 0.15333333 | P40: =IF(I40<-0.1,"Discrimination negative: review the key immediately",IF(OR(C40>$B$14,C40<$B$13),"Extreme difficulty: review the wording or level",IF(I40<$B$15,"Discrimination weak: review the wording and distractors",IF(O40<$B$17,"Ineffective distractor: replace it",IF(I40<$B$16,"Acceptable and can be improved","Good"))))) -> Good
A41: Q21 | B41: =Responses!V2 -> C | C41: =AVERAGE(Scoring!$V$3:$V$152) -> 0.55333333 | D41: =SUMIF(Scoring!$AF$3:$AF$152,">="&$B$5,Scoring!$V$3:$V$152)/$B$7 -> 0.93333333 | E41: =SUMIF(Scoring!$AF$3:$AF$152,"<="&$B$6,Scoring!$V$3:$V$152)/$B$8 -> 0.28888889 | F41: =D41-E41 -> 0.64444444 | G41: =VARP(Scoring!$V$3:$V$152) -> 0.24715556 | H41: =IF(G41=0,0,CORREL(Scoring!$V$3:$V$152,Scoring!$AF$3:$AF$152)) -> 0.54536303 | I41: =IF(G41=0,0,(H41*$B$11-SQRT(G41))/SQRT(G41+$B$10-2*H41*SQRT(G41)*$B$11)) -> 0.48724461 | J41: =($B$9-1)/($B$9-2)*(1-($B$12-G41)/($B$10+G41-2*H41*SQRT(G41)*$B$11)) -> 0.8635391 | K41: =COUNTIF(Responses!$V$3:$V$152,"A")/$B$2 -> 0.18 | L41: =COUNTIF(Responses!$V$3:$V$152,"B")/$B$2 -> 0.12 | M41: =COUNTIF(Responses!$V$3:$V$152,"C")/$B$2 -> 0.55333333 | N41: =COUNTIF(Responses!$V$3:$V$152,"D")/$B$2 -> 0.14666667 | O41: =MIN(IF(B41="A",1,K41),IF(B41="B",1,L41),IF(B41="C",1,M41),IF(B41="D",1,N41)) -> 0.12 | P41: =IF(I41<-0.1,"Discrimination negative: review the key immediately",IF(OR(C41>$B$14,C41<$B$13),"Extreme difficulty: review the wording or level",IF(I41<$B$15,"Discrimination weak: review the wording and distractors",IF(O41<$B$17,"Ineffective distractor: replace it",IF(I41<$B$16,"Acceptable and can be improved","Good"))))) -> Good
...

Sheet Distractor Analysis
A1: Item | B1: Option | C1: Is it the key? | D1: Selection rate (all) | E1: Upper group count | F1: Lower group count | G1: Difference (upper − lower) | H1: Reading
A2: Q1 | B2: A | C2: =IF(Responses!$B$2=B2,"Yes","") | D2: =COUNTIF(Responses!$B$3:$B$152,B2)/'Item Analysis'!$B$2 -> 0.16 | E2: =COUNTIFS(Responses!$B$3:$B$152,B2,Scoring!$AF$3:$AF$152,">="&'Item Analysis'!$B$5) -> 3 | F2: =COUNTIFS(Responses!$B$3:$B$152,B2,Scoring!$AF$3:$AF$152,"<="&'Item Analysis'!$B$6) -> 10 | G2: =E2-F2 -> -7 | H2: =IF(C2="Yes",IF(G2>0,"Key discriminates as it should","Key does not discriminate: review"),IF(D2<'Item Analysis'!$B$17,"Ineffective distractor",IF(G2>0,"Distractor attracts high achievers: review it","Distractor works"))) -> Distractor works
A3: Q1 | B3: B | C3: =IF(Responses!$B$2=B3,"Yes","") | D3: =COUNTIF(Responses!$B$3:$B$152,B3)/'Item Analysis'!$B$2 -> 0.22 | E3: =COUNTIFS(Responses!$B$3:$B$152,B3,Scoring!$AF$3:$AF$152,">="&'Item Analysis'!$B$5) -> 4 | F3: =COUNTIFS(Responses!$B$3:$B$152,B3,Scoring!$AF$3:$AF$152,"<="&'Item Analysis'!$B$6) -> 18 | G3: =E3-F3 -> -14 | H3: =IF(C3="Yes",IF(G3>0,"Key discriminates as it should","Key does not discriminate: review"),IF(D3<'Item Analysis'!$B$17,"Ineffective distractor",IF(G3>0,"Distractor attracts high achievers: review it","Distractor works"))) -> Distractor works
A4: Q1 | B4: C | C4: =IF(Responses!$B$2=B4,"Yes","") | D4: =COUNTIF(Responses!$B$3:$B$152,B4)/'Item Analysis'!$B$2 -> 0.18666667 | E4: =COUNTIFS(Responses!$B$3:$B$152,B4,Scoring!$AF$3:$AF$152,">="&'Item Analysis'!$B$5) -> 3 | F4: =COUNTIFS(Responses!$B$3:$B$152,B4,Scoring!$AF$3:$AF$152,"<="&'Item Analysis'!$B$6) -> 11 | G4: =E4-F4 -> -8 | H4: =IF(C4="Yes",IF(G4>0,"Key discriminates as it should","Key does not discriminate: review"),IF(D4<'Item Analysis'!$B$17,"Ineffective distractor",IF(G4>0,"Distractor attracts high achievers: review it","Distractor works"))) -> Distractor works
A5: Q1 | B5: D | C5: =IF(Responses!$B$2=B5,"Yes","") -> Yes | D5: =COUNTIF(Responses!$B$3:$B$152,B5)/'Item Analysis'!$B$2 -> 0.43333333 | E5: =COUNTIFS(Responses!$B$3:$B$152,B5,Scoring!$AF$3:$AF$152,">="&'Item Analysis'!$B$5) -> 35 | F5: =COUNTIFS(Responses!$B$3:$B$152,B5,Scoring!$AF$3:$AF$152,"<="&'Item Analysis'!$B$6) -> 6 | G5: =E5-F5 -> 29 | H5: =IF(C5="Yes",IF(G5>0,"Key discriminates as it should","Key does not discriminate: review"),IF(D5<'Item Analysis'!$B$17,"Ineffective distractor",IF(G5>0,"Distractor attracts high achievers: review it","Distractor works"))) -> Key discriminates as it should
A6: Q2 | B6: A | C6: =IF(Responses!$C$2=B6,"Yes","") | D6: =COUNTIF(Responses!$C$3:$C$152,B6)/'Item Analysis'!$B$2 -> 0.19333333 | E6: =COUNTIFS(Responses!$C$3:$C$152,B6,Scoring!$AF$3:$AF$152,">="&'Item Analysis'!$B$5) -> 4 | F6: =COUNTIFS(Responses!$C$3:$C$152,B6,Scoring!$AF$3:$AF$152,"<="&'Item Analysis'!$B$6) -> 12 | G6: =E6-F6 -> -8 | H6: =IF(C6="Yes",IF(G6>0,"Key discriminates as it should","Key does not discriminate: review"),IF(D6<'Item Analysis'!$B$17,"Ineffective distractor",IF(G6>0,"Distractor attracts high achievers: review it","Distractor works"))) -> Distractor works
A7: Q2 | B7: B | C7: =IF(Responses!$C$2=B7,"Yes","") | D7: =COUNTIF(Responses!$C$3:$C$152,B7)/'Item Analysis'!$B$2 -> 0.23333333 | E7: =COUNTIFS(Responses!$C$3:$C$152,B7,Scoring!$AF$3:$AF$152,">="&'Item Analysis'!$B$5) -> 3 | F7: =COUNTIFS(Responses!$C$3:$C$152,B7,Scoring!$AF$3:$AF$152,"<="&'Item Analysis'!$B$6) -> 16 | G7: =E7-F7 -> -13 | H7: =IF(C7="Yes",IF(G7>0,"Key discriminates as it should","Key does not discriminate: review"),IF(D7<'Item Analysis'!$B$17,"Ineffective distractor",IF(G7>0,"Distractor attracts high achievers: review it","Distractor works"))) -> Distractor works
A8: Q2 | B8: C | C8: =IF(Responses!$C$2=B8,"Yes","") -> Yes | D8: =COUNTIF(Responses!$C$3:$C$152,B8)/'Item Analysis'!$B$2 -> 0.40666667 | E8: =COUNTIFS(Responses!$C$3:$C$152,B8,Scoring!$AF$3:$AF$152,">="&'Item Analysis'!$B$5) -> 34 | F8: =COUNTIFS(Responses!$C$3:$C$152,B8,Scoring!$AF$3:$AF$152,"<="&'Item Analysis'!$B$6) -> 6 | G8: =E8-F8 -> 28 | H8: =IF(C8="Yes",IF(G8>0,"Key discriminates as it should","Key does not discriminate: review"),IF(D8<'Item Analysis'!$B$17,"Ineffective distractor",IF(G8>0,"Distractor attracts high achievers: review it","Distractor works"))) -> Key discriminates as it should
A9: Q2 | B9: D | C9: =IF(Responses!$C$2=B9,"Yes","") | D9: =COUNTIF(Responses!$C$3:$C$152,B9)/'Item Analysis'!$B$2 -> 0.16666667 | E9: =COUNTIFS(Responses!$C$3:$C$152,B9,Scoring!$AF$3:$AF$152,">="&'Item Analysis'!$B$5) -> 4 | F9: =COUNTIFS(Responses!$C$3:$C$152,B9,Scoring!$AF$3:$AF$152,"<="&'Item Analysis'!$B$6) -> 11 | G9: =E9-F9 -> -7 | H9: =IF(C9="Yes",IF(G9>0,"Key discriminates as it should","Key does not discriminate: review"),IF(D9<'Item Analysis'!$B$17,"Ineffective distractor",IF(G9>0,"Distractor attracts high achievers: review it","Distractor works"))) -> Distractor works
A10: Q3 | B10: A | C10: =IF(Responses!$D$2=B10,"Yes","") | D10: =COUNTIF(Responses!$D$3:$D$152,B10)/'Item Analysis'!$B$2 -> 0.16666667 | E10: =COUNTIFS(Responses!$D$3:$D$152,B10,Scoring!$AF$3:$AF$152,">="&'Item Analysis'!$B$5) -> 8 | F10: =COUNTIFS(Responses!$D$3:$D$152,B10,Scoring!$AF$3:$AF$152,"<="&'Item Analysis'!$B$6) -> 9 | G10: =E10-F10 -> -1 | H10: =IF(C10="Yes",IF(G10>0,"Key discriminates as it should","Key does not discriminate: review"),IF(D10<'Item Analysis'!$B$17,"Ineffective distractor",IF(G10>0,"Distractor attracts high achievers: review it","Distractor works"))) -> Distractor works
A11: Q3 | B11: B | C11: =IF(Responses!$D$2=B11,"Yes","") | D11: =COUNTIF(Responses!$D$3:$D$152,B11)/'Item Analysis'!$B$2 -> 0.2 | E11: =COUNTIFS(Responses!$D$3:$D$152,B11,Scoring!$AF$3:$AF$152,">="&'Item Analysis'!$B$5) -> 2 | F11: =COUNTIFS(Responses!$D$3:$D$152,B11,Scoring!$AF$3:$AF$152,"<="&'Item Analysis'!$B$6) -> 11 | G11: =E11-F11 -> -9 | H11: =IF(C11="Yes",IF(G11>0,"Key discriminates as it should","Key does not discriminate: review"),IF(D11<'Item Analysis'!$B$17,"Ineffective distractor",IF(G11>0,"Distractor attracts high achievers: review it","Distractor works"))) -> Distractor works
A12: Q3 | B12: C | C12: =IF(Responses!$D$2=B12,"Yes","") | D12: =COUNTIF(Responses!$D$3:$D$152,B12)/'Item Analysis'!$B$2 -> 0.26 | E12: =COUNTIFS(Responses!$D$3:$D$152,B12,Scoring!$AF$3:$AF$152,">="&'Item Analysis'!$B$5) -> 5 | F12: =COUNTIFS(Responses!$D$3:$D$152,B12,Scoring!$AF$3:$AF$152,"<="&'Item Analysis'!$B$6) -> 14 | G12: =E12-F12 -> -9 | H12: =IF(C12="Yes",IF(G12>0,"Key discriminates as it should","Key does not discriminate: review"),IF(D12<'Item Analysis'!$B$17,"Ineffective distractor",IF(G12>0,"Distractor attracts high achievers: review it","Distractor works"))) -> Distractor works
A13: Q3 | B13: D | C13: =IF(Responses!$D$2=B13,"Yes","") -> Yes | D13: =COUNTIF(Responses!$D$3:$D$152,B13)/'Item Analysis'!$B$2 -> 0.37333333 | E13: =COUNTIFS(Responses!$D$3:$D$152,B13,Scoring!$AF$3:$AF$152,">="&'Item Analysis'!$B$5) -> 30 | F13: =COUNTIFS(Responses!$D$3:$D$152,B13,Scoring!$AF$3:$AF$152,"<="&'Item Analysis'!$B$6) -> 11 | G13: =E13-F13 -> 19 | H13: =IF(C13="Yes",IF(G13>0,"Key discriminates as it should","Key does not discriminate: review"),IF(D13<'Item Analysis'!$B$17,"Ineffective distractor",IF(G13>0,"Distractor attracts high achievers: review it","Distractor works"))) -> Key discriminates as it should
A14: Q4 | B14: A | C14: =IF(Responses!$E$2=B14,"Yes","") | D14: =COUNTIF(Responses!$E$3:$E$152,B14)/'Item Analysis'!$B$2 -> 0.053333333 | E14: =COUNTIFS(Responses!$E$3:$E$152,B14,Scoring!$AF$3:$AF$152,">="&'Item Analysis'!$B$5) -> 0 | F14: =COUNTIFS(Responses!$E$3:$E$152,B14,Scoring!$AF$3:$AF$152,"<="&'Item Analysis'!$B$6) -> 8 | G14: =E14-F14 -> -8 | H14: =IF(C14="Yes",IF(G14>0,"Key discriminates as it should","Key does not discriminate: review"),IF(D14<'Item Analysis'!$B$17,"Ineffective distractor",IF(G14>0,"Distractor attracts high achievers: review it","Distractor works"))) -> Distractor works
A15: Q4 | B15: B | C15: =IF(Responses!$E$2=B15,"Yes","") -> Yes | D15: =COUNTIF(Responses!$E$3:$E$152,B15)/'Item Analysis'!$B$2 -> 0.76666667 | E15: =COUNTIFS(Responses!$E$3:$E$152,B15,Scoring!$AF$3:$AF$152,">="&'Item Analysis'!$B$5) -> 45 | F15: =COUNTIFS(Responses!$E$3:$E$152,B15,Scoring!$AF$3:$AF$152,"<="&'Item Analysis'!$B$6) -> 20 | G15: =E15-F15 -> 25 | H15: =IF(C15="Yes",IF(G15>0,"Key discriminates as it should","Key does not discriminate: review"),IF(D15<'Item Analysis'!$B$17,"Ineffective distractor",IF(G15>0,"Distractor attracts high achievers: review it","Distractor works"))) -> Key discriminates as it should
A16: Q4 | B16: C | C16: =IF(Responses!$E$2=B16,"Yes","") | D16: =COUNTIF(Responses!$E$3:$E$152,B16)/'Item Analysis'!$B$2 -> 0.06 | E16: =COUNTIFS(Responses!$E$3:$E$152,B16,Scoring!$AF$3:$AF$152,">="&'Item Analysis'!$B$5) -> 0 | F16: =COUNTIFS(Responses!$E$3:$E$152,B16,Scoring!$AF$3:$AF$152,"<="&'Item Analysis'!$B$6) -> 6 | G16: =E16-F16 -> -6 | H16: =IF(C16="Yes",IF(G16>0,"Key discriminates as it should","Key does not discriminate: review"),IF(D16<'Item Analysis'!$B$17,"Ineffective distractor",IF(G16>0,"Distractor attracts high achievers: review it","Distractor works"))) -> Distractor works
A17: Q4 | B17: D | C17: =IF(Responses!$E$2=B17,"Yes","") | D17: =COUNTIF(Responses!$E$3:$E$152,B17)/'Item Analysis'!$B$2 -> 0.12 | E17: =COUNTIFS(Responses!$E$3:$E$152,B17,Scoring!$AF$3:$AF$152,">="&'Item Analysis'!$B$5) -> 0 | F17: =COUNTIFS(Responses!$E$3:$E$152,B17,Scoring!$AF$3:$AF$152,"<="&'Item Analysis'!$B$6) -> 11 | G17: =E17-F17 -> -11 | H17: =IF(C17="Yes",IF(G17>0,"Key discriminates as it should","Key does not discriminate: review"),IF(D17<'Item Analysis'!$B$17,"Ineffective distractor",IF(G17>0,"Distractor attracts high achievers: review it","Distractor works"))) -> Distractor works
A18: Q5 | B18: A | C18: =IF(Responses!$F$2=B18,"Yes","") | D18: =COUNTIF(Responses!$F$3:$F$152,B18)/'Item Analysis'!$B$2 -> 0.28666667 | E18: =COUNTIFS(Responses!$F$3:$F$152,B18,Scoring!$AF$3:$AF$152,">="&'Item Analysis'!$B$5) -> 6 | F18: =COUNTIFS(Responses!$F$3:$F$152,B18,Scoring!$AF$3:$AF$152,"<="&'Item Analysis'!$B$6) -> 20 | G18: =E18-F18 -> -14 | H18: =IF(C18="Yes",IF(G18>0,"Key discriminates as it should","Key does not discriminate: review"),IF(D18<'Item Analysis'!$B$17,"Ineffective distractor",IF(G18>0,"Distractor attracts high achievers: review it","Distractor works"))) -> Distractor works
A19: Q5 | B19: B | C19: =IF(Responses!$F$2=B19,"Yes","") -> Yes | D19: =COUNTIF(Responses!$F$3:$F$152,B19)/'Item Analysis'!$B$2 -> 0.42666667 | E19: =COUNTIFS(Responses!$F$3:$F$152,B19,Scoring!$AF$3:$AF$152,">="&'Item Analysis'!$B$5) -> 32 | F19: =COUNTIFS(Responses!$F$3:$F$152,B19,Scoring!$AF$3:$AF$152,"<="&'Item Analysis'!$B$6) -> 6 | G19: =E19-F19 -> 26 | H19: =IF(C19="Yes",IF(G19>0,"Key discriminates as it should","Key does not discriminate: review"),IF(D19<'Item Analysis'!$B$17,"Ineffective distractor",IF(G19>0,"Distractor attracts high achievers: review it","Distractor works"))) -> Key discriminates as it should
A20: Q5 | B20: C | C20: =IF(Responses!$F$2=B20,"Yes","") | D20: =COUNTIF(Responses!$F$3:$F$152,B20)/'Item Analysis'!$B$2 -> 0.17333333 | E20: =COUNTIFS(Responses!$F$3:$F$152,B20,Scoring!$AF$3:$AF$152,">="&'Item Analysis'!$B$5) -> 4 | F20: =COUNTIFS(Responses!$F$3:$F$152,B20,Scoring!$AF$3:$AF$152,"<="&'Item Analysis'!$B$6) -> 13 | G20: =E20-F20 -> -9 | H20: =IF(C20="Yes",IF(G20>0,"Key discriminates as it should","Key does not discriminate: review"),IF(D20<'Item Analysis'!$B$17,"Ineffective distractor",IF(G20>0,"Distractor attracts high achievers: review it","Distractor works"))) -> Distractor works
A21: Q5 | B21: D | C21: =IF(Responses!$F$2=B21,"Yes","") | D21: =COUNTIF(Responses!$F$3:$F$152,B21)/'Item Analysis'!$B$2 -> 0.11333333 | E21: =COUNTIFS(Responses!$F$3:$F$152,B21,Scoring!$AF$3:$AF$152,">="&'Item Analysis'!$B$5) -> 3 | F21: =COUNTIFS(Responses!$F$3:$F$152,B21,Scoring!$AF$3:$AF$152,"<="&'Item Analysis'!$B$6) -> 6 | G21: =E21-F21 -> -3 | H21: =IF(C21="Yes",IF(G21>0,"Key discriminates as it should","Key does not discriminate: review"),IF(D21<'Item Analysis'!$B$17,"Ineffective distractor",IF(G21>0,"Distractor attracts high achievers: review it","Distractor works"))) -> Distractor works
A22: Q6 | B22: A | C22: =IF(Responses!$G$2=B22,"Yes","") | D22: =COUNTIF(Responses!$G$3:$G$152,B22)/'Item Analysis'!$B$2 -> 0.22666667 | E22: =COUNTIFS(Responses!$G$3:$G$152,B22,Scoring!$AF$3:$AF$152,">="&'Item Analysis'!$B$5) -> 4 | F22: =COUNTIFS(Responses!$G$3:$G$152,B22,Scoring!$AF$3:$AF$152,"<="&'Item Analysis'!$B$6) -> 14 | G22: =E22-F22 -> -10 | H22: =IF(C22="Yes",IF(G22>0,"Key discriminates as it should","Key does not discriminate: review"),IF(D22<'Item Analysis'!$B$17,"Ineffective distractor",IF(G22>0,"Distractor attracts high achievers: review it","Distractor works"))) -> Distractor works
A23: Q6 | B23: B | C23: =IF(Responses!$G$2=B23,"Yes","") -> Yes | D23: =COUNTIF(Responses!$G$3:$G$152,B23)/'Item Analysis'!$B$2 -> 0.47333333 | E23: =COUNTIFS(Responses!$G$3:$G$152,B23,Scoring!$AF$3:$AF$152,">="&'Item Analysis'!$B$5) -> 37 | F23: =COUNTIFS(Responses!$G$3:$G$152,B23,Scoring!$AF$3:$AF$152,"<="&'Item Analysis'!$B$6) -> 10 | G23: =E23-F23 -> 27 | H23: =IF(C23="Yes",IF(G23>0,"Key discriminates as it should","Key does not discriminate: review"),IF(D23<'Item Analysis'!$B$17,"Ineffective distractor",IF(G23>0,"Distractor attracts high achievers: review it","Distractor works"))) -> Key discriminates as it should
A24: Q6 | B24: C | C24: =IF(Responses!$G$2=B24,"Yes","") | D24: =COUNTIF(Responses!$G$3:$G$152,B24)/'Item Analysis'!$B$2 -> 0.12666667 | E24: =COUNTIFS(Responses!$G$3:$G$152,B24,Scoring!$AF$3:$AF$152,">="&'Item Analysis'!$B$5) -> 1 | F24: =COUNTIFS(Responses!$G$3:$G$152,B24,Scoring!$AF$3:$AF$152,"<="&'Item Analysis'!$B$6) -> 13 | G24: =E24-F24 -> -12 | H24: =IF(C24="Yes",IF(G24>0,"Key discriminates as it should","Key does not discriminate: review"),IF(D24<'Item Analysis'!$B$17,"Ineffective distractor",IF(G24>0,"Distractor attracts high achievers: review it","Distractor works"))) -> Distractor works
A25: Q6 | B25: D | C25: =IF(Responses!$G$2=B25,"Yes","") | D25: =COUNTIF(Responses!$G$3:$G$152,B25)/'Item Analysis'!$B$2 -> 0.17333333 | E25: =COUNTIFS(Responses!$G$3:$G$152,B25,Scoring!$AF$3:$AF$152,">="&'Item Analysis'!$B$5) -> 3 | F25: =COUNTIFS(Responses!$G$3:$G$152,B25,Scoring!$AF$3:$AF$152,"<="&'Item Analysis'!$B$6) -> 8 | G25: =E25-F25 -> -5 | H25: =IF(C25="Yes",IF(G25>0,"Key discriminates as it should","Key does not discriminate: review"),IF(D25<'Item Analysis'!$B$17,"Ineffective distractor",IF(G25>0,"Distractor attracts high achievers: review it","Distractor works"))) -> Distractor works
A26: Q7 | B26: A | C26: =IF(Responses!$H$2=B26,"Yes","") | D26: =COUNTIF(Responses!$H$3:$H$152,B26)/'Item Analysis'!$B$2 -> 0.033333333 | E26: =COUNTIFS(Responses!$H$3:$H$152,B26,Scoring!$AF$3:$AF$152,">="&'Item Analysis'!$B$5) -> 0 | F26: =COUNTIFS(Responses!$H$3:$H$152,B26,Scoring!$AF$3:$AF$152,"<="&'Item Analysis'!$B$6) -> 3 | G26: =E26-F26 -> -3 | H26: =IF(C26="Yes",IF(G26>0,"Key discriminates as it should","Key does not discriminate: review"),IF(D26<'Item Analysis'!$B$17,"Ineffective distractor",IF(G26>0,"Distractor attracts high achievers: review it","Distractor works"))) -> Ineffective distractor
A27: Q7 | B27: B | C27: =IF(Responses!$H$2=B27,"Yes","") -> Yes | D27: =COUNTIF(Responses!$H$3:$H$152,B27)/'Item Analysis'!$B$2 -> 0.25333333 | E27: =COUNTIFS(Responses!$H$3:$H$152,B27,Scoring!$AF$3:$AF$152,">="&'Item Analysis'!$B$5) -> 2 | F27: =COUNTIFS(Responses!$H$3:$H$152,B27,Scoring!$AF$3:$AF$152,"<="&'Item Analysis'!$B$6) -> 20 | G27: =E27-F27 -> -18 | H27: =IF(C27="Yes",IF(G27>0,"Key discriminates as it should","Key does not discriminate: review"),IF(D27<'Item Analysis'!$B$17,"Ineffective distractor",IF(G27>0,"Distractor attracts high achievers: review it","Distractor works"))) -> Key does not discriminate: review
A28: Q7 | B28: C | C28: =IF(Responses!$H$2=B28,"Yes","") | D28: =COUNTIF(Responses!$H$3:$H$152,B28)/'Item Analysis'!$B$2 -> 0.68 | E28: =COUNTIFS(Responses!$H$3:$H$152,B28,Scoring!$AF$3:$AF$152,">="&'Item Analysis'!$B$5) -> 43 | F28: =COUNTIFS(Responses!$H$3:$H$152,B28,Scoring!$AF$3:$AF$152,"<="&'Item Analysis'!$B$6) -> 17 | G28: =E28-F28 -> 26 | H28: =IF(C28="Yes",IF(G28>0,"Key discriminates as it should","Key does not discriminate: review"),IF(D28<'Item Analysis'!$B$17,"Ineffective distractor",IF(G28>0,"Distractor attracts high achievers: review it","Distractor works"))) -> Distractor attracts high achievers: review it
A29: Q7 | B29: D | C29: =IF(Responses!$H$2=B29,"Yes","") | D29: =COUNTIF(Responses!$H$3:$H$152,B29)/'Item Analysis'!$B$2 -> 0.033333333 | E29: =COUNTIFS(Responses!$H$3:$H$152,B29,Scoring!$AF$3:$AF$152,">="&'Item Analysis'!$B$5) -> 0 | F29: =COUNTIFS(Responses!$H$3:$H$152,B29,Scoring!$AF$3:$AF$152,"<="&'Item Analysis'!$B$6) -> 5 | G29: =E29-F29 -> -5 | H29: =IF(C29="Yes",IF(G29>0,"Key discriminates as it should","Key does not discriminate: review"),IF(D29<'Item Analysis'!$B$17,"Ineffective distractor",IF(G29>0,"Distractor attracts high achievers: review it","Distractor works"))) -> Ineffective distractor
A30: Q8 | B30: A | C30: =IF(Responses!$I$2=B30,"Yes","") | D30: =COUNTIF(Responses!$I$3:$I$152,B30)/'Item Analysis'!$B$2 -> 0.13333333 | E30: =COUNTIFS(Responses!$I$3:$I$152,B30,Scoring!$AF$3:$AF$152,">="&'Item Analysis'!$B$5) -> 0 | F30: =COUNTIFS(Responses!$I$3:$I$152,B30,Scoring!$AF$3:$AF$152,"<="&'Item Analysis'!$B$6) -> 14 | G30: =E30-F30 -> -14 | H30: =IF(C30="Yes",IF(G30>0,"Key discriminates as it should","Key does not discriminate: review"),IF(D30<'Item Analysis'!$B$17,"Ineffective distractor",IF(G30>0,"Distractor attracts high achievers: review it","Distractor works"))) -> Distractor works
A31: Q8 | B31: B | C31: =IF(Responses!$I$2=B31,"Yes","") | D31: =COUNTIF(Responses!$I$3:$I$152,B31)/'Item Analysis'!$B$2 -> 0.1 | E31: =COUNTIFS(Responses!$I$3:$I$152,B31,Scoring!$AF$3:$AF$152,">="&'Item Analysis'!$B$5) -> 1 | F31: =COUNTIFS(Responses!$I$3:$I$152,B31,Scoring!$AF$3:$AF$152,"<="&'Item Analysis'!$B$6) -> 7 | G31: =E31-F31 -> -6 | H31: =IF(C31="Yes",IF(G31>0,"Key discriminates as it should","Key does not discriminate: review"),IF(D31<'Item Analysis'!$B$17,"Ineffective distractor",IF(G31>0,"Distractor attracts high achievers: review it","Distractor works"))) -> Distractor works
A32: Q8 | B32: C | C32: =IF(Responses!$I$2=B32,"Yes","") -> Yes | D32: =COUNTIF(Responses!$I$3:$I$152,B32)/'Item Analysis'!$B$2 -> 0.66 | E32: =COUNTIFS(Responses!$I$3:$I$152,B32,Scoring!$AF$3:$AF$152,">="&'Item Analysis'!$B$5) -> 44 | F32: =COUNTIFS(Responses!$I$3:$I$152,B32,Scoring!$AF$3:$AF$152,"<="&'Item Analysis'!$B$6) -> 12 | G32: =E32-F32 -> 32 | H32: =IF(C32="Yes",IF(G32>0,"Key discriminates as it should","Key does not discriminate: review"),IF(D32<'Item Analysis'!$B$17,"Ineffective distractor",IF(G32>0,"Distractor attracts high achievers: review it","Distractor works"))) -> Key discriminates as it should
A33: Q8 | B33: D | C33: =IF(Responses!$I$2=B33,"Yes","") | D33: =COUNTIF(Responses!$I$3:$I$152,B33)/'Item Analysis'!$B$2 -> 0.10666667 | E33: =COUNTIFS(Responses!$I$3:$I$152,B33,Scoring!$AF$3:$AF$152,">="&'Item Analysis'!$B$5) -> 0 | F33: =COUNTIFS(Responses!$I$3:$I$152,B33,Scoring!$AF$3:$AF$152,"<="&'Item Analysis'!$B$6) -> 12 | G33: =E33-F33 -> -12 | H33: =IF(C33="Yes",IF(G33>0,"Key discriminates as it should","Key does not discriminate: review"),IF(D33<'Item Analysis'!$B$17,"Ineffective distractor",IF(G33>0,"Distractor attracts high achievers: review it","Distractor works"))) -> Distractor works
