Workbook

Sheet اقرأني
A1: مشغل الأسبوع 5 — العدالة: هل تعامل الفقرة المجموعتين بالعدل نفسه؟
A2: مساق القياس والتقويم التربوي — دبلوم الدراسات العليا المهني في التدريس
A4: تنبيه: البيانات محاكاة حاسوبية لأغراض التدريب، وليست لطلبة حقيقيين.
A5: اختبار رياضيات من 20 فقرة طُبّق على 480 طالباً: 300 لغة البيت لديهم العربية، و180 لغة البيت لديهم غير العربية.
A6: في البيانات فرق حقيقي في المستوى بين المجموعتين، وفيها ثلاث فقرات تعامل المجموعتين بصورة غير متكافئة.
A8: أوراق المصنف:
A9: البيانات: درجة كل طالب في كل فقرة (1 أو 0)، ومجموعته، ودرجته الكلية.
A10: المقارنة الخام: نسبة الإجابة الصحيحة في كل مجموعة والفرق بينهما، دون مراعاة المستوى.
A11: المقارنة المضبوطة: مقارنة طلبة المستوى نفسه فقط (خمس فئات للدرجة الكلية)، ثم مؤشر التوحيد.
A13: الفكرة الأساسية: الفرق الخام قد يعكس فرقاً حقيقياً في المستوى. التحيّز يظهر فقط عندما يختلف أداء طلبة المستوى نفسه.
A14: المجموعة المرجعية: لغة البيت العربية. المجموعة المركّز عليها: لغة البيت غير العربية. القيمة السالبة تعني أن الفقرة أصعب على المجموعة المركّز عليها.

Sheet البيانات
A1: الطالب | B1: لغة البيت | C1: ف1 | D1: ف2 | E1: ف3 | F1: ف4 | G1: ف5 | H1: ف6 | I1: ف7 | J1: ف8 | K1: ف9 | L1: ف10 | M1: ف11 | N1: ف12 | O1: ف13 | P1: ف14 | Q1: ف15 | R1: ف16 | S1: ف17 | T1: ف18 | U1: ف19 | V1: ف20 | W1: الدرجة الكلية
A2: S001 | B2: عربية | C2: 1 | D2: 1 | E2: 1 | F2: 1 | G2: 1 | H2: 1 | I2: 0 | J2: 1 | K2: 1 | L2: 1 | M2: 1 | N2: 1 | O2: 1 | P2: 0 | Q2: 1 | R2: 1 | S2: 1 | T2: 1 | U2: 0 | V2: 1 | W2: =SUM(C2:V2) -> 17
A3: S002 | B3: عربية | C3: 0 | D3: 0 | E3: 0 | F3: 0 | G3: 0 | H3: 0 | I3: 0 | J3: 0 | K3: 0 | L3: 0 | M3: 0 | N3: 1 | O3: 0 | P3: 0 | Q3: 0 | R3: 0 | S3: 0 | T3: 0 | U3: 0 | V3: 0 | W3: =SUM(C3:V3) -> 1
A4: S003 | B4: عربية | C4: 0 | D4: 1 | E4: 1 | F4: 0 | G4: 1 | H4: 1 | I4: 0 | J4: 0 | K4: 1 | L4: 0 | M4: 1 | N4: 1 | O4: 0 | P4: 0 | Q4: 1 | R4: 1 | S4: 1 | T4: 1 | U4: 1 | V4: 1 | W4: =SUM(C4:V4) -> 13
A5: S004 | B5: عربية | C5: 0 | D5: 1 | E5: 0 | F5: 0 | G5: 0 | H5: 0 | I5: 0 | J5: 0 | K5: 0 | L5: 0 | M5: 0 | N5: 1 | O5: 1 | P5: 0 | Q5: 0 | R5: 0 | S5: 0 | T5: 0 | U5: 0 | V5: 0 | W5: =SUM(C5:V5) -> 3
A6: S005 | B6: عربية | C6: 0 | D6: 1 | E6: 1 | F6: 0 | G6: 0 | H6: 0 | I6: 0 | J6: 0 | K6: 1 | L6: 0 | M6: 0 | N6: 1 | O6: 1 | P6: 0 | Q6: 1 | R6: 0 | S6: 1 | T6: 0 | U6: 0 | V6: 0 | W6: =SUM(C6:V6) -> 7
A7: S006 | B7: عربية | C7: 0 | D7: 1 | E7: 1 | F7: 0 | G7: 0 | H7: 1 | I7: 0 | J7: 0 | K7: 1 | L7: 0 | M7: 0 | N7: 1 | O7: 0 | P7: 0 | Q7: 1 | R7: 1 | S7: 0 | T7: 0 | U7: 0 | V7: 0 | W7: =SUM(C7:V7) -> 7
A8: S007 | B8: عربية | C8: 1 | D8: 1 | E8: 1 | F8: 0 | G8: 0 | H8: 1 | I8: 0 | J8: 0 | K8: 1 | L8: 1 | M8: 0 | N8: 1 | O8: 0 | P8: 0 | Q8: 1 | R8: 1 | S8: 1 | T8: 1 | U8: 0 | V8: 0 | W8: =SUM(C8:V8) -> 11
A9: S008 | B9: عربية | C9: 1 | D9: 0 | E9: 1 | F9: 0 | G9: 0 | H9: 1 | I9: 0 | J9: 0 | K9: 1 | L9: 0 | M9: 0 | N9: 1 | O9: 0 | P9: 0 | Q9: 1 | R9: 0 | S9: 0 | T9: 1 | U9: 0 | V9: 0 | W9: =SUM(C9:V9) -> 7
A10: S009 | B10: عربية | C10: 1 | D10: 1 | E10: 1 | F10: 0 | G10: 0 | H10: 1 | I10: 1 | J10: 1 | K10: 1 | L10: 1 | M10: 1 | N10: 1 | O10: 1 | P10: 1 | Q10: 1 | R10: 0 | S10: 1 | T10: 1 | U10: 1 | V10: 0 | W10: =SUM(C10:V10) -> 16
A11: S010 | B11: عربية | C11: 1 | D11: 0 | E11: 0 | F11: 0 | G11: 0 | H11: 1 | I11: 0 | J11: 0 | K11: 0 | L11: 0 | M11: 0 | N11: 0 | O11: 0 | P11: 0 | Q11: 1 | R11: 0 | S11: 1 | T11: 1 | U11: 0 | V11: 0 | W11: =SUM(C11:V11) -> 5
A12: S011 | B12: عربية | C12: 1 | D12: 1 | E12: 0 | F12: 0 | G12: 0 | H12: 0 | I12: 0 | J12: 0 | K12: 1 | L12: 0 | M12: 0 | N12: 1 | O12: 0 | P12: 0 | Q12: 1 | R12: 0 | S12: 0 | T12: 0 | U12: 0 | V12: 1 | W12: =SUM(C12:V12) -> 6
A13: S012 | B13: عربية | C13: 0 | D13: 0 | E13: 0 | F13: 0 | G13: 0 | H13: 0 | I13: 0 | J13: 0 | K13: 0 | L13: 0 | M13: 0 | N13: 1 | O13: 0 | P13: 0 | Q13: 1 | R13: 0 | S13: 1 | T13: 0 | U13: 0 | V13: 0 | W13: =SUM(C13:V13) -> 3
... A481: S480 | B481: غير العربية | C481: 1 | D481: 1 | E481: 0 | F481: 1 | G481: 1 | H481: 1 | I481: 0 | J481: 1 | K481: 1 | L481: 1 | M481: 1 | N481: 1 | O481: 0 | P481: 0 | Q481: 1 | R481: 1 | S481: 1 | T481: 1 | U481: 1 | V481: 0 | W481: =SUM(C481:V481) -> 15

Sheet المقارنة الخام
A1: الفقرة | B1: نسبة الصواب: العربية | C1: نسبة الصواب: غير العربية | D1: الفرق الخام
A2: ف1 | B2: =AVERAGEIF(البيانات!$B$2:$B$481,"عربية",البيانات!$C$2:$C$481) -> 0.51 | C2: =AVERAGEIF(البيانات!$B$2:$B$481,"غير العربية",البيانات!$C$2:$C$481) -> 0.55 | D2: =C2-B2 -> 0.04
A3: ف2 | B3: =AVERAGEIF(البيانات!$B$2:$B$481,"عربية",البيانات!$D$2:$D$481) -> 0.51333333 | C3: =AVERAGEIF(البيانات!$B$2:$B$481,"غير العربية",البيانات!$D$2:$D$481) -> 0.59444444 | D3: =C3-B3 -> 0.081111111
A4: ف3 | B4: =AVERAGEIF(البيانات!$B$2:$B$481,"عربية",البيانات!$E$2:$E$481) -> 0.65333333 | C4: =AVERAGEIF(البيانات!$B$2:$B$481,"غير العربية",البيانات!$E$2:$E$481) -> 0.7 | D4: =C4-B4 -> 0.046666667
A5: ف4 | B5: =AVERAGEIF(البيانات!$B$2:$B$481,"عربية",البيانات!$F$2:$F$481) -> 0.14 | C5: =AVERAGEIF(البيانات!$B$2:$B$481,"غير العربية",البيانات!$F$2:$F$481) -> 0.19444444 | D5: =C5-B5 -> 0.054444444
A6: ف5 | B6: =AVERAGEIF(البيانات!$B$2:$B$481,"عربية",البيانات!$G$2:$G$481) -> 0.32333333 | C6: =AVERAGEIF(البيانات!$B$2:$B$481,"غير العربية",البيانات!$G$2:$G$481) -> 0.45555556 | D6: =C6-B6 -> 0.13222222
A7: ف6 | B7: =AVERAGEIF(البيانات!$B$2:$B$481,"عربية",البيانات!$H$2:$H$481) -> 0.68666667 | C7: =AVERAGEIF(البيانات!$B$2:$B$481,"غير العربية",البيانات!$H$2:$H$481) -> 0.46111111 | D7: =C7-B7 -> -0.22555556
A8: ف7 | B8: =AVERAGEIF(البيانات!$B$2:$B$481,"عربية",البيانات!$I$2:$I$481) -> 0.24333333 | C8: =AVERAGEIF(البيانات!$B$2:$B$481,"غير العربية",البيانات!$I$2:$I$481) -> 0.32222222 | D8: =C8-B8 -> 0.078888889
A9: ف8 | B9: =AVERAGEIF(البيانات!$B$2:$B$481,"عربية",البيانات!$J$2:$J$481) -> 0.21666667 | C9: =AVERAGEIF(البيانات!$B$2:$B$481,"غير العربية",البيانات!$J$2:$J$481) -> 0.27222222 | D9: =C9-B9 -> 0.055555556
A10: ف9 | B10: =AVERAGEIF(البيانات!$B$2:$B$481,"عربية",البيانات!$K$2:$K$481) -> 0.73333333 | C10: =AVERAGEIF(البيانات!$B$2:$B$481,"غير العربية",البيانات!$K$2:$K$481) -> 0.75555556 | D10: =C10-B10 -> 0.022222222
A11: ف10 | B11: =AVERAGEIF(البيانات!$B$2:$B$481,"عربية",البيانات!$L$2:$L$481) -> 0.38333333 | C11: =AVERAGEIF(البيانات!$B$2:$B$481,"غير العربية",البيانات!$L$2:$L$481) -> 0.39444444 | D11: =C11-B11 -> 0.011111111
A12: ف11 | B12: =AVERAGEIF(البيانات!$B$2:$B$481,"عربية",البيانات!$M$2:$M$481) -> 0.34 | C12: =AVERAGEIF(البيانات!$B$2:$B$481,"غير العربية",البيانات!$M$2:$M$481) -> 0.48333333 | D12: =C12-B12 -> 0.14333333
A13: ف12 | B13: =AVERAGEIF(البيانات!$B$2:$B$481,"عربية",البيانات!$N$2:$N$481) -> 0.87333333 | C13: =AVERAGEIF(البيانات!$B$2:$B$481,"غير العربية",البيانات!$N$2:$N$481) -> 0.91666667 | D13: =C13-B13 -> 0.043333333
A14: ف13 | B14: =AVERAGEIF(البيانات!$B$2:$B$481,"عربية",البيانات!$O$2:$O$481) -> 0.43333333 | C14: =AVERAGEIF(البيانات!$B$2:$B$481,"غير العربية",البيانات!$O$2:$O$481) -> 0.51111111 | D14: =C14-B14 -> 0.077777778
A15: ف14 | B15: =AVERAGEIF(البيانات!$B$2:$B$481,"عربية",البيانات!$P$2:$P$481) -> 0.28333333 | C15: =AVERAGEIF(البيانات!$B$2:$B$481,"غير العربية",البيانات!$P$2:$P$481) -> 0.20555556 | D15: =C15-B15 -> -0.077777778
A16: ف15 | B16: =AVERAGEIF(البيانات!$B$2:$B$481,"عربية",البيانات!$Q$2:$Q$481) -> 0.88666667 | C16: =AVERAGEIF(البيانات!$B$2:$B$481,"غير العربية",البيانات!$Q$2:$Q$481) -> 0.88333333 | D16: =C16-B16 -> -0.0033333333
A17: ف16 | B17: =AVERAGEIF(البيانات!$B$2:$B$481,"عربية",البيانات!$R$2:$R$481) -> 0.52 | C17: =AVERAGEIF(البيانات!$B$2:$B$481,"غير العربية",البيانات!$R$2:$R$481) -> 0.61666667 | D17: =C17-B17 -> 0.096666667
A18: ف17 | B18: =AVERAGEIF(البيانات!$B$2:$B$481,"عربية",البيانات!$S$2:$S$481) -> 0.61 | C18: =AVERAGEIF(البيانات!$B$2:$B$481,"غير العربية",البيانات!$S$2:$S$481) -> 0.85 | D18: =C18-B18 -> 0.24
A19: ف18 | B19: =AVERAGEIF(البيانات!$B$2:$B$481,"عربية",البيانات!$T$2:$T$481) -> 0.44333333 | C19: =AVERAGEIF(البيانات!$B$2:$B$481,"غير العربية",البيانات!$T$2:$T$481) -> 0.54444444 | D19: =C19-B19 -> 0.10111111
A20: ف19 | B20: =AVERAGEIF(البيانات!$B$2:$B$481,"عربية",البيانات!$U$2:$U$481) -> 0.3 | C20: =AVERAGEIF(البيانات!$B$2:$B$481,"غير العربية",البيانات!$U$2:$U$481) -> 0.41111111 | D20: =C20-B20 -> 0.11111111
A21: ف20 | B21: =AVERAGEIF(البيانات!$B$2:$B$481,"عربية",البيانات!$V$2:$V$481) -> 0.22333333 | C21: =AVERAGEIF(البيانات!$B$2:$B$481,"غير العربية",البيانات!$V$2:$V$481) -> 0.28333333 | D21: =C21-B21 -> 0.06
A23: متوسط الدرجة الكلية | B23: =AVERAGEIF(البيانات!$B$2:$B$481,"عربية",البيانات!$W$2:$W$481) -> 9.3166667 | C23: =AVERAGEIF(البيانات!$B$2:$B$481,"غير العربية",البيانات!$W$2:$W$481) -> 10.405556
A24: عدد الطلبة | B24: =COUNTIF(البيانات!$B$2:$B$481,"عربية") -> 300 | C24: =COUNTIF(البيانات!$B$2:$B$481,"غير العربية") -> 180

Sheet المقارنة المضبوطة
A1: حدود فئات الدرجة الكلية | B1: الفئة 1: من | C1: إلى | D1: الفئة 2: من | E1: إلى | F1: الفئة 3: من | G1: إلى | H1: الفئة 4: من | I1: إلى | J1: الفئة 5: من | K1: إلى | M1: حد «يستحق الفحص» | N1: 0.05
B2: 0 | C2: 4 | D2: 5 | E2: 8 | F2: 9 | G2: 12 | H2: 13 | I2: 16 | J2: 17 | K2: 20 | M2: حد «فرق كبير» | N2: 0.1
A5: الفقرة | B5: ف1: عدد غير العربية | C5: ف1: صواب غير العربية | D5: ف1: صواب العربية | E5: ف2: عدد غير العربية | F5: ف2: صواب غير العربية | G5: ف2: صواب العربية | H5: ف3: عدد غير العربية | I5: ف3: صواب غير العربية | J5: ف3: صواب العربية | K5: ف4: عدد غير العربية | L5: ف4: صواب غير العربية | M5: ف4: صواب العربية | N5: ف5: عدد غير العربية | O5: ف5: صواب غير العربية | P5: ف5: صواب العربية | Q5: مؤشر التوحيد | R5: الحكم
A6: ف1 | B6: =COUNTIFS(البيانات!$B$2:$B$481,"غير العربية",البيانات!$W$2:$W$481,">="&$B$2,البيانات!$W$2:$W$481,"<="&$C$2) -> 36 | C6: =IFERROR(AVERAGEIFS(البيانات!$C$2:$C$481,البيانات!$B$2:$B$481,"غير العربية",البيانات!$W$2:$W$481,">="&$B$2,البيانات!$W$2:$W$481,"<="&$C$2),"") -> 0.083333333 | D6: =IFERROR(AVERAGEIFS(البيانات!$C$2:$C$481,البيانات!$B$2:$B$481,"عربية",البيانات!$W$2:$W$481,">="&$B$2,البيانات!$W$2:$W$481,"<="&$C$2),"") -> 0.10526316 | E6: =COUNTIFS(البيانات!$B$2:$B$481,"غير العربية",البيانات!$W$2:$W$481,">="&$D$2,البيانات!$W$2:$W$481,"<="&$E$2) -> 36 | F6: =IFERROR(AVERAGEIFS(البيانات!$C$2:$C$481,البيانات!$B$2:$B$481,"غير العربية",البيانات!$W$2:$W$481,">="&$D$2,البيانات!$W$2:$W$481,"<="&$E$2),"") -> 0.33333333 | G6: =IFERROR(AVERAGEIFS(البيانات!$C$2:$C$481,البيانات!$B$2:$B$481,"عربية",البيانات!$W$2:$W$481,">="&$D$2,البيانات!$W$2:$W$481,"<="&$E$2),"") -> 0.33846154 | H6: =COUNTIFS(البيانات!$B$2:$B$481,"غير العربية",البيانات!$W$2:$W$481,">="&$F$2,البيانات!$W$2:$W$481,"<="&$G$2) -> 37 | I6: =IFERROR(AVERAGEIFS(البيانات!$C$2:$C$481,البيانات!$B$2:$B$481,"غير العربية",البيانات!$W$2:$W$481,">="&$F$2,البيانات!$W$2:$W$481,"<="&$G$2),"") -> 0.51351351 | J6: =IFERROR(AVERAGEIFS(البيانات!$C$2:$C$481,البيانات!$B$2:$B$481,"عربية",البيانات!$W$2:$W$481,">="&$F$2,البيانات!$W$2:$W$481,"<="&$G$2),"") -> 0.6056338 | K6: =COUNTIFS(البيانات!$B$2:$B$481,"غير العربية",البيانات!$W$2:$W$481,">="&$H$2,البيانات!$W$2:$W$481,"<="&$I$2) -> 35 | L6: =IFERROR(AVERAGEIFS(البيانات!$C$2:$C$481,البيانات!$B$2:$B$481,"غير العربية",البيانات!$W$2:$W$481,">="&$H$2,البيانات!$W$2:$W$481,"<="&$I$2),"") -> 0.85714286 | M6: =IFERROR(AVERAGEIFS(البيانات!$C$2:$C$481,البيانات!$B$2:$B$481,"عربية",البيانات!$W$2:$W$481,">="&$H$2,البيانات!$W$2:$W$481,"<="&$I$2),"") -> 0.89583333 | N6: =COUNTIFS(البيانات!$B$2:$B$481,"غير العربية",البيانات!$W$2:$W$481,">="&$J$2,البيانات!$W$2:$W$481,"<="&$K$2) -> 36 | O6: =IFERROR(AVERAGEIFS(البيانات!$C$2:$C$481,البيانات!$B$2:$B$481,"غير العربية",البيانات!$W$2:$W$481,">="&$J$2,البيانات!$W$2:$W$481,"<="&$K$2),"") -> 0.97222222 | P6: =IFERROR(AVERAGEIFS(البيانات!$C$2:$C$481,البيانات!$B$2:$B$481,"عربية",البيانات!$W$2:$W$481,">="&$J$2,البيانات!$W$2:$W$481,"<="&$K$2),"") -> 0.925 | Q6: =(IF(AND(ISNUMBER(C6),ISNUMBER(D6)),B6*(C6-D6),0)+IF(AND(ISNUMBER(F6),ISNUMBER(G6)),E6*(F6-G6),0)+IF(AND(ISNUMBER(I6),ISNUMBER(J6)),H6*(I6-J6),0)+IF(AND(ISNUMBER(L6),ISNUMBER(M6)),K6*(L6-M6),0)+IF(AND(ISNUMBER(O6),ISNUMBER(P6)),N6*(O6-P6),0))/(IF(AND(ISNUMBER(C6),ISNUMBER(D6)),B6,0)+IF(AND(ISNUMBER(F6),ISNUMBER(G6)),E6,0)+IF(AND(ISNUMBER(I6),ISNUMBER(J6)),H6,0)+IF(AND(ISNUMBER(L6),ISNUMBER(M6)),K6,0)+IF(AND(ISNUMBER(O6),ISNUMBER(P6)),N6,0)) -> -0.022426147 | R6: =IF(ABS(Q6)>$N$2,IF(Q6<0,"فرق كبير ضد غير العربية","فرق كبير لصالح غير العربية"),IF(ABS(Q6)>=$N$1,"يستحق الفحص","مهمل")) -> مهمل
A7: ف2 | B7: =COUNTIFS(البيانات!$B$2:$B$481,"غير العربية",البيانات!$W$2:$W$481,">="&$B$2,البيانات!$W$2:$W$481,"<="&$C$2) -> 36 | C7: =IFERROR(AVERAGEIFS(البيانات!$D$2:$D$481,البيانات!$B$2:$B$481,"غير العربية",البيانات!$W$2:$W$481,">="&$B$2,البيانات!$W$2:$W$481,"<="&$C$2),"") -> 0.11111111 | D7: =IFERROR(AVERAGEIFS(البيانات!$D$2:$D$481,البيانات!$B$2:$B$481,"عربية",البيانات!$W$2:$W$481,">="&$B$2,البيانات!$W$2:$W$481,"<="&$C$2),"") -> 0.11842105 | E7: =COUNTIFS(البيانات!$B$2:$B$481,"غير العربية",البيانات!$W$2:$W$481,">="&$D$2,البيانات!$W$2:$W$481,"<="&$E$2) -> 36 | F7: =IFERROR(AVERAGEIFS(البيانات!$D$2:$D$481,البيانات!$B$2:$B$481,"غير العربية",البيانات!$W$2:$W$481,">="&$D$2,البيانات!$W$2:$W$481,"<="&$E$2),"") -> 0.36111111 | G7: =IFERROR(AVERAGEIFS(البيانات!$D$2:$D$481,البيانات!$B$2:$B$481,"عربية",البيانات!$W$2:$W$481,">="&$D$2,البيانات!$W$2:$W$481,"<="&$E$2),"") -> 0.35384615 | H7: =COUNTIFS(البيانات!$B$2:$B$481,"غير العربية",البيانات!$W$2:$W$481,">="&$F$2,البيانات!$W$2:$W$481,"<="&$G$2) -> 37 | I7: =IFERROR(AVERAGEIFS(البيانات!$D$2:$D$481,البيانات!$B$2:$B$481,"غير العربية",البيانات!$W$2:$W$481,">="&$F$2,البيانات!$W$2:$W$481,"<="&$G$2),"") -> 0.7027027 | J7: =IFERROR(AVERAGEIFS(البيانات!$D$2:$D$481,البيانات!$B$2:$B$481,"عربية",البيانات!$W$2:$W$481,">="&$F$2,البيانات!$W$2:$W$481,"<="&$G$2),"") -> 0.63380282 | K7: =COUNTIFS(البيانات!$B$2:$B$481,"غير العربية",البيانات!$W$2:$W$481,">="&$H$2,البيانات!$W$2:$W$481,"<="&$I$2) -> 35 | L7: =IFERROR(AVERAGEIFS(البيانات!$D$2:$D$481,البيانات!$B$2:$B$481,"غير العربية",البيانات!$W$2:$W$481,">="&$H$2,البيانات!$W$2:$W$481,"<="&$I$2),"") -> 0.82857143 | M7: =IFERROR(AVERAGEIFS(البيانات!$D$2:$D$481,البيانات!$B$2:$B$481,"عربية",البيانات!$W$2:$W$481,">="&$H$2,البيانات!$W$2:$W$481,"<="&$I$2),"") -> 0.79166667 | N7: =COUNTIFS(البيانات!$B$2:$B$481,"غير العربية",البيانات!$W$2:$W$481,">="&$J$2,البيانات!$W$2:$W$481,"<="&$K$2) -> 36 | O7: =IFERROR(AVERAGEIFS(البيانات!$D$2:$D$481,البيانات!$B$2:$B$481,"غير العربية",البيانات!$W$2:$W$481,">="&$J$2,البيانات!$W$2:$W$481,"<="&$K$2),"") -> 0.97222222 | P7: =IFERROR(AVERAGEIFS(البيانات!$D$2:$D$481,البيانات!$B$2:$B$481,"عربية",البيانات!$W$2:$W$481,">="&$J$2,البيانات!$W$2:$W$481,"<="&$K$2),"") -> 0.975 | Q7: =(IF(AND(ISNUMBER(C7),ISNUMBER(D7)),B7*(C7-D7),0)+IF(AND(ISNUMBER(F7),ISNUMBER(G7)),E7*(F7-G7),0)+IF(AND(ISNUMBER(I7),ISNUMBER(J7)),H7*(I7-J7),0)+IF(AND(ISNUMBER(L7),ISNUMBER(M7)),K7*(L7-M7),0)+IF(AND(ISNUMBER(O7),ISNUMBER(P7)),N7*(O7-P7),0))/(IF(AND(ISNUMBER(C7),ISNUMBER(D7)),B7,0)+IF(AND(ISNUMBER(F7),ISNUMBER(G7)),E7,0)+IF(AND(ISNUMBER(I7),ISNUMBER(J7)),H7,0)+IF(AND(ISNUMBER(L7),ISNUMBER(M7)),K7,0)+IF(AND(ISNUMBER(O7),ISNUMBER(P7)),N7,0)) -> 0.020774128 | R7: =IF(ABS(Q7)>$N$2,IF(Q7<0,"فرق كبير ضد غير العربية","فرق كبير لصالح غير العربية"),IF(ABS(Q7)>=$N$1,"يستحق الفحص","مهمل")) -> مهمل
A8: ف3 | B8: =COUNTIFS(البيانات!$B$2:$B$481,"غير العربية",البيانات!$W$2:$W$481,">="&$B$2,البيانات!$W$2:$W$481,"<="&$C$2) -> 36 | C8: =IFERROR(AVERAGEIFS(البيانات!$E$2:$E$481,البيانات!$B$2:$B$481,"غير العربية",البيانات!$W$2:$W$481,">="&$B$2,البيانات!$W$2:$W$481,"<="&$C$2),"") -> 0.027777778 | D8: =IFERROR(AVERAGEIFS(البيانات!$E$2:$E$481,البيانات!$B$2:$B$481,"عربية",البيانات!$W$2:$W$481,">="&$B$2,البيانات!$W$2:$W$481,"<="&$C$2),"") -> 0.092105263 | E8: =COUNTIFS(البيانات!$B$2:$B$481,"غير العربية",البيانات!$W$2:$W$481,">="&$D$2,البيانات!$W$2:$W$481,"<="&$E$2) -> 36 | F8: =IFERROR(AVERAGEIFS(البيانات!$E$2:$E$481,البيانات!$B$2:$B$481,"غير العربية",البيانات!$W$2:$W$481,">="&$D$2,البيانات!$W$2:$W$481,"<="&$E$2),"") -> 0.61111111 | G8: =IFERROR(AVERAGEIFS(البيانات!$E$2:$E$481,البيانات!$B$2:$B$481,"عربية",البيانات!$W$2:$W$481,">="&$D$2,البيانات!$W$2:$W$481,"<="&$E$2),"") -> 0.66153846 | H8: =COUNTIFS(البيانات!$B$2:$B$481,"غير العربية",البيانات!$W$2:$W$481,">="&$F$2,البيانات!$W$2:$W$481,"<="&$G$2) -> 37 | I8: =IFERROR(AVERAGEIFS(البيانات!$E$2:$E$481,البيانات!$B$2:$B$481,"غير العربية",البيانات!$W$2:$W$481,">="&$F$2,البيانات!$W$2:$W$481,"<="&$G$2),"") -> 0.89189189 | J8: =IFERROR(AVERAGEIFS(البيانات!$E$2:$E$481,البيانات!$B$2:$B$481,"عربية",البيانات!$W$2:$W$481,">="&$F$2,البيانات!$W$2:$W$481,"<="&$G$2),"") -> 0.84507042 | K8: =COUNTIFS(البيانات!$B$2:$B$481,"غير العربية",البيانات!$W$2:$W$481,">="&$H$2,البيانات!$W$2:$W$481,"<="&$I$2) -> 35 | L8: =IFERROR(AVERAGEIFS(البيانات!$E$2:$E$481,البيانات!$B$2:$B$481,"غير العربية",البيانات!$W$2:$W$481,">="&$H$2,البيانات!$W$2:$W$481,"<="&$I$2),"") -> 0.97142857 | M8: =IFERROR(AVERAGEIFS(البيانات!$E$2:$E$481,البيانات!$B$2:$B$481,"عربية",البيانات!$W$2:$W$481,">="&$H$2,البيانات!$W$2:$W$481,"<="&$I$2),"") -> 0.97916667 | N8: =COUNTIFS(البيانات!$B$2:$B$481,"غير العربية",البيانات!$W$2:$W$481,">="&$J$2,البيانات!$W$2:$W$481,"<="&$K$2) -> 36 | O8: =IFERROR(AVERAGEIFS(البيانات!$E$2:$E$481,البيانات!$B$2:$B$481,"غير العربية",البيانات!$W$2:$W$481,">="&$J$2,البيانات!$W$2:$W$481,"<="&$K$2),"") -> 1 | P8: =IFERROR(AVERAGEIFS(البيانات!$E$2:$E$481,البيانات!$B$2:$B$481,"عربية",البيانات!$W$2:$W$481,">="&$J$2,البيانات!$W$2:$W$481,"<="&$K$2),"") -> 0.975 | Q8: =(IF(AND(ISNUMBER(C8),ISNUMBER(D8)),B8*(C8-D8),0)+IF(AND(ISNUMBER(F8),ISNUMBER(G8)),E8*(F8-G8),0)+IF(AND(ISNUMBER(I8),ISNUMBER(J8)),H8*(I8-J8),0)+IF(AND(ISNUMBER(L8),ISNUMBER(M8)),K8*(L8-M8),0)+IF(AND(ISNUMBER(O8),ISNUMBER(P8)),N8*(O8-P8),0))/(IF(AND(ISNUMBER(C8),ISNUMBER(D8)),B8,0)+IF(AND(ISNUMBER(F8),ISNUMBER(G8)),E8,0)+IF(AND(ISNUMBER(I8),ISNUMBER(J8)),H8,0)+IF(AND(ISNUMBER(L8),ISNUMBER(M8)),K8,0)+IF(AND(ISNUMBER(O8),ISNUMBER(P8)),N8,0)) -> -0.0098311836 | R8: =IF(ABS(Q8)>$N$2,IF(Q8<0,"فرق كبير ضد غير العربية","فرق كبير لصالح غير العربية"),IF(ABS(Q8)>=$N$1,"يستحق الفحص","مهمل")) -> مهمل
A9: ف4 | B9: =COUNTIFS(البيانات!$B$2:$B$481,"غير العربية",البيانات!$W$2:$W$481,">="&$B$2,البيانات!$W$2:$W$481,"<="&$C$2) -> 36 | C9: =IFERROR(AVERAGEIFS(البيانات!$F$2:$F$481,البيانات!$B$2:$B$481,"غير العربية",البيانات!$W$2:$W$481,">="&$B$2,البيانات!$W$2:$W$481,"<="&$C$2),"") -> 0 | D9: =IFERROR(AVERAGEIFS(البيانات!$F$2:$F$481,البيانات!$B$2:$B$481,"عربية",البيانات!$W$2:$W$481,">="&$B$2,البيانات!$W$2:$W$481,"<="&$C$2),"") -> 0 | E9: =COUNTIFS(البيانات!$B$2:$B$481,"غير العربية",البيانات!$W$2:$W$481,">="&$D$2,البيانات!$W$2:$W$481,"<="&$E$2) -> 36 | F9: =IFERROR(AVERAGEIFS(البيانات!$F$2:$F$481,البيانات!$B$2:$B$481,"غير العربية",البيانات!$W$2:$W$481,">="&$D$2,البيانات!$W$2:$W$481,"<="&$E$2),"") -> 0.027777778 | G9: =IFERROR(AVERAGEIFS(البيانات!$F$2:$F$481,البيانات!$B$2:$B$481,"عربية",البيانات!$W$2:$W$481,">="&$D$2,البيانات!$W$2:$W$481,"<="&$E$2),"") -> 0.030769231 | H9: =COUNTIFS(البيانات!$B$2:$B$481,"غير العربية",البيانات!$W$2:$W$481,">="&$F$2,البيانات!$W$2:$W$481,"<="&$G$2) -> 37 | I9: =IFERROR(AVERAGEIFS(البيانات!$F$2:$F$481,البيانات!$B$2:$B$481,"غير العربية",البيانات!$W$2:$W$481,">="&$F$2,البيانات!$W$2:$W$481,"<="&$G$2),"") -> 0.054054054 | J9: =IFERROR(AVERAGEIFS(البيانات!$F$2:$F$481,البيانات!$B$2:$B$481,"عربية",البيانات!$W$2:$W$481,">="&$F$2,البيانات!$W$2:$W$481,"<="&$G$2),"") -> 0.042253521 | K9: =COUNTIFS(البيانات!$B$2:$B$481,"غير العربية",البيانات!$W$2:$W$481,">="&$H$2,البيانات!$W$2:$W$481,"<="&$I$2) -> 35 | L9: =IFERROR(AVERAGEIFS(البيانات!$F$2:$F$481,البيانات!$B$2:$B$481,"غير العربية",البيانات!$W$2:$W$481,">="&$H$2,البيانات!$W$2:$W$481,"<="&$I$2),"") -> 0.17142857 | M9: =IFERROR(AVERAGEIFS(البيانات!$F$2:$F$481,البيانات!$B$2:$B$481,"عربية",البيانات!$W$2:$W$481,">="&$H$2,البيانات!$W$2:$W$481,"<="&$I$2),"") -> 0.20833333 | N9: =COUNTIFS(البيانات!$B$2:$B$481,"غير العربية",البيانات!$W$2:$W$481,">="&$J$2,البيانات!$W$2:$W$481,"<="&$K$2) -> 36 | O9: =IFERROR(AVERAGEIFS(البيانات!$F$2:$F$481,البيانات!$B$2:$B$481,"غير العربية",البيانات!$W$2:$W$481,">="&$J$2,البيانات!$W$2:$W$481,"<="&$K$2),"") -> 0.72222222 | P9: =IFERROR(AVERAGEIFS(البيانات!$F$2:$F$481,البيانات!$B$2:$B$481,"عربية",البيانات!$W$2:$W$481,">="&$J$2,البيانات!$W$2:$W$481,"<="&$K$2),"") -> 0.675 | Q9: =(IF(AND(ISNUMBER(C9),ISNUMBER(D9)),B9*(C9-D9),0)+IF(AND(ISNUMBER(F9),ISNUMBER(G9)),E9*(F9-G9),0)+IF(AND(ISNUMBER(I9),ISNUMBER(J9)),H9*(I9-J9),0)+IF(AND(ISNUMBER(L9),ISNUMBER(M9)),K9*(L9-M9),0)+IF(AND(ISNUMBER(O9),ISNUMBER(P9)),N9*(O9-P9),0))/(IF(AND(ISNUMBER(C9),ISNUMBER(D9)),B9,0)+IF(AND(ISNUMBER(F9),ISNUMBER(G9)),E9,0)+IF(AND(ISNUMBER(I9),ISNUMBER(J9)),H9,0)+IF(AND(ISNUMBER(L9),ISNUMBER(M9)),K9,0)+IF(AND(ISNUMBER(O9),ISNUMBER(P9)),N9,0)) -> 0.004095893 | R9: =IF(ABS(Q9)>$N$2,IF(Q9<0,"فرق كبير ضد غير العربية","فرق كبير لصالح غير العربية"),IF(ABS(Q9)>=$N$1,"يستحق الفحص","مهمل")) -> مهمل
A10: ف5 | B10: =COUNTIFS(البيانات!$B$2:$B$481,"غير العربية",البيانات!$W$2:$W$481,">="&$B$2,البيانات!$W$2:$W$481,"<="&$C$2) -> 36 | C10: =IFERROR(AVERAGEIFS(البيانات!$G$2:$G$481,البيانات!$B$2:$B$481,"غير العربية",البيانات!$W$2:$W$481,">="&$B$2,البيانات!$W$2:$W$481,"<="&$C$2),"") -> 0.027777778 | D10: =IFERROR(AVERAGEIFS(البيانات!$G$2:$G$481,البيانات!$B$2:$B$481,"عربية",البيانات!$W$2:$W$481,">="&$B$2,البيانات!$W$2:$W$481,"<="&$C$2),"") -> 0 | E10: =COUNTIFS(البيانات!$B$2:$B$481,"غير العربية",البيانات!$W$2:$W$481,">="&$D$2,البيانات!$W$2:$W$481,"<="&$E$2) -> 36 | F10: =IFERROR(AVERAGEIFS(البيانات!$G$2:$G$481,البيانات!$B$2:$B$481,"غير العربية",البيانات!$W$2:$W$481,">="&$D$2,البيانات!$W$2:$W$481,"<="&$E$2),"") -> 0.13888889 | G10: =IFERROR(AVERAGEIFS(البيانات!$G$2:$G$481,البيانات!$B$2:$B$481,"عربية",البيانات!$W$2:$W$481,">="&$D$2,البيانات!$W$2:$W$481,"<="&$E$2),"") -> 0.030769231 | H10: =COUNTIFS(البيانات!$B$2:$B$481,"غير العربية",البيانات!$W$2:$W$481,">="&$F$2,البيانات!$W$2:$W$481,"<="&$G$2) -> 37 | I10: =IFERROR(AVERAGEIFS(البيانات!$G$2:$G$481,البيانات!$B$2:$B$481,"غير العربية",البيانات!$W$2:$W$481,">="&$F$2,البيانات!$W$2:$W$481,"<="&$G$2),"") -> 0.43243243 | J10: =IFERROR(AVERAGEIFS(البيانات!$G$2:$G$481,البيانات!$B$2:$B$481,"عربية",البيانات!$W$2:$W$481,">="&$F$2,البيانات!$W$2:$W$481,"<="&$G$2),"") -> 0.30985915 | K10: =COUNTIFS(البيانات!$B$2:$B$481,"غير العربية",البيانات!$W$2:$W$481,">="&$H$2,البيانات!$W$2:$W$481,"<="&$I$2) -> 35 | L10: =IFERROR(AVERAGEIFS(البيانات!$G$2:$G$481,البيانات!$B$2:$B$481,"غير العربية",البيانات!$W$2:$W$481,">="&$H$2,البيانات!$W$2:$W$481,"<="&$I$2),"") -> 0.71428571 | M10: =IFERROR(AVERAGEIFS(البيانات!$G$2:$G$481,البيانات!$B$2:$B$481,"عربية",البيانات!$W$2:$W$481,">="&$H$2,البيانات!$W$2:$W$481,"<="&$I$2),"") -> 0.72916667 | N10: =COUNTIFS(البيانات!$B$2:$B$481,"غير العربية",البيانات!$W$2:$W$481,">="&$J$2,البيانات!$W$2:$W$481,"<="&$K$2) -> 36 | O10: =IFERROR(AVERAGEIFS(البيانات!$G$2:$G$481,البيانات!$B$2:$B$481,"غير العربية",البيانات!$W$2:$W$481,">="&$J$2,البيانات!$W$2:$W$481,"<="&$K$2),"") -> 0.97222222 | P10: =IFERROR(AVERAGEIFS(البيانات!$G$2:$G$481,البيانات!$B$2:$B$481,"عربية",البيانات!$W$2:$W$481,">="&$J$2,البيانات!$W$2:$W$481,"<="&$K$2),"") -> 0.95 | Q10: =(IF(AND(ISNUMBER(C10),ISNUMBER(D10)),B10*(C10-D10),0)+IF(AND(ISNUMBER(F10),ISNUMBER(G10)),E10*(F10-G10),0)+IF(AND(ISNUMBER(I10),ISNUMBER(J10)),H10*(I10-J10),0)+IF(AND(ISNUMBER(L10),ISNUMBER(M10)),K10*(L10-M10),0)+IF(AND(ISNUMBER(O10),ISNUMBER(P10)),N10*(O10-P10),0))/(IF(AND(ISNUMBER(C10),ISNUMBER(D10)),B10,0)+IF(AND(ISNUMBER(F10),ISNUMBER(G10)),E10,0)+IF(AND(ISNUMBER(I10),ISNUMBER(J10)),H10,0)+IF(AND(ISNUMBER(L10),ISNUMBER(M10)),K10,0)+IF(AND(ISNUMBER(O10),ISNUMBER(P10)),N10,0)) -> 0.053926031 | R10: =IF(ABS(Q10)>$N$2,IF(Q10<0,"فرق كبير ضد غير العربية","فرق كبير لصالح غير العربية"),IF(ABS(Q10)>=$N$1,"يستحق الفحص","مهمل")) -> يستحق الفحص
A11: ف6 | B11: =COUNTIFS(البيانات!$B$2:$B$481,"غير العربية",البيانات!$W$2:$W$481,">="&$B$2,البيانات!$W$2:$W$481,"<="&$C$2) -> 36 | C11: =IFERROR(AVERAGEIFS(البيانات!$H$2:$H$481,البيانات!$B$2:$B$481,"غير العربية",البيانات!$W$2:$W$481,">="&$B$2,البيانات!$W$2:$W$481,"<="&$C$2),"") -> 0.027777778 | D11: =IFERROR(AVERAGEIFS(البيانات!$H$2:$H$481,البيانات!$B$2:$B$481,"عربية",البيانات!$W$2:$W$481,">="&$B$2,البيانات!$W$2:$W$481,"<="&$C$2),"") -> 0.21052632 | E11: =COUNTIFS(البيانات!$B$2:$B$481,"غير العربية",البيانات!$W$2:$W$481,">="&$D$2,البيانات!$W$2:$W$481,"<="&$E$2) -> 36 | F11: =IFERROR(AVERAGEIFS(البيانات!$H$2:$H$481,البيانات!$B$2:$B$481,"غير العربية",البيانات!$W$2:$W$481,">="&$D$2,البيانات!$W$2:$W$481,"<="&$E$2),"") -> 0.13888889 | G11: =IFERROR(AVERAGEIFS(البيانات!$H$2:$H$481,البيانات!$B$2:$B$481,"عربية",البيانات!$W$2:$W$481,">="&$D$2,البيانات!$W$2:$W$481,"<="&$E$2),"") -> 0.66153846 | H11: =COUNTIFS(البيانات!$B$2:$B$481,"غير العربية",البيانات!$W$2:$W$481,">="&$F$2,البيانات!$W$2:$W$481,"<="&$G$2) -> 37 | I11: =IFERROR(AVERAGEIFS(البيانات!$H$2:$H$481,البيانات!$B$2:$B$481,"غير العربية",البيانات!$W$2:$W$481,">="&$F$2,البيانات!$W$2:$W$481,"<="&$G$2),"") -> 0.51351351 | J11: =IFERROR(AVERAGEIFS(البيانات!$H$2:$H$481,البيانات!$B$2:$B$481,"عربية",البيانات!$W$2:$W$481,">="&$F$2,البيانات!$W$2:$W$481,"<="&$G$2),"") -> 0.84507042 | K11: =COUNTIFS(البيانات!$B$2:$B$481,"غير العربية",البيانات!$W$2:$W$481,">="&$H$2,البيانات!$W$2:$W$481,"<="&$I$2) -> 35 | L11: =IFERROR(AVERAGEIFS(البيانات!$H$2:$H$481,البيانات!$B$2:$B$481,"غير العربية",البيانات!$W$2:$W$481,">="&$H$2,البيانات!$W$2:$W$481,"<="&$I$2),"") -> 0.68571429 | M11: =IFERROR(AVERAGEIFS(البيانات!$H$2:$H$481,البيانات!$B$2:$B$481,"عربية",البيانات!$W$2:$W$481,">="&$H$2,البيانات!$W$2:$W$481,"<="&$I$2),"") -> 0.97916667 | N11: =COUNTIFS(البيانات!$B$2:$B$481,"غير العربية",البيانات!$W$2:$W$481,">="&$J$2,البيانات!$W$2:$W$481,"<="&$K$2) -> 36 | O11: =IFERROR(AVERAGEIFS(البيانات!$H$2:$H$481,البيانات!$B$2:$B$481,"غير العربية",البيانات!$W$2:$W$481,">="&$J$2,البيانات!$W$2:$W$481,"<="&$K$2),"") -> 0.94444444 | P11: =IFERROR(AVERAGEIFS(البيانات!$H$2:$H$481,البيانات!$B$2:$B$481,"عربية",البيانات!$W$2:$W$481,">="&$J$2,البيانات!$W$2:$W$481,"<="&$K$2),"") -> 1 | Q11: =(IF(AND(ISNUMBER(C11),ISNUMBER(D11)),B11*(C11-D11),0)+IF(AND(ISNUMBER(F11),ISNUMBER(G11)),E11*(F11-G11),0)+IF(AND(ISNUMBER(I11),ISNUMBER(J11)),H11*(I11-J11),0)+IF(AND(ISNUMBER(L11),ISNUMBER(M11)),K11*(L11-M11),0)+IF(AND(ISNUMBER(O11),ISNUMBER(P11)),N11*(O11-P11),0))/(IF(AND(ISNUMBER(C11),ISNUMBER(D11)),B11,0)+IF(AND(ISNUMBER(F11),ISNUMBER(G11)),E11,0)+IF(AND(ISNUMBER(I11),ISNUMBER(J11)),H11,0)+IF(AND(ISNUMBER(L11),ISNUMBER(M11)),K11,0)+IF(AND(ISNUMBER(O11),ISNUMBER(P11)),N11,0)) -> -0.27740428 | R11: =IF(ABS(Q11)>$N$2,IF(Q11<0,"فرق كبير ضد غير العربية","فرق كبير لصالح غير العربية"),IF(ABS(Q11)>=$N$1,"يستحق الفحص","مهمل")) -> فرق كبير ضد غير العربية
A12: ف7 | B12: =COUNTIFS(البيانات!$B$2:$B$481,"غير العربية",البيانات!$W$2:$W$481,">="&$B$2,البيانات!$W$2:$W$481,"<="&$C$2) -> 36 | C12: =IFERROR(AVERAGEIFS(البيانات!$I$2:$I$481,البيانات!$B$2:$B$481,"غير العربية",البيانات!$W$2:$W$481,">="&$B$2,البيانات!$W$2:$W$481,"<="&$C$2),"") -> 0.055555556 | D12: =IFERROR(AVERAGEIFS(البيانات!$I$2:$I$481,البيانات!$B$2:$B$481,"عربية",البيانات!$W$2:$W$481,">="&$B$2,البيانات!$W$2:$W$481,"<="&$C$2),"") -> 0.013157895 | E12: =COUNTIFS(البيانات!$B$2:$B$481,"غير العربية",البيانات!$W$2:$W$481,">="&$D$2,البيانات!$W$2:$W$481,"<="&$E$2) -> 36 | F12: =IFERROR(AVERAGEIFS(البيانات!$I$2:$I$481,البيانات!$B$2:$B$481,"غير العربية",البيانات!$W$2:$W$481,">="&$D$2,البيانات!$W$2:$W$481,"<="&$E$2),"") -> 0.055555556 | G12: =IFERROR(AVERAGEIFS(البيانات!$I$2:$I$481,البيانات!$B$2:$B$481,"عربية",البيانات!$W$2:$W$481,">="&$D$2,البيانات!$W$2:$W$481,"<="&$E$2),"") -> 0.061538462 | H12: =COUNTIFS(البيانات!$B$2:$B$481,"غير العربية",البيانات!$W$2:$W$481,">="&$F$2,البيانات!$W$2:$W$481,"<="&$G$2) -> 37 | I12: =IFERROR(AVERAGEIFS(البيانات!$I$2:$I$481,البيانات!$B$2:$B$481,"غير العربية",البيانات!$W$2:$W$481,">="&$F$2,البيانات!$W$2:$W$481,"<="&$G$2),"") -> 0.18918919 | J12: =IFERROR(AVERAGEIFS(البيانات!$I$2:$I$481,البيانات!$B$2:$B$481,"عربية",البيانات!$W$2:$W$481,">="&$F$2,البيانات!$W$2:$W$481,"<="&$G$2),"") -> 0.25352113 | K12: =COUNTIFS(البيانات!$B$2:$B$481,"غير العربية",البيانات!$W$2:$W$481,">="&$H$2,البيانات!$W$2:$W$481,"<="&$I$2) -> 35 | L12: =IFERROR(AVERAGEIFS(البيانات!$I$2:$I$481,البيانات!$B$2:$B$481,"غير العربية",البيانات!$W$2:$W$481,">="&$H$2,البيانات!$W$2:$W$481,"<="&$I$2),"") -> 0.4 | M12: =IFERROR(AVERAGEIFS(البيانات!$I$2:$I$481,البيانات!$B$2:$B$481,"عربية",البيانات!$W$2:$W$481,">="&$H$2,البيانات!$W$2:$W$481,"<="&$I$2),"") -> 0.33333333 | N12: =COUNTIFS(البيانات!$B$2:$B$481,"غير العربية",البيانات!$W$2:$W$481,">="&$J$2,البيانات!$W$2:$W$481,"<="&$K$2) -> 36 | O12: =IFERROR(AVERAGEIFS(البيانات!$I$2:$I$481,البيانات!$B$2:$B$481,"غير العربية",البيانات!$W$2:$W$481,">="&$J$2,البيانات!$W$2:$W$481,"<="&$K$2),"") -> 0.91666667 | P12: =IFERROR(AVERAGEIFS(البيانات!$I$2:$I$481,البيانات!$B$2:$B$481,"عربية",البيانات!$W$2:$W$481,">="&$J$2,البيانات!$W$2:$W$481,"<="&$K$2),"") -> 0.85 | Q12: =(IF(AND(ISNUMBER(C12),ISNUMBER(D12)),B12*(C12-D12),0)+IF(AND(ISNUMBER(F12),ISNUMBER(G12)),E12*(F12-G12),0)+IF(AND(ISNUMBER(I12),ISNUMBER(J12)),H12*(I12-J12),0)+IF(AND(ISNUMBER(L12),ISNUMBER(M12)),K12*(L12-M12),0)+IF(AND(ISNUMBER(O12),ISNUMBER(P12)),N12*(O12-P12),0))/(IF(AND(ISNUMBER(C12),ISNUMBER(D12)),B12,0)+IF(AND(ISNUMBER(F12),ISNUMBER(G12)),E12,0)+IF(AND(ISNUMBER(I12),ISNUMBER(J12)),H12,0)+IF(AND(ISNUMBER(L12),ISNUMBER(M12)),K12,0)+IF(AND(ISNUMBER(O12),ISNUMBER(P12)),N12,0)) -> 0.02035546 | R12: =IF(ABS(Q12)>$N$2,IF(Q12<0,"فرق كبير ضد غير العربية","فرق كبير لصالح غير العربية"),IF(ABS(Q12)>=$N$1,"يستحق الفحص","مهمل")) -> مهمل
A13: ف8 | B13: =COUNTIFS(البيانات!$B$2:$B$481,"غير العربية",البيانات!$W$2:$W$481,">="&$B$2,البيانات!$W$2:$W$481,"<="&$C$2) -> 36 | C13: =IFERROR(AVERAGEIFS(البيانات!$J$2:$J$481,البيانات!$B$2:$B$481,"غير العربية",البيانات!$W$2:$W$481,">="&$B$2,البيانات!$W$2:$W$481,"<="&$C$2),"") -> 0 | D13: =IFERROR(AVERAGEIFS(البيانات!$J$2:$J$481,البيانات!$B$2:$B$481,"عربية",البيانات!$W$2:$W$481,">="&$B$2,البيانات!$W$2:$W$481,"<="&$C$2),"") -> 0 | E13: =COUNTIFS(البيانات!$B$2:$B$481,"غير العربية",البيانات!$W$2:$W$481,">="&$D$2,البيانات!$W$2:$W$481,"<="&$E$2) -> 36 | F13: =IFERROR(AVERAGEIFS(البيانات!$J$2:$J$481,البيانات!$B$2:$B$481,"غير العربية",البيانات!$W$2:$W$481,">="&$D$2,البيانات!$W$2:$W$481,"<="&$E$2),"") -> 0.027777778 | G13: =IFERROR(AVERAGEIFS(البيانات!$J$2:$J$481,البيانات!$B$2:$B$481,"عربية",البيانات!$W$2:$W$481,">="&$D$2,البيانات!$W$2:$W$481,"<="&$E$2),"") -> 0.015384615 | H13: =COUNTIFS(البيانات!$B$2:$B$481,"غير العربية",البيانات!$W$2:$W$481,">="&$F$2,البيانات!$W$2:$W$481,"<="&$G$2) -> 37 | I13: =IFERROR(AVERAGEIFS(البيانات!$J$2:$J$481,البيانات!$B$2:$B$481,"غير العربية",البيانات!$W$2:$W$481,">="&$F$2,البيانات!$W$2:$W$481,"<="&$G$2),"") -> 0.18918919 | J13: =IFERROR(AVERAGEIFS(البيانات!$J$2:$J$481,البيانات!$B$2:$B$481,"عربية",البيانات!$W$2:$W$481,">="&$F$2,البيانات!$W$2:$W$481,"<="&$G$2),"") -> 0.14084507 | K13: =COUNTIFS(البيانات!$B$2:$B$481,"غير العربية",البيانات!$W$2:$W$481,">="&$H$2,البيانات!$W$2:$W$481,"<="&$I$2) -> 35 | L13: =IFERROR(AVERAGEIFS(البيانات!$J$2:$J$481,البيانات!$B$2:$B$481,"غير العربية",البيانات!$W$2:$W$481,">="&$H$2,البيانات!$W$2:$W$481,"<="&$I$2),"") -> 0.34285714 | M13: =IFERROR(AVERAGEIFS(البيانات!$J$2:$J$481,البيانات!$B$2:$B$481,"عربية",البيانات!$W$2:$W$481,">="&$H$2,البيانات!$W$2:$W$481,"<="&$I$2),"") -> 0.35416667 | N13: =COUNTIFS(البيانات!$B$2:$B$481,"غير العربية",البيانات!$W$2:$W$481,">="&$J$2,البيانات!$W$2:$W$481,"<="&$K$2) -> 36 | O13: =IFERROR(AVERAGEIFS(البيانات!$J$2:$J$481,البيانات!$B$2:$B$481,"غير العربية",البيانات!$W$2:$W$481,">="&$J$2,البيانات!$W$2:$W$481,"<="&$K$2),"") -> 0.80555556 | P13: =IFERROR(AVERAGEIFS(البيانات!$J$2:$J$481,البيانات!$B$2:$B$481,"عربية",البيانات!$W$2:$W$481,">="&$J$2,البيانات!$W$2:$W$481,"<="&$K$2),"") -> 0.925 | Q13: =(IF(AND(ISNUMBER(C13),ISNUMBER(D13)),B13*(C13-D13),0)+IF(AND(ISNUMBER(F13),ISNUMBER(G13)),E13*(F13-G13),0)+IF(AND(ISNUMBER(I13),ISNUMBER(J13)),H13*(I13-J13),0)+IF(AND(ISNUMBER(L13),ISNUMBER(M13)),K13*(L13-M13),0)+IF(AND(ISNUMBER(O13),ISNUMBER(P13)),N13*(O13-P13),0))/(IF(AND(ISNUMBER(C13),ISNUMBER(D13)),B13,0)+IF(AND(ISNUMBER(F13),ISNUMBER(G13)),E13,0)+IF(AND(ISNUMBER(I13),ISNUMBER(J13)),H13,0)+IF(AND(ISNUMBER(L13),ISNUMBER(M13)),K13,0)+IF(AND(ISNUMBER(O13),ISNUMBER(P13)),N13,0)) -> -0.013671928 | R13: =IF(ABS(Q13)>$N$2,IF(Q13<0,"فرق كبير ضد غير العربية","فرق كبير لصالح غير العربية"),IF(ABS(Q13)>=$N$1,"يستحق الفحص","مهمل")) -> مهمل
A14: ف9 | B14: =COUNTIFS(البيانات!$B$2:$B$481,"غير العربية",البيانات!$W$2:$W$481,">="&$B$2,البيانات!$W$2:$W$481,"<="&$C$2) -> 36 | C14: =IFERROR(AVERAGEIFS(البيانات!$K$2:$K$481,البيانات!$B$2:$B$481,"غير العربية",البيانات!$W$2:$W$481,">="&$B$2,البيانات!$W$2:$W$481,"<="&$C$2),"") -> 0.19444444 | D14: =IFERROR(AVERAGEIFS(البيانات!$K$2:$K$481,البيانات!$B$2:$B$481,"عربية",البيانات!$W$2:$W$481,">="&$B$2,البيانات!$W$2:$W$481,"<="&$C$2),"") -> 0.26315789 | E14: =COUNTIFS(البيانات!$B$2:$B$481,"غير العربية",البيانات!$W$2:$W$481,">="&$D$2,البيانات!$W$2:$W$481,"<="&$E$2) -> 36 | F14: =IFERROR(AVERAGEIFS(البيانات!$K$2:$K$481,البيانات!$B$2:$B$481,"غير العربية",البيانات!$W$2:$W$481,">="&$D$2,البيانات!$W$2:$W$481,"<="&$E$2),"") -> 0.66666667 | G14: =IFERROR(AVERAGEIFS(البيانات!$K$2:$K$481,البيانات!$B$2:$B$481,"عربية",البيانات!$W$2:$W$481,">="&$D$2,البيانات!$W$2:$W$481,"<="&$E$2),"") -> 0.72307692 | H14: =COUNTIFS(البيانات!$B$2:$B$481,"غير العربية",البيانات!$W$2:$W$481,">="&$F$2,البيانات!$W$2:$W$481,"<="&$G$2) -> 37 | I14: =IFERROR(AVERAGEIFS(البيانات!$K$2:$K$481,البيانات!$B$2:$B$481,"غير العربية",البيانات!$W$2:$W$481,">="&$F$2,البيانات!$W$2:$W$481,"<="&$G$2),"") -> 0.91891892 | J14: =IFERROR(AVERAGEIFS(البيانات!$K$2:$K$481,البيانات!$B$2:$B$481,"عربية",البيانات!$W$2:$W$481,">="&$F$2,البيانات!$W$2:$W$481,"<="&$G$2),"") -> 0.92957746 | K14: =COUNTIFS(البيانات!$B$2:$B$481,"غير العربية",البيانات!$W$2:$W$481,">="&$H$2,البيانات!$W$2:$W$481,"<="&$I$2) -> 35 | L14: =IFERROR(AVERAGEIFS(البيانات!$K$2:$K$481,البيانات!$B$2:$B$481,"غير العربية",البيانات!$W$2:$W$481,">="&$H$2,البيانات!$W$2:$W$481,"<="&$I$2),"") -> 1 | M14: =IFERROR(AVERAGEIFS(البيانات!$K$2:$K$481,البيانات!$B$2:$B$481,"عربية",البيانات!$W$2:$W$481,">="&$H$2,البيانات!$W$2:$W$481,"<="&$I$2),"") -> 0.97916667 | N14: =COUNTIFS(البيانات!$B$2:$B$481,"غير العربية",البيانات!$W$2:$W$481,">="&$J$2,البيانات!$W$2:$W$481,"<="&$K$2) -> 36 | O14: =IFERROR(AVERAGEIFS(البيانات!$K$2:$K$481,البيانات!$B$2:$B$481,"غير العربية",البيانات!$W$2:$W$481,">="&$J$2,البيانات!$W$2:$W$481,"<="&$K$2),"") -> 1 | P14: =IFERROR(AVERAGEIFS(البيانات!$K$2:$K$481,البيانات!$B$2:$B$481,"عربية",البيانات!$W$2:$W$481,">="&$J$2,البيانات!$W$2:$W$481,"<="&$K$2),"") -> 1 | Q14: =(IF(AND(ISNUMBER(C14),ISNUMBER(D14)),B14*(C14-D14),0)+IF(AND(ISNUMBER(F14),ISNUMBER(G14)),E14*(F14-G14),0)+IF(AND(ISNUMBER(I14),ISNUMBER(J14)),H14*(I14-J14),0)+IF(AND(ISNUMBER(L14),ISNUMBER(M14)),K14*(L14-M14),0)+IF(AND(ISNUMBER(O14),ISNUMBER(P14)),N14*(O14-P14),0))/(IF(AND(ISNUMBER(C14),ISNUMBER(D14)),B14,0)+IF(AND(ISNUMBER(F14),ISNUMBER(G14)),E14,0)+IF(AND(ISNUMBER(I14),ISNUMBER(J14)),H14,0)+IF(AND(ISNUMBER(L14),ISNUMBER(M14)),K14,0)+IF(AND(ISNUMBER(O14),ISNUMBER(P14)),N14,0)) -> -0.023164739 | R14: =IF(ABS(Q14)>$N$2,IF(Q14<0,"فرق كبير ضد غير العربية","فرق كبير لصالح غير العربية"),IF(ABS(Q14)>=$N$1,"يستحق الفحص","مهمل")) -> مهمل
A15: ف10 | B15: =COUNTIFS(البيانات!$B$2:$B$481,"غير العربية",البيانات!$W$2:$W$481,">="&$B$2,البيانات!$W$2:$W$481,"<="&$C$2) -> 36 | C15: =IFERROR(AVERAGEIFS(البيانات!$L$2:$L$481,البيانات!$B$2:$B$481,"غير العربية",البيانات!$W$2:$W$481,">="&$B$2,البيانات!$W$2:$W$481,"<="&$C$2),"") -> 0 | D15: =IFERROR(AVERAGEIFS(البيانات!$L$2:$L$481,البيانات!$B$2:$B$481,"عربية",البيانات!$W$2:$W$481,">="&$B$2,البيانات!$W$2:$W$481,"<="&$C$2),"") -> 0.013157895 | E15: =COUNTIFS(البيانات!$B$2:$B$481,"غير العربية",البيانات!$W$2:$W$481,">="&$D$2,البيانات!$W$2:$W$481,"<="&$E$2) -> 36 | F15: =IFERROR(AVERAGEIFS(البيانات!$L$2:$L$481,البيانات!$B$2:$B$481,"غير العربية",البيانات!$W$2:$W$481,">="&$D$2,البيانات!$W$2:$W$481,"<="&$E$2),"") -> 0.13888889 | G15: =IFERROR(AVERAGEIFS(البيانات!$L$2:$L$481,البيانات!$B$2:$B$481,"عربية",البيانات!$W$2:$W$481,">="&$D$2,البيانات!$W$2:$W$481,"<="&$E$2),"") -> 0.16923077 | H15: =COUNTIFS(البيانات!$B$2:$B$481,"غير العربية",البيانات!$W$2:$W$481,">="&$F$2,البيانات!$W$2:$W$481,"<="&$G$2) -> 37 | I15: =IFERROR(AVERAGEIFS(البيانات!$L$2:$L$481,البيانات!$B$2:$B$481,"غير العربية",البيانات!$W$2:$W$481,">="&$F$2,البيانات!$W$2:$W$481,"<="&$G$2),"") -> 0.18918919 | J15: =IFERROR(AVERAGEIFS(البيانات!$L$2:$L$481,البيانات!$B$2:$B$481,"عربية",البيانات!$W$2:$W$481,">="&$F$2,البيانات!$W$2:$W$481,"<="&$G$2),"") -> 0.4084507 | K15: =COUNTIFS(البيانات!$B$2:$B$481,"غير العربية",البيانات!$W$2:$W$481,">="&$H$2,البيانات!$W$2:$W$481,"<="&$I$2) -> 35 | L15: =IFERROR(AVERAGEIFS(البيانات!$L$2:$L$481,البيانات!$B$2:$B$481,"غير العربية",البيانات!$W$2:$W$481,">="&$H$2,البيانات!$W$2:$W$481,"<="&$I$2),"") -> 0.71428571 | M15: =IFERROR(AVERAGEIFS(البيانات!$L$2:$L$481,البيانات!$B$2:$B$481,"عربية",البيانات!$W$2:$W$481,">="&$H$2,البيانات!$W$2:$W$481,"<="&$I$2),"") -> 0.75 | N15: =COUNTIFS(البيانات!$B$2:$B$481,"غير العربية",البيانات!$W$2:$W$481,">="&$J$2,البيانات!$W$2:$W$481,"<="&$K$2) -> 36 | O15: =IFERROR(AVERAGEIFS(البيانات!$L$2:$L$481,البيانات!$B$2:$B$481,"غير العربية",البيانات!$W$2:$W$481,">="&$J$2,البيانات!$W$2:$W$481,"<="&$K$2),"") -> 0.94444444 | P15: =IFERROR(AVERAGEIFS(البيانات!$L$2:$L$481,البيانات!$B$2:$B$481,"عربية",البيانات!$W$2:$W$481,">="&$J$2,البيانات!$W$2:$W$481,"<="&$K$2),"") -> 0.95 | Q15: =(IF(AND(ISNUMBER(C15),ISNUMBER(D15)),B15*(C15-D15),0)+IF(AND(ISNUMBER(F15),ISNUMBER(G15)),E15*(F15-G15),0)+IF(AND(ISNUMBER(I15),ISNUMBER(J15)),H15*(I15-J15),0)+IF(AND(ISNUMBER(L15),ISNUMBER(M15)),K15*(L15-M15),0)+IF(AND(ISNUMBER(O15),ISNUMBER(P15)),N15*(O15-P15),0))/(IF(AND(ISNUMBER(C15),ISNUMBER(D15)),B15,0)+IF(AND(ISNUMBER(F15),ISNUMBER(G15)),E15,0)+IF(AND(ISNUMBER(I15),ISNUMBER(J15)),H15,0)+IF(AND(ISNUMBER(L15),ISNUMBER(M15)),K15,0)+IF(AND(ISNUMBER(O15),ISNUMBER(P15)),N15,0)) -> -0.061825933 | R15: =IF(ABS(Q15)>$N$2,IF(Q15<0,"فرق كبير ضد غير العربية","فرق كبير لصالح غير العربية"),IF(ABS(Q15)>=$N$1,"يستحق الفحص","مهمل")) -> يستحق الفحص
A16: ف11 | B16: =COUNTIFS(البيانات!$B$2:$B$481,"غير العربية",البيانات!$W$2:$W$481,">="&$B$2,البيانات!$W$2:$W$481,"<="&$C$2) -> 36 | C16: =IFERROR(AVERAGEIFS(البيانات!$M$2:$M$481,البيانات!$B$2:$B$481,"غير العربية",البيانات!$W$2:$W$481,">="&$B$2,البيانات!$W$2:$W$481,"<="&$C$2),"") -> 0 | D16: =IFERROR(AVERAGEIFS(البيانات!$M$2:$M$481,البيانات!$B$2:$B$481,"عربية",البيانات!$W$2:$W$481,">="&$B$2,البيانات!$W$2:$W$481,"<="&$C$2),"") -> 0 | E16: =COUNTIFS(البيانات!$B$2:$B$481,"غير العربية",البيانات!$W$2:$W$481,">="&$D$2,البيانات!$W$2:$W$481,"<="&$E$2) -> 36 | F16: =IFERROR(AVERAGEIFS(البيانات!$M$2:$M$481,البيانات!$B$2:$B$481,"غير العربية",البيانات!$W$2:$W$481,">="&$D$2,البيانات!$W$2:$W$481,"<="&$E$2),"") -> 0.13888889 | G16: =IFERROR(AVERAGEIFS(البيانات!$M$2:$M$481,البيانات!$B$2:$B$481,"عربية",البيانات!$W$2:$W$481,">="&$D$2,البيانات!$W$2:$W$481,"<="&$E$2),"") -> 0.046153846 | H16: =COUNTIFS(البيانات!$B$2:$B$481,"غير العربية",البيانات!$W$2:$W$481,">="&$F$2,البيانات!$W$2:$W$481,"<="&$G$2) -> 37 | I16: =IFERROR(AVERAGEIFS(البيانات!$M$2:$M$481,البيانات!$B$2:$B$481,"غير العربية",البيانات!$W$2:$W$481,">="&$F$2,البيانات!$W$2:$W$481,"<="&$G$2),"") -> 0.51351351 | J16: =IFERROR(AVERAGEIFS(البيانات!$M$2:$M$481,البيانات!$B$2:$B$481,"عربية",البيانات!$W$2:$W$481,">="&$F$2,البيانات!$W$2:$W$481,"<="&$G$2),"") -> 0.29577465 | K16: =COUNTIFS(البيانات!$B$2:$B$481,"غير العربية",البيانات!$W$2:$W$481,">="&$H$2,البيانات!$W$2:$W$481,"<="&$I$2) -> 35 | L16: =IFERROR(AVERAGEIFS(البيانات!$M$2:$M$481,البيانات!$B$2:$B$481,"غير العربية",البيانات!$W$2:$W$481,">="&$H$2,البيانات!$W$2:$W$481,"<="&$I$2),"") -> 0.77142857 | M16: =IFERROR(AVERAGEIFS(البيانات!$M$2:$M$481,البيانات!$B$2:$B$481,"عربية",البيانات!$W$2:$W$481,">="&$H$2,البيانات!$W$2:$W$481,"<="&$I$2),"") -> 0.83333333 | N16: =COUNTIFS(البيانات!$B$2:$B$481,"غير العربية",البيانات!$W$2:$W$481,">="&$J$2,البيانات!$W$2:$W$481,"<="&$K$2) -> 36 | O16: =IFERROR(AVERAGEIFS(البيانات!$M$2:$M$481,البيانات!$B$2:$B$481,"غير العربية",البيانات!$W$2:$W$481,">="&$J$2,البيانات!$W$2:$W$481,"<="&$K$2),"") -> 1 | P16: =IFERROR(AVERAGEIFS(البيانات!$M$2:$M$481,البيانات!$B$2:$B$481,"عربية",البيانات!$W$2:$W$481,">="&$J$2,البيانات!$W$2:$W$481,"<="&$K$2),"") -> 0.95 | Q16: =(IF(AND(ISNUMBER(C16),ISNUMBER(D16)),B16*(C16-D16),0)+IF(AND(ISNUMBER(F16),ISNUMBER(G16)),E16*(F16-G16),0)+IF(AND(ISNUMBER(I16),ISNUMBER(J16)),H16*(I16-J16),0)+IF(AND(ISNUMBER(L16),ISNUMBER(M16)),K16*(L16-M16),0)+IF(AND(ISNUMBER(O16),ISNUMBER(P16)),N16*(O16-P16),0))/(IF(AND(ISNUMBER(C16),ISNUMBER(D16)),B16,0)+IF(AND(ISNUMBER(F16),ISNUMBER(G16)),E16,0)+IF(AND(ISNUMBER(I16),ISNUMBER(J16)),H16,0)+IF(AND(ISNUMBER(L16),ISNUMBER(M16)),K16,0)+IF(AND(ISNUMBER(O16),ISNUMBER(P16)),N16,0)) -> 0.061267405 | R16: =IF(ABS(Q16)>$N$2,IF(Q16<0,"فرق كبير ضد غير العربية","فرق كبير لصالح غير العربية"),IF(ABS(Q16)>=$N$1,"يستحق الفحص","مهمل")) -> يستحق الفحص
A17: ف12 | B17: =COUNTIFS(البيانات!$B$2:$B$481,"غير العربية",البيانات!$W$2:$W$481,">="&$B$2,البيانات!$W$2:$W$481,"<="&$C$2) -> 36 | C17: =IFERROR(AVERAGEIFS(البيانات!$N$2:$N$481,البيانات!$B$2:$B$481,"غير العربية",البيانات!$W$2:$W$481,">="&$B$2,البيانات!$W$2:$W$481,"<="&$C$2),"") -> 0.66666667 | D17: =IFERROR(AVERAGEIFS(البيانات!$N$2:$N$481,البيانات!$B$2:$B$481,"عربية",البيانات!$W$2:$W$481,">="&$B$2,البيانات!$W$2:$W$481,"<="&$C$2),"") -> 0.57894737 | E17: =COUNTIFS(البيانات!$B$2:$B$481,"غير العربية",البيانات!$W$2:$W$481,">="&$D$2,البيانات!$W$2:$W$481,"<="&$E$2) -> 36 | F17: =IFERROR(AVERAGEIFS(البيانات!$N$2:$N$481,البيانات!$B$2:$B$481,"غير العربية",البيانات!$W$2:$W$481,">="&$D$2,البيانات!$W$2:$W$481,"<="&$E$2),"") -> 0.94444444 | G17: =IFERROR(AVERAGEIFS(البيانات!$N$2:$N$481,البيانات!$B$2:$B$481,"عربية",البيانات!$W$2:$W$481,">="&$D$2,البيانات!$W$2:$W$481,"<="&$E$2),"") -> 0.93846154 | H17: =COUNTIFS(البيانات!$B$2:$B$481,"غير العربية",البيانات!$W$2:$W$481,">="&$F$2,البيانات!$W$2:$W$481,"<="&$G$2) -> 37 | I17: =IFERROR(AVERAGEIFS(البيانات!$N$2:$N$481,البيانات!$B$2:$B$481,"غير العربية",البيانات!$W$2:$W$481,">="&$F$2,البيانات!$W$2:$W$481,"<="&$G$2),"") -> 0.97297297 | J17: =IFERROR(AVERAGEIFS(البيانات!$N$2:$N$481,البيانات!$B$2:$B$481,"عربية",البيانات!$W$2:$W$481,">="&$F$2,البيانات!$W$2:$W$481,"<="&$G$2),"") -> 0.97183099 | K17: =COUNTIFS(البيانات!$B$2:$B$481,"غير العربية",البيانات!$W$2:$W$481,">="&$H$2,البيانات!$W$2:$W$481,"<="&$I$2) -> 35 | L17: =IFERROR(AVERAGEIFS(البيانات!$N$2:$N$481,البيانات!$B$2:$B$481,"غير العربية",البيانات!$W$2:$W$481,">="&$H$2,البيانات!$W$2:$W$481,"<="&$I$2),"") -> 1 | M17: =IFERROR(AVERAGEIFS(البيانات!$N$2:$N$481,البيانات!$B$2:$B$481,"عربية",البيانات!$W$2:$W$481,">="&$H$2,البيانات!$W$2:$W$481,"<="&$I$2),"") -> 1 | N17: =COUNTIFS(البيانات!$B$2:$B$481,"غير العربية",البيانات!$W$2:$W$481,">="&$J$2,البيانات!$W$2:$W$481,"<="&$K$2) -> 36 | O17: =IFERROR(AVERAGEIFS(البيانات!$N$2:$N$481,البيانات!$B$2:$B$481,"غير العربية",البيانات!$W$2:$W$481,">="&$J$2,البيانات!$W$2:$W$481,"<="&$K$2),"") -> 1 | P17: =IFERROR(AVERAGEIFS(البيانات!$N$2:$N$481,البيانات!$B$2:$B$481,"عربية",البيانات!$W$2:$W$481,">="&$J$2,البيانات!$W$2:$W$481,"<="&$K$2),"") -> 1 | Q17: =(IF(AND(ISNUMBER(C17),ISNUMBER(D17)),B17*(C17-D17),0)+IF(AND(ISNUMBER(F17),ISNUMBER(G17)),E17*(F17-G17),0)+IF(AND(ISNUMBER(I17),ISNUMBER(J17)),H17*(I17-J17),0)+IF(AND(ISNUMBER(L17),ISNUMBER(M17)),K17*(L17-M17),0)+IF(AND(ISNUMBER(O17),ISNUMBER(P17)),N17*(O17-P17),0))/(IF(AND(ISNUMBER(C17),ISNUMBER(D17)),B17,0)+IF(AND(ISNUMBER(F17),ISNUMBER(G17)),E17,0)+IF(AND(ISNUMBER(I17),ISNUMBER(J17)),H17,0)+IF(AND(ISNUMBER(L17),ISNUMBER(M17)),K17,0)+IF(AND(ISNUMBER(O17),ISNUMBER(P17)),N17,0)) -> 0.018975183 | R17: =IF(ABS(Q17)>$N$2,IF(Q17<0,"فرق كبير ضد غير العربية","فرق كبير لصالح غير العربية"),IF(ABS(Q17)>=$N$1,"يستحق الفحص","مهمل")) -> مهمل
A18: ف13 | B18: =COUNTIFS(البيانات!$B$2:$B$481,"غير العربية",البيانات!$W$2:$W$481,">="&$B$2,البيانات!$W$2:$W$481,"<="&$C$2) -> 36 | C18: =IFERROR(AVERAGEIFS(البيانات!$O$2:$O$481,البيانات!$B$2:$B$481,"غير العربية",البيانات!$W$2:$W$481,">="&$B$2,البيانات!$W$2:$W$481,"<="&$C$2),"") -> 0.027777778 | D18: =IFERROR(AVERAGEIFS(البيانات!$O$2:$O$481,البيانات!$B$2:$B$481,"عربية",البيانات!$W$2:$W$481,">="&$B$2,البيانات!$W$2:$W$481,"<="&$C$2),"") -> 0.078947368 | E18: =COUNTIFS(البيانات!$B$2:$B$481,"غير العربية",البيانات!$W$2:$W$481,">="&$D$2,البيانات!$W$2:$W$481,"<="&$E$2) -> 36 | F18: =IFERROR(AVERAGEIFS(البيانات!$O$2:$O$481,البيانات!$B$2:$B$481,"غير العربية",البيانات!$W$2:$W$481,">="&$D$2,البيانات!$W$2:$W$481,"<="&$E$2),"") -> 0.30555556 | G18: =IFERROR(AVERAGEIFS(البيانات!$O$2:$O$481,البيانات!$B$2:$B$481,"عربية",البيانات!$W$2:$W$481,">="&$D$2,البيانات!$W$2:$W$481,"<="&$E$2),"") -> 0.30769231 | H18: =COUNTIFS(البيانات!$B$2:$B$481,"غير العربية",البيانات!$W$2:$W$481,">="&$F$2,البيانات!$W$2:$W$481,"<="&$G$2) -> 37 | I18: =IFERROR(AVERAGEIFS(البيانات!$O$2:$O$481,البيانات!$B$2:$B$481,"غير العربية",البيانات!$W$2:$W$481,">="&$F$2,البيانات!$W$2:$W$481,"<="&$G$2),"") -> 0.59459459 | J18: =IFERROR(AVERAGEIFS(البيانات!$O$2:$O$481,البيانات!$B$2:$B$481,"عربية",البيانات!$W$2:$W$481,">="&$F$2,البيانات!$W$2:$W$481,"<="&$G$2),"") -> 0.49295775 | K18: =COUNTIFS(البيانات!$B$2:$B$481,"غير العربية",البيانات!$W$2:$W$481,">="&$H$2,البيانات!$W$2:$W$481,"<="&$I$2) -> 35 | L18: =IFERROR(AVERAGEIFS(البيانات!$O$2:$O$481,البيانات!$B$2:$B$481,"غير العربية",البيانات!$W$2:$W$481,">="&$H$2,البيانات!$W$2:$W$481,"<="&$I$2),"") -> 0.71428571 | M18: =IFERROR(AVERAGEIFS(البيانات!$O$2:$O$481,البيانات!$B$2:$B$481,"عربية",البيانات!$W$2:$W$481,">="&$H$2,البيانات!$W$2:$W$481,"<="&$I$2),"") -> 0.64583333 | N18: =COUNTIFS(البيانات!$B$2:$B$481,"غير العربية",البيانات!$W$2:$W$481,">="&$J$2,البيانات!$W$2:$W$481,"<="&$K$2) -> 36 | O18: =IFERROR(AVERAGEIFS(البيانات!$O$2:$O$481,البيانات!$B$2:$B$481,"غير العربية",البيانات!$W$2:$W$481,">="&$J$2,البيانات!$W$2:$W$481,"<="&$K$2),"") -> 0.91666667 | P18: =IFERROR(AVERAGEIFS(البيانات!$O$2:$O$481,البيانات!$B$2:$B$481,"عربية",البيانات!$W$2:$W$481,">="&$J$2,البيانات!$W$2:$W$481,"<="&$K$2),"") -> 0.95 | Q18: =(IF(AND(ISNUMBER(C18),ISNUMBER(D18)),B18*(C18-D18),0)+IF(AND(ISNUMBER(F18),ISNUMBER(G18)),E18*(F18-G18),0)+IF(AND(ISNUMBER(I18),ISNUMBER(J18)),H18*(I18-J18),0)+IF(AND(ISNUMBER(L18),ISNUMBER(M18)),K18*(L18-M18),0)+IF(AND(ISNUMBER(O18),ISNUMBER(P18)),N18*(O18-P18),0))/(IF(AND(ISNUMBER(C18),ISNUMBER(D18)),B18,0)+IF(AND(ISNUMBER(F18),ISNUMBER(G18)),E18,0)+IF(AND(ISNUMBER(I18),ISNUMBER(J18)),H18,0)+IF(AND(ISNUMBER(L18),ISNUMBER(M18)),K18,0)+IF(AND(ISNUMBER(O18),ISNUMBER(P18)),N18,0)) -> 0.016874269 | R18: =IF(ABS(Q18)>$N$2,IF(Q18<0,"فرق كبير ضد غير العربية","فرق كبير لصالح غير العربية"),IF(ABS(Q18)>=$N$1,"يستحق الفحص","مهمل")) -> مهمل
A19: ف14 | B19: =COUNTIFS(البيانات!$B$2:$B$481,"غير العربية",البيانات!$W$2:$W$481,">="&$B$2,البيانات!$W$2:$W$481,"<="&$C$2) -> 36 | C19: =IFERROR(AVERAGEIFS(البيانات!$P$2:$P$481,البيانات!$B$2:$B$481,"غير العربية",البيانات!$W$2:$W$481,">="&$B$2,البيانات!$W$2:$W$481,"<="&$C$2),"") -> 0 | D19: =IFERROR(AVERAGEIFS(البيانات!$P$2:$P$481,البيانات!$B$2:$B$481,"عربية",البيانات!$W$2:$W$481,">="&$B$2,البيانات!$W$2:$W$481,"<="&$C$2),"") -> 0.039473684 | E19: =COUNTIFS(البيانات!$B$2:$B$481,"غير العربية",البيانات!$W$2:$W$481,">="&$D$2,البيانات!$W$2:$W$481,"<="&$E$2) -> 36 | F19: =IFERROR(AVERAGEIFS(البيانات!$P$2:$P$481,البيانات!$B$2:$B$481,"غير العربية",البيانات!$W$2:$W$481,">="&$D$2,البيانات!$W$2:$W$481,"<="&$E$2),"") -> 0.083333333 | G19: =IFERROR(AVERAGEIFS(البيانات!$P$2:$P$481,البيانات!$B$2:$B$481,"عربية",البيانات!$W$2:$W$481,">="&$D$2,البيانات!$W$2:$W$481,"<="&$E$2),"") -> 0.10769231 | H19: =COUNTIFS(البيانات!$B$2:$B$481,"غير العربية",البيانات!$W$2:$W$481,">="&$F$2,البيانات!$W$2:$W$481,"<="&$G$2) -> 37 | I19: =IFERROR(AVERAGEIFS(البيانات!$P$2:$P$481,البيانات!$B$2:$B$481,"غير العربية",البيانات!$W$2:$W$481,">="&$F$2,البيانات!$W$2:$W$481,"<="&$G$2),"") -> 0.081081081 | J19: =IFERROR(AVERAGEIFS(البيانات!$P$2:$P$481,البيانات!$B$2:$B$481,"عربية",البيانات!$W$2:$W$481,">="&$F$2,البيانات!$W$2:$W$481,"<="&$G$2),"") -> 0.23943662 | K19: =COUNTIFS(البيانات!$B$2:$B$481,"غير العربية",البيانات!$W$2:$W$481,">="&$H$2,البيانات!$W$2:$W$481,"<="&$I$2) -> 35 | L19: =IFERROR(AVERAGEIFS(البيانات!$P$2:$P$481,البيانات!$B$2:$B$481,"غير العربية",البيانات!$W$2:$W$481,">="&$H$2,البيانات!$W$2:$W$481,"<="&$I$2),"") -> 0.17142857 | M19: =IFERROR(AVERAGEIFS(البيانات!$P$2:$P$481,البيانات!$B$2:$B$481,"عربية",البيانات!$W$2:$W$481,">="&$H$2,البيانات!$W$2:$W$481,"<="&$I$2),"") -> 0.45833333 | N19: =COUNTIFS(البيانات!$B$2:$B$481,"غير العربية",البيانات!$W$2:$W$481,">="&$J$2,البيانات!$W$2:$W$481,"<="&$K$2) -> 36 | O19: =IFERROR(AVERAGEIFS(البيانات!$P$2:$P$481,البيانات!$B$2:$B$481,"غير العربية",البيانات!$W$2:$W$481,">="&$J$2,البيانات!$W$2:$W$481,"<="&$K$2),"") -> 0.69444444 | P19: =IFERROR(AVERAGEIFS(البيانات!$P$2:$P$481,البيانات!$B$2:$B$481,"عربية",البيانات!$W$2:$W$481,">="&$J$2,البيانات!$W$2:$W$481,"<="&$K$2),"") -> 0.9 | Q19: =(IF(AND(ISNUMBER(C19),ISNUMBER(D19)),B19*(C19-D19),0)+IF(AND(ISNUMBER(F19),ISNUMBER(G19)),E19*(F19-G19),0)+IF(AND(ISNUMBER(I19),ISNUMBER(J19)),H19*(I19-J19),0)+IF(AND(ISNUMBER(L19),ISNUMBER(M19)),K19*(L19-M19),0)+IF(AND(ISNUMBER(O19),ISNUMBER(P19)),N19*(O19-P19),0))/(IF(AND(ISNUMBER(C19),ISNUMBER(D19)),B19,0)+IF(AND(ISNUMBER(F19),ISNUMBER(G19)),E19,0)+IF(AND(ISNUMBER(I19),ISNUMBER(J19)),H19,0)+IF(AND(ISNUMBER(L19),ISNUMBER(M19)),K19,0)+IF(AND(ISNUMBER(O19),ISNUMBER(P19)),N19,0)) -> -0.14221554 | R19: =IF(ABS(Q19)>$N$2,IF(Q19<0,"فرق كبير ضد غير العربية","فرق كبير لصالح غير العربية"),IF(ABS(Q19)>=$N$1,"يستحق الفحص","مهمل")) -> فرق كبير ضد غير العربية
A20: ف15 | B20: =COUNTIFS(البيانات!$B$2:$B$481,"غير العربية",البيانات!$W$2:$W$481,">="&$B$2,البيانات!$W$2:$W$481,"<="&$C$2) -> 36 | C20: =IFERROR(AVERAGEIFS(البيانات!$Q$2:$Q$481,البيانات!$B$2:$B$481,"غير العربية",البيانات!$W$2:$W$481,">="&$B$2,البيانات!$W$2:$W$481,"<="&$C$2),"") -> 0.5 | D20: =IFERROR(AVERAGEIFS(البيانات!$Q$2:$Q$481,البيانات!$B$2:$B$481,"عربية",البيانات!$W$2:$W$481,">="&$B$2,البيانات!$W$2:$W$481,"<="&$C$2),"") -> 0.59210526 | E20: =COUNTIFS(البيانات!$B$2:$B$481,"غير العربية",البيانات!$W$2:$W$481,">="&$D$2,البيانات!$W$2:$W$481,"<="&$E$2) -> 36 | F20: =IFERROR(AVERAGEIFS(البيانات!$Q$2:$Q$481,البيانات!$B$2:$B$481,"غير العربية",البيانات!$W$2:$W$481,">="&$D$2,البيانات!$W$2:$W$481,"<="&$E$2),"") -> 0.94444444 | G20: =IFERROR(AVERAGEIFS(البيانات!$Q$2:$Q$481,البيانات!$B$2:$B$481,"عربية",البيانات!$W$2:$W$481,">="&$D$2,البيانات!$W$2:$W$481,"<="&$E$2),"") -> 0.95384615 | H20: =COUNTIFS(البيانات!$B$2:$B$481,"غير العربية",البيانات!$W$2:$W$481,">="&$F$2,البيانات!$W$2:$W$481,"<="&$G$2) -> 37 | I20: =IFERROR(AVERAGEIFS(البيانات!$Q$2:$Q$481,البيانات!$B$2:$B$481,"غير العربية",البيانات!$W$2:$W$481,">="&$F$2,البيانات!$W$2:$W$481,"<="&$G$2),"") -> 0.97297297 | J20: =IFERROR(AVERAGEIFS(البيانات!$Q$2:$Q$481,البيانات!$B$2:$B$481,"عربية",البيانات!$W$2:$W$481,">="&$F$2,البيانات!$W$2:$W$481,"<="&$G$2),"") -> 1 | K20: =COUNTIFS(البيانات!$B$2:$B$481,"غير العربية",البيانات!$W$2:$W$481,">="&$H$2,البيانات!$W$2:$W$481,"<="&$I$2) -> 35 | L20: =IFERROR(AVERAGEIFS(البيانات!$Q$2:$Q$481,البيانات!$B$2:$B$481,"غير العربية",البيانات!$W$2:$W$481,">="&$H$2,البيانات!$W$2:$W$481,"<="&$I$2),"") -> 1 | M20: =IFERROR(AVERAGEIFS(البيانات!$Q$2:$Q$481,البيانات!$B$2:$B$481,"عربية",البيانات!$W$2:$W$481,">="&$H$2,البيانات!$W$2:$W$481,"<="&$I$2),"") -> 1 | N20: =COUNTIFS(البيانات!$B$2:$B$481,"غير العربية",البيانات!$W$2:$W$481,">="&$J$2,البيانات!$W$2:$W$481,"<="&$K$2) -> 36 | O20: =IFERROR(AVERAGEIFS(البيانات!$Q$2:$Q$481,البيانات!$B$2:$B$481,"غير العربية",البيانات!$W$2:$W$481,">="&$J$2,البيانات!$W$2:$W$481,"<="&$K$2),"") -> 1 | P20: =IFERROR(AVERAGEIFS(البيانات!$Q$2:$Q$481,البيانات!$B$2:$B$481,"عربية",البيانات!$W$2:$W$481,">="&$J$2,البيانات!$W$2:$W$481,"<="&$K$2),"") -> 1 | Q20: =(IF(AND(ISNUMBER(C20),ISNUMBER(D20)),B20*(C20-D20),0)+IF(AND(ISNUMBER(F20),ISNUMBER(G20)),E20*(F20-G20),0)+IF(AND(ISNUMBER(I20),ISNUMBER(J20)),H20*(I20-J20),0)+IF(AND(ISNUMBER(L20),ISNUMBER(M20)),K20*(L20-M20),0)+IF(AND(ISNUMBER(O20),ISNUMBER(P20)),N20*(O20-P20),0))/(IF(AND(ISNUMBER(C20),ISNUMBER(D20)),B20,0)+IF(AND(ISNUMBER(F20),ISNUMBER(G20)),E20,0)+IF(AND(ISNUMBER(I20),ISNUMBER(J20)),H20,0)+IF(AND(ISNUMBER(L20),ISNUMBER(M20)),K20,0)+IF(AND(ISNUMBER(O20),ISNUMBER(P20)),N20,0)) -> -0.02585695 | R20: =IF(ABS(Q20)>$N$2,IF(Q20<0,"فرق كبير ضد غير العربية","فرق كبير لصالح غير العربية"),IF(ABS(Q20)>=$N$1,"يستحق الفحص","مهمل")) -> مهمل
A21: ف16 | B21: =COUNTIFS(البيانات!$B$2:$B$481,"غير العربية",البيانات!$W$2:$W$481,">="&$B$2,البيانات!$W$2:$W$481,"<="&$C$2) -> 36 | C21: =IFERROR(AVERAGEIFS(البيانات!$R$2:$R$481,البيانات!$B$2:$B$481,"غير العربية",البيانات!$W$2:$W$481,">="&$B$2,البيانات!$W$2:$W$481,"<="&$C$2),"") -> 0.027777778 | D21: =IFERROR(AVERAGEIFS(البيانات!$R$2:$R$481,البيانات!$B$2:$B$481,"عربية",البيانات!$W$2:$W$481,">="&$B$2,البيانات!$W$2:$W$481,"<="&$C$2),"") -> 0.026315789 | E21: =COUNTIFS(البيانات!$B$2:$B$481,"غير العربية",البيانات!$W$2:$W$481,">="&$D$2,البيانات!$W$2:$W$481,"<="&$E$2) -> 36 | F21: =IFERROR(AVERAGEIFS(البيانات!$R$2:$R$481,البيانات!$B$2:$B$481,"غير العربية",البيانات!$W$2:$W$481,">="&$D$2,البيانات!$W$2:$W$481,"<="&$E$2),"") -> 0.41666667 | G21: =IFERROR(AVERAGEIFS(البيانات!$R$2:$R$481,البيانات!$B$2:$B$481,"عربية",البيانات!$W$2:$W$481,">="&$D$2,البيانات!$W$2:$W$481,"<="&$E$2),"") -> 0.30769231 | H21: =COUNTIFS(البيانات!$B$2:$B$481,"غير العربية",البيانات!$W$2:$W$481,">="&$F$2,البيانات!$W$2:$W$481,"<="&$G$2) -> 37 | I21: =IFERROR(AVERAGEIFS(البيانات!$R$2:$R$481,البيانات!$B$2:$B$481,"غير العربية",البيانات!$W$2:$W$481,">="&$F$2,البيانات!$W$2:$W$481,"<="&$G$2),"") -> 0.7027027 | J21: =IFERROR(AVERAGEIFS(البيانات!$R$2:$R$481,البيانات!$B$2:$B$481,"عربية",البيانات!$W$2:$W$481,">="&$F$2,البيانات!$W$2:$W$481,"<="&$G$2),"") -> 0.77464789 | K21: =COUNTIFS(البيانات!$B$2:$B$481,"غير العربية",البيانات!$W$2:$W$481,">="&$H$2,البيانات!$W$2:$W$481,"<="&$I$2) -> 35 | L21: =IFERROR(AVERAGEIFS(البيانات!$R$2:$R$481,البيانات!$B$2:$B$481,"غير العربية",البيانات!$W$2:$W$481,">="&$H$2,البيانات!$W$2:$W$481,"<="&$I$2),"") -> 0.97142857 | M21: =IFERROR(AVERAGEIFS(البيانات!$R$2:$R$481,البيانات!$B$2:$B$481,"عربية",البيانات!$W$2:$W$481,">="&$H$2,البيانات!$W$2:$W$481,"<="&$I$2),"") -> 0.83333333 | N21: =COUNTIFS(البيانات!$B$2:$B$481,"غير العربية",البيانات!$W$2:$W$481,">="&$J$2,البيانات!$W$2:$W$481,"<="&$K$2) -> 36 | O21: =IFERROR(AVERAGEIFS(البيانات!$R$2:$R$481,البيانات!$B$2:$B$481,"غير العربية",البيانات!$W$2:$W$481,">="&$J$2,البيانات!$W$2:$W$481,"<="&$K$2),"") -> 0.97222222 | P21: =IFERROR(AVERAGEIFS(البيانات!$R$2:$R$481,البيانات!$B$2:$B$481,"عربية",البيانات!$W$2:$W$481,">="&$J$2,البيانات!$W$2:$W$481,"<="&$K$2),"") -> 0.975 | Q21: =(IF(AND(ISNUMBER(C21),ISNUMBER(D21)),B21*(C21-D21),0)+IF(AND(ISNUMBER(F21),ISNUMBER(G21)),E21*(F21-G21),0)+IF(AND(ISNUMBER(I21),ISNUMBER(J21)),H21*(I21-J21),0)+IF(AND(ISNUMBER(L21),ISNUMBER(M21)),K21*(L21-M21),0)+IF(AND(ISNUMBER(O21),ISNUMBER(P21)),N21*(O21-P21),0))/(IF(AND(ISNUMBER(C21),ISNUMBER(D21)),B21,0)+IF(AND(ISNUMBER(F21),ISNUMBER(G21)),E21,0)+IF(AND(ISNUMBER(I21),ISNUMBER(J21)),H21,0)+IF(AND(ISNUMBER(L21),ISNUMBER(M21)),K21,0)+IF(AND(ISNUMBER(O21),ISNUMBER(P21)),N21,0)) -> 0.033594833 | R21: =IF(ABS(Q21)>$N$2,IF(Q21<0,"فرق كبير ضد غير العربية","فرق كبير لصالح غير العربية"),IF(ABS(Q21)>=$N$1,"يستحق الفحص","مهمل")) -> مهمل
A22: ف17 | B22: =COUNTIFS(البيانات!$B$2:$B$481,"غير العربية",البيانات!$W$2:$W$481,">="&$B$2,البيانات!$W$2:$W$481,"<="&$C$2) -> 36 | C22: =IFERROR(AVERAGEIFS(البيانات!$S$2:$S$481,البيانات!$B$2:$B$481,"غير العربية",البيانات!$W$2:$W$481,">="&$B$2,البيانات!$W$2:$W$481,"<="&$C$2),"") -> 0.33333333 | D22: =IFERROR(AVERAGEIFS(البيانات!$S$2:$S$481,البيانات!$B$2:$B$481,"عربية",البيانات!$W$2:$W$481,">="&$B$2,البيانات!$W$2:$W$481,"<="&$C$2),"") -> 0.11842105 | E22: =COUNTIFS(البيانات!$B$2:$B$481,"غير العربية",البيانات!$W$2:$W$481,">="&$D$2,البيانات!$W$2:$W$481,"<="&$E$2) -> 36 | F22: =IFERROR(AVERAGEIFS(البيانات!$S$2:$S$481,البيانات!$B$2:$B$481,"غير العربية",البيانات!$W$2:$W$481,">="&$D$2,البيانات!$W$2:$W$481,"<="&$E$2),"") -> 0.94444444 | G22: =IFERROR(AVERAGEIFS(البيانات!$S$2:$S$481,البيانات!$B$2:$B$481,"عربية",البيانات!$W$2:$W$481,">="&$D$2,البيانات!$W$2:$W$481,"<="&$E$2),"") -> 0.47692308 | H22: =COUNTIFS(البيانات!$B$2:$B$481,"غير العربية",البيانات!$W$2:$W$481,">="&$F$2,البيانات!$W$2:$W$481,"<="&$G$2) -> 37 | I22: =IFERROR(AVERAGEIFS(البيانات!$S$2:$S$481,البيانات!$B$2:$B$481,"غير العربية",البيانات!$W$2:$W$481,">="&$F$2,البيانات!$W$2:$W$481,"<="&$G$2),"") -> 0.97297297 | J22: =IFERROR(AVERAGEIFS(البيانات!$S$2:$S$481,البيانات!$B$2:$B$481,"عربية",البيانات!$W$2:$W$481,">="&$F$2,البيانات!$W$2:$W$481,"<="&$G$2),"") -> 0.81690141 | K22: =COUNTIFS(البيانات!$B$2:$B$481,"غير العربية",البيانات!$W$2:$W$481,">="&$H$2,البيانات!$W$2:$W$481,"<="&$I$2) -> 35 | L22: =IFERROR(AVERAGEIFS(البيانات!$S$2:$S$481,البيانات!$B$2:$B$481,"غير العربية",البيانات!$W$2:$W$481,">="&$H$2,البيانات!$W$2:$W$481,"<="&$I$2),"") -> 1 | M22: =IFERROR(AVERAGEIFS(البيانات!$S$2:$S$481,البيانات!$B$2:$B$481,"عربية",البيانات!$W$2:$W$481,">="&$H$2,البيانات!$W$2:$W$481,"<="&$I$2),"") -> 0.9375 | N22: =COUNTIFS(البيانات!$B$2:$B$481,"غير العربية",البيانات!$W$2:$W$481,">="&$J$2,البيانات!$W$2:$W$481,"<="&$K$2) -> 36 | O22: =IFERROR(AVERAGEIFS(البيانات!$S$2:$S$481,البيانات!$B$2:$B$481,"غير العربية",البيانات!$W$2:$W$481,">="&$J$2,البيانات!$W$2:$W$481,"<="&$K$2),"") -> 1 | P22: =IFERROR(AVERAGEIFS(البيانات!$S$2:$S$481,البيانات!$B$2:$B$481,"عربية",البيانات!$W$2:$W$481,">="&$J$2,البيانات!$W$2:$W$481,"<="&$K$2),"") -> 1 | Q22: =(IF(AND(ISNUMBER(C22),ISNUMBER(D22)),B22*(C22-D22),0)+IF(AND(ISNUMBER(F22),ISNUMBER(G22)),E22*(F22-G22),0)+IF(AND(ISNUMBER(I22),ISNUMBER(J22)),H22*(I22-J22),0)+IF(AND(ISNUMBER(L22),ISNUMBER(M22)),K22*(L22-M22),0)+IF(AND(ISNUMBER(O22),ISNUMBER(P22)),N22*(O22-P22),0))/(IF(AND(ISNUMBER(C22),ISNUMBER(D22)),B22,0)+IF(AND(ISNUMBER(F22),ISNUMBER(G22)),E22,0)+IF(AND(ISNUMBER(I22),ISNUMBER(J22)),H22,0)+IF(AND(ISNUMBER(L22),ISNUMBER(M22)),K22,0)+IF(AND(ISNUMBER(O22),ISNUMBER(P22)),N22,0)) -> 0.18072088 | R22: =IF(ABS(Q22)>$N$2,IF(Q22<0,"فرق كبير ضد غير العربية","فرق كبير لصالح غير العربية"),IF(ABS(Q22)>=$N$1,"يستحق الفحص","مهمل")) -> فرق كبير لصالح غير العربية
